[2023-09-23T00:18:38.393+0000] {taskinstance.py:1125} INFO - Dependencies all met for dep_context=non-requeueable deps ti=<TaskInstance: resume_generation_dag.generate_resume manual__2023-09-23T00:18:34.053685+00:00 [queued]>
[2023-09-23T00:18:38.399+0000] {taskinstance.py:1125} INFO - Dependencies all met for dep_context=requeueable deps ti=<TaskInstance: resume_generation_dag.generate_resume manual__2023-09-23T00:18:34.053685+00:00 [queued]>
[2023-09-23T00:18:38.400+0000] {taskinstance.py:1331} INFO - Starting attempt 1 of 1
[2023-09-23T00:18:38.407+0000] {taskinstance.py:1350} INFO - Executing <Task(_PythonDecoratedOperator): generate_resume> on 2023-09-23 00:18:34.053685+00:00
[2023-09-23T00:18:38.412+0000] {standard_task_runner.py:57} INFO - Started process 1201 to run task
[2023-09-23T00:18:38.415+0000] {standard_task_runner.py:84} INFO - Running: ['***', 'tasks', 'run', 'resume_generation_dag', 'generate_resume', 'manual__2023-09-23T00:18:34.053685+00:00', '--job-id', '8', '--raw', '--subdir', 'DAGS_FOLDER/resume_generation.py', '--cfg-path', '/tmp/tmpf4uop1aa']
[2023-09-23T00:18:38.418+0000] {standard_task_runner.py:85} INFO - Job 8: Subtask generate_resume
[2023-09-23T00:18:38.429+0000] {logging_mixin.py:149} WARNING - /home/***/.local/lib/python3.9/site-packages/***/settings.py:188 DeprecationWarning: The sql_alchemy_conn option in [core] has been moved to the sql_alchemy_conn option in [database] - the old setting has been used, but please update your config.
[2023-09-23T00:18:38.459+0000] {task_command.py:410} INFO - Running <TaskInstance: resume_generation_dag.generate_resume manual__2023-09-23T00:18:34.053685+00:00 [running]> on host c90ec447a7d6
[2023-09-23T00:18:38.523+0000] {taskinstance.py:1568} INFO - Exporting env vars: AIRFLOW_CTX_DAG_OWNER='***' AIRFLOW_CTX_DAG_ID='resume_generation_dag' AIRFLOW_CTX_TASK_ID='generate_resume' AIRFLOW_CTX_EXECUTION_DATE='2023-09-23T00:18:34.053685+00:00' AIRFLOW_CTX_TRY_NUMBER='1' AIRFLOW_CTX_DAG_RUN_ID='manual__2023-09-23T00:18:34.053685+00:00'
[2023-09-23T00:18:38.677+0000] {taskinstance.py:1847} ERROR - Task failed with exception
Traceback (most recent call last):
  File "/home/airflow/.local/lib/python3.9/site-packages/airflow/decorators/base.py", line 220, in execute
    return_value = super().execute(context)
  File "/home/airflow/.local/lib/python3.9/site-packages/airflow/operators/python.py", line 181, in execute
    return_value = self.execute_callable()
  File "/home/airflow/.local/lib/python3.9/site-packages/airflow/operators/python.py", line 198, in execute_callable
    return self.python_callable(*self.op_args, **self.op_kwargs)
  File "/opt/airflow/dags/resume_generation.py", line 94, in generate_resume
    resume_gen(v['job_title'],",".join(v["skills"]),v['employer_name'],v['job_apply_link'])
  File "/opt/airflow/dags/resume_generation.py", line 42, in resume_gen
    with open('myself.txt', 'r') as file:
FileNotFoundError: [Errno 2] No such file or directory: 'myself.txt'
[2023-09-23T00:18:38.717+0000] {taskinstance.py:1368} INFO - Marking task as FAILED. dag_id=resume_generation_dag, task_id=generate_resume, execution_date=20230923T001834, start_date=20230923T001838, end_date=20230923T001838
[2023-09-23T00:18:38.726+0000] {standard_task_runner.py:104} ERROR - Failed to execute job 8 for task generate_resume ([Errno 2] No such file or directory: 'myself.txt'; 1201)
[2023-09-23T00:18:38.752+0000] {local_task_job_runner.py:232} INFO - Task exited with return code 1
[2023-09-23T00:18:38.780+0000] {taskinstance.py:2674} INFO - 0 downstream tasks scheduled from follow-on schedule check
