[2023-09-22T22:19:21.022+0000] {taskinstance.py:1125} INFO - Dependencies all met for dep_context=non-requeueable deps ti=<TaskInstance: job_extraction_with_task_flow.load_llm manual__2023-09-22T22:19:15.863037+00:00 [queued]>
[2023-09-22T22:19:21.030+0000] {taskinstance.py:1125} INFO - Dependencies all met for dep_context=requeueable deps ti=<TaskInstance: job_extraction_with_task_flow.load_llm manual__2023-09-22T22:19:15.863037+00:00 [queued]>
[2023-09-22T22:19:21.031+0000] {taskinstance.py:1331} INFO - Starting attempt 1 of 1
[2023-09-22T22:19:21.046+0000] {taskinstance.py:1350} INFO - Executing <Task(_PythonDecoratedOperator): load_llm> on 2023-09-22 22:19:15.863037+00:00
[2023-09-22T22:19:21.064+0000] {standard_task_runner.py:57} INFO - Started process 283 to run task
[2023-09-22T22:19:21.142+0000] {standard_task_runner.py:84} INFO - Running: ['***', 'tasks', 'run', 'job_extraction_with_task_flow', 'load_llm', 'manual__2023-09-22T22:19:15.863037+00:00', '--job-id', '2', '--raw', '--subdir', 'DAGS_FOLDER/test3.py', '--cfg-path', '/tmp/tmpjak6tx1r']
[2023-09-22T22:19:21.370+0000] {standard_task_runner.py:85} INFO - Job 2: Subtask load_llm
[2023-09-22T22:19:24.255+0000] {logging_mixin.py:149} WARNING - /home/***/.local/lib/python3.9/site-packages/***/settings.py:188 DeprecationWarning: The sql_alchemy_conn option in [core] has been moved to the sql_alchemy_conn option in [database] - the old setting has been used, but please update your config.
[2023-09-22T22:19:25.839+0000] {task_command.py:410} INFO - Running <TaskInstance: job_extraction_with_task_flow.load_llm manual__2023-09-22T22:19:15.863037+00:00 [running]> on host 94a57e116d67
[2023-09-22T22:19:29.213+0000] {taskinstance.py:1568} INFO - Exporting env vars: AIRFLOW_CTX_DAG_OWNER='***' AIRFLOW_CTX_DAG_ID='job_extraction_with_task_flow' AIRFLOW_CTX_TASK_ID='load_llm' AIRFLOW_CTX_EXECUTION_DATE='2023-09-22T22:19:15.863037+00:00' AIRFLOW_CTX_TRY_NUMBER='1' AIRFLOW_CTX_DAG_RUN_ID='manual__2023-09-22T22:19:15.863037+00:00'
[2023-09-22T22:19:29.759+0000] {python.py:183} INFO - Done. Returned value was: cache=None verbose=False callbacks=None callback_manager=None tags=None metadata=None client=<class 'openai.api_resources.chat_completion.ChatCompletion'> model_name='gpt-3.5-turbo' temperature=0.0 model_kwargs={} openai_api_key='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' openai_api_base='' openai_organization='' openai_proxy='' request_timeout=None max_retries=6 streaming=False n=1 max_tokens=3000 tiktoken_model_name=None
[2023-09-22T22:19:29.767+0000] {taskinstance.py:1847} ERROR - Task failed with exception
Traceback (most recent call last):
  File "/home/airflow/.local/lib/python3.9/site-packages/airflow/utils/session.py", line 73, in wrapper
    return func(*args, **kwargs)
  File "/home/airflow/.local/lib/python3.9/site-packages/airflow/models/taskinstance.py", line 2377, in xcom_push
    XCom.set(
  File "/home/airflow/.local/lib/python3.9/site-packages/airflow/utils/session.py", line 73, in wrapper
    return func(*args, **kwargs)
  File "/home/airflow/.local/lib/python3.9/site-packages/airflow/models/xcom.py", line 237, in set
    value = cls.serialize_value(
  File "/home/airflow/.local/lib/python3.9/site-packages/airflow/models/xcom.py", line 632, in serialize_value
    return json.dumps(value, cls=XComEncoder).encode("UTF-8")
  File "/usr/local/lib/python3.9/json/__init__.py", line 234, in dumps
    return cls(
  File "/home/airflow/.local/lib/python3.9/site-packages/airflow/utils/json.py", line 104, in encode
    return super().encode(o)
  File "/usr/local/lib/python3.9/json/encoder.py", line 199, in encode
    chunks = self.iterencode(o, _one_shot=True)
  File "/usr/local/lib/python3.9/json/encoder.py", line 257, in iterencode
    return _iterencode(o, 0)
  File "/home/airflow/.local/lib/python3.9/site-packages/airflow/utils/json.py", line 91, in default
    return serialize(o)
  File "/home/airflow/.local/lib/python3.9/site-packages/airflow/serialization/serde.py", line 132, in serialize
    qn = qualname(o)
  File "/home/airflow/.local/lib/python3.9/site-packages/airflow/utils/module_loading.py", line 47, in qualname
    return f"{o.__module__}.{o.__name__}"
AttributeError: 'ChatOpenAI' object has no attribute '__name__'
[2023-09-22T22:19:29.780+0000] {taskinstance.py:1368} INFO - Marking task as FAILED. dag_id=job_extraction_with_task_flow, task_id=load_llm, execution_date=20230922T221915, start_date=20230922T221921, end_date=20230922T221929
[2023-09-22T22:19:29.787+0000] {standard_task_runner.py:104} ERROR - Failed to execute job 2 for task load_llm ('ChatOpenAI' object has no attribute '__name__'; 283)
[2023-09-22T22:19:29.808+0000] {local_task_job_runner.py:232} INFO - Task exited with return code 1
[2023-09-22T22:19:29.836+0000] {taskinstance.py:2674} INFO - 0 downstream tasks scheduled from follow-on schedule check
