[2023-10-03T19:33:51.726+0000] {taskinstance.py:1125} INFO - Dependencies all met for dep_context=non-requeueable deps ti=<TaskInstance: resume_generation_dag.generate_resume manual__2023-10-03T19:33:48.345802+00:00 [queued]>
[2023-10-03T19:33:51.732+0000] {taskinstance.py:1125} INFO - Dependencies all met for dep_context=requeueable deps ti=<TaskInstance: resume_generation_dag.generate_resume manual__2023-10-03T19:33:48.345802+00:00 [queued]>
[2023-10-03T19:33:51.733+0000] {taskinstance.py:1331} INFO - Starting attempt 1 of 1
[2023-10-03T19:33:51.740+0000] {taskinstance.py:1350} INFO - Executing <Task(_PythonDecoratedOperator): generate_resume> on 2023-10-03 19:33:48.345802+00:00
[2023-10-03T19:33:51.743+0000] {standard_task_runner.py:57} INFO - Started process 463 to run task
[2023-10-03T19:33:51.746+0000] {standard_task_runner.py:84} INFO - Running: ['***', 'tasks', 'run', 'resume_generation_dag', 'generate_resume', 'manual__2023-10-03T19:33:48.345802+00:00', '--job-id', '6', '--raw', '--subdir', 'DAGS_FOLDER/resume_generation.py', '--cfg-path', '/tmp/tmp8mukrgrm']
[2023-10-03T19:33:51.749+0000] {standard_task_runner.py:85} INFO - Job 6: Subtask generate_resume
[2023-10-03T19:33:51.760+0000] {logging_mixin.py:149} WARNING - /home/***/.local/lib/python3.9/site-packages/***/settings.py:188 DeprecationWarning: The sql_alchemy_conn option in [core] has been moved to the sql_alchemy_conn option in [database] - the old setting has been used, but please update your config.
[2023-10-03T19:33:51.786+0000] {task_command.py:410} INFO - Running <TaskInstance: resume_generation_dag.generate_resume manual__2023-10-03T19:33:48.345802+00:00 [running]> on host a19f7e7baf22
[2023-10-03T19:33:51.847+0000] {taskinstance.py:1568} INFO - Exporting env vars: AIRFLOW_CTX_DAG_OWNER='***' AIRFLOW_CTX_DAG_ID='resume_generation_dag' AIRFLOW_CTX_TASK_ID='generate_resume' AIRFLOW_CTX_EXECUTION_DATE='2023-10-03T19:33:48.345802+00:00' AIRFLOW_CTX_TRY_NUMBER='1' AIRFLOW_CTX_DAG_RUN_ID='manual__2023-10-03T19:33:48.345802+00:00'
[2023-10-03T19:34:21.949+0000] {logging_mixin.py:149} INFO - FULL_PATH
[2023-10-03T19:34:22.101+0000] {logging_mixin.py:149} INFO - /opt/***/dags/resumes/Resume_1206067 B.C. LTD._1.txt
[2023-10-03T19:35:10.469+0000] {logging_mixin.py:149} INFO - FULL_PATH
[2023-10-03T19:35:10.472+0000] {logging_mixin.py:149} INFO - /opt/***/dags/resumes/Resume_Block_2.txt
[2023-10-03T19:35:54.210+0000] {logging_mixin.py:149} INFO - FULL_PATH
[2023-10-03T19:35:54.218+0000] {logging_mixin.py:149} INFO - /opt/***/dags/resumes/Resume_Intuit_3.txt
[2023-10-03T19:36:25.099+0000] {logging_mixin.py:149} INFO - FULL_PATH
[2023-10-03T19:36:25.102+0000] {logging_mixin.py:149} INFO - /opt/***/dags/resumes/Resume_Olympic Industries ULC_4.txt
[2023-10-03T19:37:06.178+0000] {logging_mixin.py:149} INFO - FULL_PATH
[2023-10-03T19:37:06.186+0000] {logging_mixin.py:149} INFO - /opt/***/dags/resumes/Resume_Ripple_5.txt
[2023-10-03T19:37:33.517+0000] {logging_mixin.py:149} INFO - FULL_PATH
[2023-10-03T19:37:33.519+0000] {logging_mixin.py:149} INFO - /opt/***/dags/resumes/Resume_Flighthub_6.txt
[2023-10-03T19:38:05.557+0000] {logging_mixin.py:149} INFO - FULL_PATH
[2023-10-03T19:38:05.562+0000] {logging_mixin.py:149} INFO - /opt/***/dags/resumes/Resume_Coursera_7.txt
[2023-10-03T19:38:43.549+0000] {logging_mixin.py:149} INFO - FULL_PATH
[2023-10-03T19:38:43.552+0000] {logging_mixin.py:149} INFO - /opt/***/dags/resumes/Resume_Radley James_8.txt
[2023-10-03T19:39:14.695+0000] {logging_mixin.py:149} INFO - FULL_PATH
[2023-10-03T19:39:14.709+0000] {logging_mixin.py:149} INFO - /opt/***/dags/resumes/Resume_Sony Playstation_9.txt
[2023-10-03T19:39:32.538+0000] {local_task_job_runner.py:122} ERROR - Received SIGTERM. Terminating subprocesses
[2023-10-03T19:39:32.620+0000] {process_utils.py:131} INFO - Sending Signals.SIGTERM to group 463. PIDs of all processes in the group: [463]
[2023-10-03T19:39:32.638+0000] {process_utils.py:86} INFO - Sending the signal Signals.SIGTERM to group 463
[2023-10-03T19:39:32.649+0000] {taskinstance.py:1540} ERROR - Received SIGTERM. Terminating subprocesses.
[2023-10-03T19:39:32.809+0000] {taskinstance.py:1847} ERROR - Task failed with exception
Traceback (most recent call last):
  File "/home/airflow/.local/lib/python3.9/site-packages/airflow/decorators/base.py", line 220, in execute
    return_value = super().execute(context)
  File "/home/airflow/.local/lib/python3.9/site-packages/airflow/operators/python.py", line 181, in execute
    return_value = self.execute_callable()
  File "/home/airflow/.local/lib/python3.9/site-packages/airflow/operators/python.py", line 198, in execute_callable
    return self.python_callable(*self.op_args, **self.op_kwargs)
  File "/opt/airflow/dags/resume_generation.py", line 99, in generate_resume
    resume_gen(v['job_title'],",".join(v["skills"]),v['employer_name'],v['job_apply_link'],v['job_tag'],cnt)
  File "/opt/airflow/dags/resume_generation.py", line 47, in resume_gen
    val=chain.run({
  File "/home/airflow/.local/lib/python3.9/site-packages/langchain/chains/base.py", line 507, in run
    return self(args[0], callbacks=callbacks, tags=tags, metadata=metadata)[
  File "/home/airflow/.local/lib/python3.9/site-packages/langchain/chains/base.py", line 312, in __call__
    raise e
  File "/home/airflow/.local/lib/python3.9/site-packages/langchain/chains/base.py", line 306, in __call__
    self._call(inputs, run_manager=run_manager)
  File "/home/airflow/.local/lib/python3.9/site-packages/langchain/chains/llm.py", line 93, in _call
    response = self.generate([inputs], run_manager=run_manager)
  File "/home/airflow/.local/lib/python3.9/site-packages/langchain/chains/llm.py", line 103, in generate
    return self.llm.generate_prompt(
  File "/home/airflow/.local/lib/python3.9/site-packages/langchain/chat_models/base.py", line 475, in generate_prompt
    return self.generate(prompt_messages, stop=stop, callbacks=callbacks, **kwargs)
  File "/home/airflow/.local/lib/python3.9/site-packages/langchain/chat_models/base.py", line 365, in generate
    raise e
  File "/home/airflow/.local/lib/python3.9/site-packages/langchain/chat_models/base.py", line 355, in generate
    self._generate_with_cache(
  File "/home/airflow/.local/lib/python3.9/site-packages/langchain/chat_models/base.py", line 507, in _generate_with_cache
    return self._generate(
  File "/home/airflow/.local/lib/python3.9/site-packages/langchain/chat_models/openai.py", line 345, in _generate
    response = self.completion_with_retry(
  File "/home/airflow/.local/lib/python3.9/site-packages/langchain/chat_models/openai.py", line 284, in completion_with_retry
    return _completion_with_retry(**kwargs)
  File "/home/airflow/.local/lib/python3.9/site-packages/tenacity/__init__.py", line 289, in wrapped_f
    return self(f, *args, **kw)
  File "/home/airflow/.local/lib/python3.9/site-packages/tenacity/__init__.py", line 379, in __call__
    do = self.iter(retry_state=retry_state)
  File "/home/airflow/.local/lib/python3.9/site-packages/tenacity/__init__.py", line 314, in iter
    return fut.result()
  File "/usr/local/lib/python3.9/concurrent/futures/_base.py", line 439, in result
    return self.__get_result()
  File "/usr/local/lib/python3.9/concurrent/futures/_base.py", line 391, in __get_result
    raise self._exception
  File "/home/airflow/.local/lib/python3.9/site-packages/tenacity/__init__.py", line 382, in __call__
    result = fn(*args, **kwargs)
  File "/home/airflow/.local/lib/python3.9/site-packages/langchain/chat_models/openai.py", line 282, in _completion_with_retry
    return self.client.create(**kwargs)
  File "/home/airflow/.local/lib/python3.9/site-packages/openai/api_resources/chat_completion.py", line 25, in create
    return super().create(*args, **kwargs)
  File "/home/airflow/.local/lib/python3.9/site-packages/openai/api_resources/abstract/engine_api_resource.py", line 155, in create
    response, _, api_key = requestor.request(
  File "/home/airflow/.local/lib/python3.9/site-packages/openai/api_requestor.py", line 289, in request
    result = self.request_raw(
  File "/home/airflow/.local/lib/python3.9/site-packages/openai/api_requestor.py", line 606, in request_raw
    result = _thread_context.session.request(
  File "/home/airflow/.local/lib/python3.9/site-packages/requests/sessions.py", line 587, in request
    resp = self.send(prep, **send_kwargs)
  File "/home/airflow/.local/lib/python3.9/site-packages/requests/sessions.py", line 701, in send
    r = adapter.send(request, **kwargs)
  File "/home/airflow/.local/lib/python3.9/site-packages/requests/adapters.py", line 487, in send
    resp = conn.urlopen(
  File "/home/airflow/.local/lib/python3.9/site-packages/urllib3/connectionpool.py", line 703, in urlopen
    httplib_response = self._make_request(
  File "/home/airflow/.local/lib/python3.9/site-packages/urllib3/connectionpool.py", line 449, in _make_request
    six.raise_from(e, None)
  File "<string>", line 3, in raise_from
  File "/home/airflow/.local/lib/python3.9/site-packages/urllib3/connectionpool.py", line 444, in _make_request
    httplib_response = conn.getresponse()
  File "/usr/local/lib/python3.9/http/client.py", line 1377, in getresponse
    response.begin()
  File "/usr/local/lib/python3.9/http/client.py", line 320, in begin
    version, status, reason = self._read_status()
  File "/usr/local/lib/python3.9/http/client.py", line 281, in _read_status
    line = str(self.fp.readline(_MAXLINE + 1), "iso-8859-1")
  File "/usr/local/lib/python3.9/socket.py", line 704, in readinto
    return self._sock.recv_into(b)
  File "/usr/local/lib/python3.9/ssl.py", line 1242, in recv_into
    return self.read(nbytes, buffer)
  File "/usr/local/lib/python3.9/ssl.py", line 1100, in read
    return self._sslobj.read(len, buffer)
  File "/home/airflow/.local/lib/python3.9/site-packages/airflow/models/taskinstance.py", line 1542, in signal_handler
    raise AirflowException("Task received SIGTERM signal")
airflow.exceptions.AirflowException: Task received SIGTERM signal
[2023-10-03T19:39:32.853+0000] {taskinstance.py:1368} INFO - Marking task as FAILED. dag_id=resume_generation_dag, task_id=generate_resume, execution_date=20231003T193348, start_date=20231003T193351, end_date=20231003T193932
[2023-10-03T19:39:32.892+0000] {standard_task_runner.py:104} ERROR - Failed to execute job 6 for task generate_resume (Task received SIGTERM signal; 463)
[2023-10-03T19:39:32.959+0000] {process_utils.py:79} INFO - Process psutil.Process(pid=463, status='terminated', exitcode=1, started='19:33:51') (463) terminated with exit code 1
[2023-10-03T19:39:32.965+0000] {local_task_job_runner.py:232} INFO - Task exited with return code 143
[2023-10-03T19:39:33.007+0000] {taskinstance.py:2674} INFO - 0 downstream tasks scheduled from follow-on schedule check
[2023-10-03T19:39:34.174+0000] {local_task_job_runner.py:122} ERROR - Received SIGTERM. Terminating subprocesses
