[2023-09-22T21:42:32.900+0000] {taskinstance.py:1125} INFO - Dependencies all met for dep_context=non-requeueable deps ti=<TaskInstance: job_extraction_with_task_flow.load_llm manual__2023-09-22T21:42:30.678295+00:00 [queued]>
[2023-09-22T21:42:32.906+0000] {taskinstance.py:1125} INFO - Dependencies all met for dep_context=requeueable deps ti=<TaskInstance: job_extraction_with_task_flow.load_llm manual__2023-09-22T21:42:30.678295+00:00 [queued]>
[2023-09-22T21:42:32.909+0000] {taskinstance.py:1331} INFO - Starting attempt 1 of 2
[2023-09-22T21:42:32.918+0000] {taskinstance.py:1350} INFO - Executing <Task(_PythonDecoratedOperator): load_llm> on 2023-09-22 21:42:30.678295+00:00
[2023-09-22T21:42:32.922+0000] {standard_task_runner.py:57} INFO - Started process 351 to run task
[2023-09-22T21:42:32.925+0000] {standard_task_runner.py:84} INFO - Running: ['***', 'tasks', 'run', 'job_extraction_with_task_flow', 'load_llm', 'manual__2023-09-22T21:42:30.678295+00:00', '--job-id', '8', '--raw', '--subdir', 'DAGS_FOLDER/test3.py', '--cfg-path', '/tmp/tmpvqi0x4vb']
[2023-09-22T21:42:32.928+0000] {standard_task_runner.py:85} INFO - Job 8: Subtask load_llm
[2023-09-22T21:42:32.941+0000] {logging_mixin.py:149} WARNING - /home/***/.local/lib/python3.9/site-packages/***/settings.py:188 DeprecationWarning: The sql_alchemy_conn option in [core] has been moved to the sql_alchemy_conn option in [database] - the old setting has been used, but please update your config.
[2023-09-22T21:42:32.974+0000] {task_command.py:410} INFO - Running <TaskInstance: job_extraction_with_task_flow.load_llm manual__2023-09-22T21:42:30.678295+00:00 [running]> on host 6d8bf768d09b
[2023-09-22T21:42:33.031+0000] {taskinstance.py:1568} INFO - Exporting env vars: AIRFLOW_CTX_DAG_OWNER='***' AIRFLOW_CTX_DAG_ID='job_extraction_with_task_flow' AIRFLOW_CTX_TASK_ID='load_llm' AIRFLOW_CTX_EXECUTION_DATE='2023-09-22T21:42:30.678295+00:00' AIRFLOW_CTX_TRY_NUMBER='1' AIRFLOW_CTX_DAG_RUN_ID='manual__2023-09-22T21:42:30.678295+00:00'
[2023-09-22T21:42:33.036+0000] {taskinstance.py:1847} ERROR - Task failed with exception
Traceback (most recent call last):
  File "/home/airflow/.local/lib/python3.9/site-packages/airflow/decorators/base.py", line 220, in execute
    return_value = super().execute(context)
  File "/home/airflow/.local/lib/python3.9/site-packages/airflow/operators/python.py", line 181, in execute
    return_value = self.execute_callable()
  File "/home/airflow/.local/lib/python3.9/site-packages/airflow/operators/python.py", line 198, in execute_callable
    return self.python_callable(*self.op_args, **self.op_kwargs)
  File "/opt/airflow/dags/test3.py", line 86, in load_llm
    llm=ChatOpenAI(model=model_name,temperature = 0,
  File "/home/airflow/.local/lib/python3.9/site-packages/langchain/load/serializable.py", line 75, in __init__
    super().__init__(**kwargs)
  File "/home/airflow/.local/lib/python3.9/site-packages/pydantic/main.py", line 341, in __init__
    raise validation_error
pydantic.error_wrappers.ValidationError: 1 validation error for ChatOpenAI
__root__
  Did not find openai_api_key, please add an environment variable `OPENAI_API_KEY` which contains it, or pass  `openai_api_key` as a named parameter. (type=value_error)
[2023-09-22T21:42:33.048+0000] {taskinstance.py:1368} INFO - Marking task as UP_FOR_RETRY. dag_id=job_extraction_with_task_flow, task_id=load_llm, execution_date=20230922T214230, start_date=20230922T214232, end_date=20230922T214233
[2023-09-22T21:42:33.057+0000] {standard_task_runner.py:104} ERROR - Failed to execute job 8 for task load_llm (1 validation error for ChatOpenAI
__root__
  Did not find openai_api_key, please add an environment variable `OPENAI_API_KEY` which contains it, or pass  `openai_api_key` as a named parameter. (type=value_error); 351)
[2023-09-22T21:42:33.100+0000] {local_task_job_runner.py:232} INFO - Task exited with return code 1
[2023-09-22T21:42:33.117+0000] {taskinstance.py:2674} INFO - 0 downstream tasks scheduled from follow-on schedule check
