[2023-09-22T21:47:34.665+0000] {taskinstance.py:1125} INFO - Dependencies all met for dep_context=non-requeueable deps ti=<TaskInstance: job_extraction_with_task_flow.load_llm manual__2023-09-22T21:42:30.678295+00:00 [queued]>
[2023-09-22T21:47:34.670+0000] {taskinstance.py:1125} INFO - Dependencies all met for dep_context=requeueable deps ti=<TaskInstance: job_extraction_with_task_flow.load_llm manual__2023-09-22T21:42:30.678295+00:00 [queued]>
[2023-09-22T21:47:34.671+0000] {taskinstance.py:1331} INFO - Starting attempt 2 of 2
[2023-09-22T21:47:34.678+0000] {taskinstance.py:1350} INFO - Executing <Task(_PythonDecoratedOperator): load_llm> on 2023-09-22 21:42:30.678295+00:00
[2023-09-22T21:47:34.683+0000] {standard_task_runner.py:57} INFO - Started process 660 to run task
[2023-09-22T21:47:34.686+0000] {standard_task_runner.py:84} INFO - Running: ['***', 'tasks', 'run', 'job_extraction_with_task_flow', 'load_llm', 'manual__2023-09-22T21:42:30.678295+00:00', '--job-id', '12', '--raw', '--subdir', 'DAGS_FOLDER/test3.py', '--cfg-path', '/tmp/tmpityox_ko']
[2023-09-22T21:47:34.688+0000] {standard_task_runner.py:85} INFO - Job 12: Subtask load_llm
[2023-09-22T21:47:34.701+0000] {logging_mixin.py:149} WARNING - /home/***/.local/lib/python3.9/site-packages/***/settings.py:188 DeprecationWarning: The sql_alchemy_conn option in [core] has been moved to the sql_alchemy_conn option in [database] - the old setting has been used, but please update your config.
[2023-09-22T21:47:34.727+0000] {task_command.py:410} INFO - Running <TaskInstance: job_extraction_with_task_flow.load_llm manual__2023-09-22T21:42:30.678295+00:00 [running]> on host 6d8bf768d09b
[2023-09-22T21:47:34.776+0000] {taskinstance.py:1568} INFO - Exporting env vars: AIRFLOW_CTX_DAG_OWNER='***' AIRFLOW_CTX_DAG_ID='job_extraction_with_task_flow' AIRFLOW_CTX_TASK_ID='load_llm' AIRFLOW_CTX_EXECUTION_DATE='2023-09-22T21:42:30.678295+00:00' AIRFLOW_CTX_TRY_NUMBER='2' AIRFLOW_CTX_DAG_RUN_ID='manual__2023-09-22T21:42:30.678295+00:00'
[2023-09-22T21:47:34.779+0000] {taskinstance.py:1847} ERROR - Task failed with exception
Traceback (most recent call last):
  File "/home/airflow/.local/lib/python3.9/site-packages/airflow/decorators/base.py", line 220, in execute
    return_value = super().execute(context)
  File "/home/airflow/.local/lib/python3.9/site-packages/airflow/operators/python.py", line 181, in execute
    return_value = self.execute_callable()
  File "/home/airflow/.local/lib/python3.9/site-packages/airflow/operators/python.py", line 198, in execute_callable
    return self.python_callable(*self.op_args, **self.op_kwargs)
  File "/opt/airflow/dags/test3.py", line 86, in load_llm
    llm=ChatOpenAI(model=model_name,temperature = 0,
  File "/home/airflow/.local/lib/python3.9/site-packages/langchain/load/serializable.py", line 75, in __init__
    super().__init__(**kwargs)
  File "/home/airflow/.local/lib/python3.9/site-packages/pydantic/main.py", line 341, in __init__
    raise validation_error
pydantic.error_wrappers.ValidationError: 1 validation error for ChatOpenAI
__root__
  Did not find openai_api_key, please add an environment variable `OPENAI_API_KEY` which contains it, or pass  `openai_api_key` as a named parameter. (type=value_error)
[2023-09-22T21:47:34.791+0000] {taskinstance.py:1368} INFO - Marking task as FAILED. dag_id=job_extraction_with_task_flow, task_id=load_llm, execution_date=20230922T214230, start_date=20230922T214734, end_date=20230922T214734
[2023-09-22T21:47:34.799+0000] {standard_task_runner.py:104} ERROR - Failed to execute job 12 for task load_llm (1 validation error for ChatOpenAI
__root__
  Did not find openai_api_key, please add an environment variable `OPENAI_API_KEY` which contains it, or pass  `openai_api_key` as a named parameter. (type=value_error); 660)
[2023-09-22T21:47:34.818+0000] {local_task_job_runner.py:232} INFO - Task exited with return code 1
[2023-09-22T21:47:34.846+0000] {taskinstance.py:2674} INFO - 0 downstream tasks scheduled from follow-on schedule check
