[2023-09-22T16:52:39.975+0000] {logging_mixin.py:149} WARNING - /home/***/.local/lib/python3.9/site-packages/***/utils/sqlalchemy.py:124 DeprecationWarning: The sql_alchemy_conn option in [core] has been moved to the sql_alchemy_conn option in [database] - the old setting has been used, but please update your config.
[2023-09-22T16:52:40.170+0000] {taskinstance.py:1125} INFO - Dependencies all met for dep_context=non-requeueable deps ti=<TaskInstance: dag_with_taskflow_api_v02.greet scheduled__2021-11-15T00:00:00+00:00 [queued]>
[2023-09-22T16:52:40.198+0000] {taskinstance.py:1125} INFO - Dependencies all met for dep_context=requeueable deps ti=<TaskInstance: dag_with_taskflow_api_v02.greet scheduled__2021-11-15T00:00:00+00:00 [queued]>
[2023-09-22T16:52:40.200+0000] {taskinstance.py:1331} INFO - Starting attempt 1 of 6
[2023-09-22T16:52:40.260+0000] {taskinstance.py:1350} INFO - Executing <Task(_PythonDecoratedOperator): greet> on 2021-11-15 00:00:00+00:00
[2023-09-22T16:52:40.280+0000] {standard_task_runner.py:57} INFO - Started process 622 to run task
[2023-09-22T16:52:40.313+0000] {standard_task_runner.py:84} INFO - Running: ['***', 'tasks', 'run', 'dag_with_taskflow_api_v02', 'greet', 'scheduled__2021-11-15T00:00:00+00:00', '--job-id', '169', '--raw', '--subdir', 'DAGS_FOLDER/test2.py', '--cfg-path', '/tmp/tmpz0thrsba']
[2023-09-22T16:52:40.330+0000] {standard_task_runner.py:85} INFO - Job 169: Subtask greet
[2023-09-22T16:52:40.385+0000] {logging_mixin.py:149} WARNING - /home/***/.local/lib/python3.9/site-packages/***/settings.py:188 DeprecationWarning: The sql_alchemy_conn option in [core] has been moved to the sql_alchemy_conn option in [database] - the old setting has been used, but please update your config.
[2023-09-22T16:52:40.517+0000] {task_command.py:410} INFO - Running <TaskInstance: dag_with_taskflow_api_v02.greet scheduled__2021-11-15T00:00:00+00:00 [running]> on host 75cee4990e54
[2023-09-22T16:52:40.563+0000] {logging_mixin.py:149} WARNING - /home/***/.local/lib/python3.9/site-packages/***/utils/sqlalchemy.py:124 DeprecationWarning: The sql_alchemy_conn option in [core] has been moved to the sql_alchemy_conn option in [database] - the old setting has been used, but please update your config.
[2023-09-22T16:52:46.265+0000] {local_task_job_runner.py:122} ERROR - Received SIGTERM. Terminating subprocesses
[2023-09-22T16:52:46.373+0000] {taskinstance.py:1568} INFO - Exporting env vars: AIRFLOW_CTX_DAG_OWNER='coder2j' AIRFLOW_CTX_DAG_ID='dag_with_taskflow_api_v02' AIRFLOW_CTX_TASK_ID='greet' AIRFLOW_CTX_EXECUTION_DATE='2021-11-15T00:00:00+00:00' AIRFLOW_CTX_TRY_NUMBER='1' AIRFLOW_CTX_DAG_RUN_ID='scheduled__2021-11-15T00:00:00+00:00'
[2023-09-22T16:52:46.378+0000] {process_utils.py:131} INFO - Sending Signals.SIGTERM to group 622. PIDs of all processes in the group: [622]
[2023-09-22T16:52:46.447+0000] {logging_mixin.py:149} INFO - Hello World! My name is Jerry Fridman and I am 19 years old!
[2023-09-22T16:52:46.516+0000] {process_utils.py:86} INFO - Sending the signal Signals.SIGTERM to group 622
[2023-09-22T16:52:46.520+0000] {python.py:183} INFO - Done. Returned value was: None
[2023-09-22T16:52:46.555+0000] {taskinstance.py:1847} ERROR - Task failed with exception
Traceback (most recent call last):
  File "/usr/local/lib/python3.9/logging/__init__.py", line 1087, in emit
    self.flush()
  File "/usr/local/lib/python3.9/logging/__init__.py", line 1067, in flush
    self.stream.flush()
RuntimeError: reentrant call inside <_io.BufferedWriter name='/opt/***/logs/dag_id=dag_with_taskflow_api_v02/run_id=scheduled__2021-11-15T00:00:00+00:00/task_id=greet/attempt=1.log'>

During handling of the above exception, another exception occurred:

Traceback (most recent call last):
  File "/usr/local/lib/python3.9/logging/__init__.py", line 1087, in emit
    self.flush()
  File "/usr/local/lib/python3.9/logging/__init__.py", line 1067, in flush
    self.stream.flush()
RuntimeError: reentrant call inside <_io.BufferedWriter name='/opt/***/logs/dag_id=dag_with_taskflow_api_v02/run_id=scheduled__2021-11-15T00:00:00+00:00/task_id=greet/attempt=1.log'>

During handling of the above exception, another exception occurred:

Traceback (most recent call last):
  File "/usr/local/lib/python3.9/logging/__init__.py", line 1087, in emit
    self.flush()
  File "/usr/local/lib/python3.9/logging/__init__.py", line 1067, in flush
    self.stream.flush()
RuntimeError: reentrant call inside <_io.BufferedWriter name='/opt/***/logs/dag_id=dag_with_taskflow_api_v02/run_id=scheduled__2021-11-15T00:00:00+00:00/task_id=greet/attempt=1.log'>

During handling of the above exception, another exception occurred:

Traceback (most recent call last):
  File "/usr/local/lib/python3.9/logging/__init__.py", line 1087, in emit
    self.flush()
  File "/usr/local/lib/python3.9/logging/__init__.py", line 1067, in flush
    self.stream.flush()
RuntimeError: reentrant call inside <_io.BufferedWriter name='/opt/***/logs/dag_id=dag_with_taskflow_api_v02/run_id=scheduled__2021-11-15T00:00:00+00:00/task_id=greet/attempt=1.log'>

During handling of the above exception, another exception occurred:

Traceback (most recent call last):
  File "/usr/local/lib/python3.9/logging/__init__.py", line 1087, in emit
    self.flush()
  File "/usr/local/lib/python3.9/logging/__init__.py", line 1067, in flush
    self.stream.flush()
RuntimeError: reentrant call inside <_io.BufferedWriter name='/opt/***/logs/dag_id=dag_with_taskflow_api_v02/run_id=scheduled__2021-11-15T00:00:00+00:00/task_id=greet/attempt=1.log'>

During handling of the above exception, another exception occurred:

Traceback (most recent call last):
  File "/usr/local/lib/python3.9/logging/__init__.py", line 1087, in emit
    self.flush()
  File "/usr/local/lib/python3.9/logging/__init__.py", line 1067, in flush
    self.stream.flush()
RuntimeError: reentrant call inside <_io.BufferedWriter name='/opt/***/logs/dag_id=dag_with_taskflow_api_v02/run_id=scheduled__2021-11-15T00:00:00+00:00/task_id=greet/attempt=1.log'>

During handling of the above exception, another exception occurred:

Traceback (most recent call last):
  File "/usr/local/lib/python3.9/logging/__init__.py", line 1087, in emit
    self.flush()
  File "/usr/local/lib/python3.9/logging/__init__.py", line 1067, in flush
    self.stream.flush()
RuntimeError: reentrant call inside <_io.BufferedWriter name='/opt/***/logs/dag_id=dag_with_taskflow_api_v02/run_id=scheduled__2021-11-15T00:00:00+00:00/task_id=greet/attempt=1.log'>

During handling of the above exception, another exception occurred:

Traceback (most recent call last):
  File "/usr/local/lib/python3.9/logging/__init__.py", line 1087, in emit
    self.flush()
  File "/usr/local/lib/python3.9/logging/__init__.py", line 1067, in flush
    self.stream.flush()
RuntimeError: reentrant call inside <_io.BufferedWriter name='/opt/***/logs/dag_id=dag_with_taskflow_api_v02/run_id=scheduled__2021-11-15T00:00:00+00:00/task_id=greet/attempt=1.log'>

During handling of the above exception, another exception occurred:

Traceback (most recent call last):
  File "/usr/local/lib/python3.9/logging/__init__.py", line 1087, in emit
    self.flush()
  File "/usr/local/lib/python3.9/logging/__init__.py", line 1067, in flush
    self.stream.flush()
RuntimeError: reentrant call inside <_io.BufferedWriter name='/opt/***/logs/dag_id=dag_with_taskflow_api_v02/run_id=scheduled__2021-11-15T00:00:00+00:00/task_id=greet/attempt=1.log'>

During handling of the above exception, another exception occurred:

Traceback (most recent call last):
  File "/usr/local/lib/python3.9/logging/__init__.py", line 1087, in emit
    self.flush()
  File "/usr/local/lib/python3.9/logging/__init__.py", line 1067, in flush
    self.stream.flush()
RuntimeError: reentrant call inside <_io.BufferedWriter name='/opt/***/logs/dag_id=dag_with_taskflow_api_v02/run_id=scheduled__2021-11-15T00:00:00+00:00/task_id=greet/attempt=1.log'>

During handling of the above exception, another exception occurred:

Traceback (most recent call last):
  File "/usr/local/lib/python3.9/logging/__init__.py", line 1087, in emit
    self.flush()
  File "/usr/local/lib/python3.9/logging/__init__.py", line 1067, in flush
    self.stream.flush()
RuntimeError: reentrant call inside <_io.BufferedWriter name='/opt/***/logs/dag_id=dag_with_taskflow_api_v02/run_id=scheduled__2021-11-15T00:00:00+00:00/task_id=greet/attempt=1.log'>

During handling of the above exception, another exception occurred:

Traceback (most recent call last):
  File "/usr/local/lib/python3.9/logging/__init__.py", line 1087, in emit
    self.flush()
  File "/usr/local/lib/python3.9/logging/__init__.py", line 1067, in flush
    self.stream.flush()
RuntimeError: reentrant call inside <_io.BufferedWriter name='/opt/***/logs/dag_id=dag_with_taskflow_api_v02/run_id=scheduled__2021-11-15T00:00:00+00:00/task_id=greet/attempt=1.log'>

During handling of the above exception, another exception occurred:

Traceback (most recent call last):
  File "/usr/local/lib/python3.9/logging/__init__.py", line 1087, in emit
    self.flush()
  File "/usr/local/lib/python3.9/logging/__init__.py", line 1067, in flush
    self.stream.flush()
RuntimeError: reentrant call inside <_io.BufferedWriter name='/opt/***/logs/dag_id=dag_with_taskflow_api_v02/run_id=scheduled__2021-11-15T00:00:00+00:00/task_id=greet/attempt=1.log'>

During handling of the above exception, another exception occurred:

Traceback (most recent call last):
  File "/usr/local/lib/python3.9/logging/__init__.py", line 1087, in emit
    self.flush()
  File "/usr/local/lib/python3.9/logging/__init__.py", line 1067, in flush
    self.stream.flush()
RuntimeError: reentrant call inside <_io.BufferedWriter name='/opt/***/logs/dag_id=dag_with_taskflow_api_v02/run_id=scheduled__2021-11-15T00:00:00+00:00/task_id=greet/attempt=1.log'>

During handling of the above exception, another exception occurred:

Traceback (most recent call last):
  File "/usr/local/lib/python3.9/logging/__init__.py", line 1087, in emit
    self.flush()
  File "/usr/local/lib/python3.9/logging/__init__.py", line 1067, in flush
    self.stream.flush()
RuntimeError: reentrant call inside <_io.BufferedWriter name='/opt/***/logs/dag_id=dag_with_taskflow_api_v02/run_id=scheduled__2021-11-15T00:00:00+00:00/task_id=greet/attempt=1.log'>

During handling of the above exception, another exception occurred:

Traceback (most recent call last):
  File "/usr/local/lib/python3.9/logging/__init__.py", line 1087, in emit
    self.flush()
  File "/usr/local/lib/python3.9/logging/__init__.py", line 1067, in flush
    self.stream.flush()
RuntimeError: reentrant call inside <_io.BufferedWriter name='/opt/***/logs/dag_id=dag_with_taskflow_api_v02/run_id=scheduled__2021-11-15T00:00:00+00:00/task_id=greet/attempt=1.log'>

During handling of the above exception, another exception occurred:

Traceback (most recent call last):
  File "/usr/local/lib/python3.9/logging/__init__.py", line 1087, in emit
    self.flush()
  File "/usr/local/lib/python3.9/logging/__init__.py", line 1067, in flush
    self.stream.flush()
RuntimeError: reentrant call inside <_io.BufferedWriter name='/opt/***/logs/dag_id=dag_with_taskflow_api_v02/run_id=scheduled__2021-11-15T00:00:00+00:00/task_id=greet/attempt=1.log'>

During handling of the above exception, another exception occurred:

Traceback (most recent call last):
  File "/usr/local/lib/python3.9/logging/__init__.py", line 1087, in emit
    self.flush()
  File "/usr/local/lib/python3.9/logging/__init__.py", line 1067, in flush
    self.stream.flush()
RuntimeError: reentrant call inside <_io.BufferedWriter name='/opt/***/logs/dag_id=dag_with_taskflow_api_v02/run_id=scheduled__2021-11-15T00:00:00+00:00/task_id=greet/attempt=1.log'>

During handling of the above exception, another exception occurred:

Traceback (most recent call last):
  File "/usr/local/lib/python3.9/logging/__init__.py", line 1087, in emit
    self.flush()
  File "/usr/local/lib/python3.9/logging/__init__.py", line 1067, in flush
    self.stream.flush()
RuntimeError: reentrant call inside <_io.BufferedWriter name='/opt/***/logs/dag_id=dag_with_taskflow_api_v02/run_id=scheduled__2021-11-15T00:00:00+00:00/task_id=greet/attempt=1.log'>

During handling of the above exception, another exception occurred:

Traceback (most recent call last):
  File "/usr/local/lib/python3.9/logging/__init__.py", line 1087, in emit
    self.flush()
  File "/usr/local/lib/python3.9/logging/__init__.py", line 1067, in flush
    self.stream.flush()
RuntimeError: reentrant call inside <_io.BufferedWriter name='/opt/***/logs/dag_id=dag_with_taskflow_api_v02/run_id=scheduled__2021-11-15T00:00:00+00:00/task_id=greet/attempt=1.log'>

During handling of the above exception, another exception occurred:

Traceback (most recent call last):
  File "/usr/local/lib/python3.9/logging/__init__.py", line 1087, in emit
    self.flush()
  File "/usr/local/lib/python3.9/logging/__init__.py", line 1067, in flush
    self.stream.flush()
RuntimeError: reentrant call inside <_io.BufferedWriter name='/opt/***/logs/dag_id=dag_with_taskflow_api_v02/run_id=scheduled__2021-11-15T00:00:00+00:00/task_id=greet/attempt=1.log'>

During handling of the above exception, another exception occurred:

Traceback (most recent call last):
  File "/usr/local/lib/python3.9/logging/__init__.py", line 1087, in emit
    self.flush()
  File "/usr/local/lib/python3.9/logging/__init__.py", line 1067, in flush
    self.stream.flush()
RuntimeError: reentrant call inside <_io.BufferedWriter name='/opt/***/logs/dag_id=dag_with_taskflow_api_v02/run_id=scheduled__2021-11-15T00:00:00+00:00/task_id=greet/attempt=1.log'>

During handling of the above exception, another exception occurred:

Traceback (most recent call last):
  File "/usr/local/lib/python3.9/logging/__init__.py", line 1087, in emit
    self.flush()
  File "/usr/local/lib/python3.9/logging/__init__.py", line 1067, in flush
    self.stream.flush()
RuntimeError: reentrant call inside <_io.BufferedWriter name='/opt/***/logs/dag_id=dag_with_taskflow_api_v02/run_id=scheduled__2021-11-15T00:00:00+00:00/task_id=greet/attempt=1.log'>

During handling of the above exception, another exception occurred:

Traceback (most recent call last):
  File "/usr/local/lib/python3.9/logging/__init__.py", line 1087, in emit
    self.flush()
  File "/usr/local/lib/python3.9/logging/__init__.py", line 1067, in flush
    self.stream.flush()
RuntimeError: reentrant call inside <_io.BufferedWriter name='/opt/***/logs/dag_id=dag_with_taskflow_api_v02/run_id=scheduled__2021-11-15T00:00:00+00:00/task_id=greet/attempt=1.log'>

During handling of the above exception, another exception occurred:

Traceback (most recent call last):
  File "/usr/local/lib/python3.9/logging/__init__.py", line 1087, in emit
    self.flush()
  File "/usr/local/lib/python3.9/logging/__init__.py", line 1067, in flush
    self.stream.flush()
RuntimeError: reentrant call inside <_io.BufferedWriter name='/opt/***/logs/dag_id=dag_with_taskflow_api_v02/run_id=scheduled__2021-11-15T00:00:00+00:00/task_id=greet/attempt=1.log'>

During handling of the above exception, another exception occurred:

Traceback (most recent call last):
  File "/usr/local/lib/python3.9/logging/__init__.py", line 1087, in emit
    self.flush()
  File "/usr/local/lib/python3.9/logging/__init__.py", line 1067, in flush
    self.stream.flush()
RuntimeError: reentrant call inside <_io.BufferedWriter name='/opt/***/logs/dag_id=dag_with_taskflow_api_v02/run_id=scheduled__2021-11-15T00:00:00+00:00/task_id=greet/attempt=1.log'>

During handling of the above exception, another exception occurred:

Traceback (most recent call last):
  File "/usr/local/lib/python3.9/logging/__init__.py", line 1087, in emit
    self.flush()
  File "/usr/local/lib/python3.9/logging/__init__.py", line 1067, in flush
    self.stream.flush()
RuntimeError: reentrant call inside <_io.BufferedWriter name='/opt/***/logs/dag_id=dag_with_taskflow_api_v02/run_id=scheduled__2021-11-15T00:00:00+00:00/task_id=greet/attempt=1.log'>

During handling of the above exception, another exception occurred:

Traceback (most recent call last):
  File "/usr/local/lib/python3.9/logging/__init__.py", line 1087, in emit
    self.flush()
  File "/usr/local/lib/python3.9/logging/__init__.py", line 1067, in flush
    self.stream.flush()
RuntimeError: reentrant call inside <_io.BufferedWriter name='/opt/***/logs/dag_id=dag_with_taskflow_api_v02/run_id=scheduled__2021-11-15T00:00:00+00:00/task_id=greet/attempt=1.log'>

During handling of the above exception, another exception occurred:

Traceback (most recent call last):
  File "/usr/local/lib/python3.9/logging/__init__.py", line 1087, in emit
    self.flush()
  File "/usr/local/lib/python3.9/logging/__init__.py", line 1067, in flush
    self.stream.flush()
RuntimeError: reentrant call inside <_io.BufferedWriter name='/opt/***/logs/dag_id=dag_with_taskflow_api_v02/run_id=scheduled__2021-11-15T00:00:00+00:00/task_id=greet/attempt=1.log'>

During handling of the above exception, another exception occurred:

Traceback (most recent call last):
  File "/usr/local/lib/python3.9/logging/__init__.py", line 1087, in emit
    self.flush()
  File "/usr/local/lib/python3.9/logging/__init__.py", line 1067, in flush
    self.stream.flush()
RuntimeError: reentrant call inside <_io.BufferedWriter name='/opt/***/logs/dag_id=dag_with_taskflow_api_v02/run_id=scheduled__2021-11-15T00:00:00+00:00/task_id=greet/attempt=1.log'>

During handling of the above exception, another exception occurred:

Traceback (most recent call last):
  File "/usr/local/lib/python3.9/logging/__init__.py", line 1087, in emit
    self.flush()
  File "/usr/local/lib/python3.9/logging/__init__.py", line 1067, in flush
    self.stream.flush()
RuntimeError: reentrant call inside <_io.BufferedWriter name='/opt/***/logs/dag_id=dag_with_taskflow_api_v02/run_id=scheduled__2021-11-15T00:00:00+00:00/task_id=greet/attempt=1.log'>

During handling of the above exception, another exception occurred:

Traceback (most recent call last):
  File "/usr/local/lib/python3.9/logging/__init__.py", line 1087, in emit
    self.flush()
  File "/usr/local/lib/python3.9/logging/__init__.py", line 1067, in flush
    self.stream.flush()
RuntimeError: reentrant call inside <_io.BufferedWriter name='/opt/***/logs/dag_id=dag_with_taskflow_api_v02/run_id=scheduled__2021-11-15T00:00:00+00:00/task_id=greet/attempt=1.log'>

During handling of the above exception, another exception occurred:

Traceback (most recent call last):
  File "/usr/local/lib/python3.9/logging/__init__.py", line 1087, in emit
    self.flush()
  File "/usr/local/lib/python3.9/logging/__init__.py", line 1067, in flush
    self.stream.flush()
RuntimeError: reentrant call inside <_io.BufferedWriter name='/opt/***/logs/dag_id=dag_with_taskflow_api_v02/run_id=scheduled__2021-11-15T00:00:00+00:00/task_id=greet/attempt=1.log'>

During handling of the above exception, another exception occurred:

Traceback (most recent call last):
  File "/usr/local/lib/python3.9/logging/__init__.py", line 1087, in emit
    self.flush()
  File "/usr/local/lib/python3.9/logging/__init__.py", line 1067, in flush
    self.stream.flush()
RuntimeError: reentrant call inside <_io.BufferedWriter name='/opt/***/logs/dag_id=dag_with_taskflow_api_v02/run_id=scheduled__2021-11-15T00:00:00+00:00/task_id=greet/attempt=1.log'>

During handling of the above exception, another exception occurred:

Traceback (most recent call last):
  File "/usr/local/lib/python3.9/logging/__init__.py", line 1087, in emit
    self.flush()
  File "/usr/local/lib/python3.9/logging/__init__.py", line 1067, in flush
    self.stream.flush()
RuntimeError: reentrant call inside <_io.BufferedWriter name='/opt/***/logs/dag_id=dag_with_taskflow_api_v02/run_id=scheduled__2021-11-15T00:00:00+00:00/task_id=greet/attempt=1.log'>

During handling of the above exception, another exception occurred:

Traceback (most recent call last):
  File "/usr/local/lib/python3.9/logging/__init__.py", line 1087, in emit
    self.flush()
  File "/usr/local/lib/python3.9/logging/__init__.py", line 1067, in flush
    self.stream.flush()
RuntimeError: reentrant call inside <_io.BufferedWriter name='/opt/***/logs/dag_id=dag_with_taskflow_api_v02/run_id=scheduled__2021-11-15T00:00:00+00:00/task_id=greet/attempt=1.log'>

During handling of the above exception, another exception occurred:

Traceback (most recent call last):
  File "/usr/local/lib/python3.9/logging/__init__.py", line 1087, in emit
    self.flush()
  File "/usr/local/lib/python3.9/logging/__init__.py", line 1067, in flush
    self.stream.flush()
RuntimeError: reentrant call inside <_io.BufferedWriter name='/opt/***/logs/dag_id=dag_with_taskflow_api_v02/run_id=scheduled__2021-11-15T00:00:00+00:00/task_id=greet/attempt=1.log'>

During handling of the above exception, another exception occurred:

Traceback (most recent call last):
  File "/usr/local/lib/python3.9/logging/__init__.py", line 1087, in emit
    self.flush()
  File "/usr/local/lib/python3.9/logging/__init__.py", line 1067, in flush
    self.stream.flush()
RuntimeError: reentrant call inside <_io.BufferedWriter name='/opt/***/logs/dag_id=dag_with_taskflow_api_v02/run_id=scheduled__2021-11-15T00:00:00+00:00/task_id=greet/attempt=1.log'>

During handling of the above exception, another exception occurred:

Traceback (most recent call last):
  File "/usr/local/lib/python3.9/logging/__init__.py", line 1087, in emit
    self.flush()
  File "/usr/local/lib/python3.9/logging/__init__.py", line 1067, in flush
    self.stream.flush()
RuntimeError: reentrant call inside <_io.BufferedWriter name='/opt/***/logs/dag_id=dag_with_taskflow_api_v02/run_id=scheduled__2021-11-15T00:00:00+00:00/task_id=greet/attempt=1.log'>

During handling of the above exception, another exception occurred:

Traceback (most recent call last):
  File "/usr/local/lib/python3.9/logging/__init__.py", line 1087, in emit
    self.flush()
  File "/usr/local/lib/python3.9/logging/__init__.py", line 1067, in flush
    self.stream.flush()
RuntimeError: reentrant call inside <_io.BufferedWriter name='/opt/***/logs/dag_id=dag_with_taskflow_api_v02/run_id=scheduled__2021-11-15T00:00:00+00:00/task_id=greet/attempt=1.log'>

During handling of the above exception, another exception occurred:

Traceback (most recent call last):
  File "/usr/local/lib/python3.9/logging/__init__.py", line 1087, in emit
    self.flush()
  File "/usr/local/lib/python3.9/logging/__init__.py", line 1067, in flush
    self.stream.flush()
RuntimeError: reentrant call inside <_io.BufferedWriter name='/opt/***/logs/dag_id=dag_with_taskflow_api_v02/run_id=scheduled__2021-11-15T00:00:00+00:00/task_id=greet/attempt=1.log'>

During handling of the above exception, another exception occurred:

Traceback (most recent call last):
  File "/usr/local/lib/python3.9/logging/__init__.py", line 1087, in emit
    self.flush()
  File "/usr/local/lib/python3.9/logging/__init__.py", line 1067, in flush
    self.stream.flush()
RuntimeError: reentrant call inside <_io.BufferedWriter name='/opt/***/logs/dag_id=dag_with_taskflow_api_v02/run_id=scheduled__2021-11-15T00:00:00+00:00/task_id=greet/attempt=1.log'>

During handling of the above exception, another exception occurred:

Traceback (most recent call last):
  File "/usr/local/lib/python3.9/logging/__init__.py", line 1087, in emit
    self.flush()
  File "/usr/local/lib/python3.9/logging/__init__.py", line 1067, in flush
    self.stream.flush()
RuntimeError: reentrant call inside <_io.BufferedWriter name='/opt/***/logs/dag_id=dag_with_taskflow_api_v02/run_id=scheduled__2021-11-15T00:00:00+00:00/task_id=greet/attempt=1.log'>

During handling of the above exception, another exception occurred:

Traceback (most recent call last):
  File "/usr/local/lib/python3.9/logging/__init__.py", line 1087, in emit
    self.flush()
  File "/usr/local/lib/python3.9/logging/__init__.py", line 1067, in flush
    self.stream.flush()
RuntimeError: reentrant call inside <_io.BufferedWriter name='/opt/***/logs/dag_id=dag_with_taskflow_api_v02/run_id=scheduled__2021-11-15T00:00:00+00:00/task_id=greet/attempt=1.log'>

During handling of the above exception, another exception occurred:

Traceback (most recent call last):
  File "/usr/local/lib/python3.9/logging/__init__.py", line 1087, in emit
    self.flush()
  File "/usr/local/lib/python3.9/logging/__init__.py", line 1067, in flush
    self.stream.flush()
RuntimeError: reentrant call inside <_io.BufferedWriter name='/opt/***/logs/dag_id=dag_with_taskflow_api_v02/run_id=scheduled__2021-11-15T00:00:00+00:00/task_id=greet/attempt=1.log'>

During handling of the above exception, another exception occurred:

Traceback (most recent call last):
  File "/usr/local/lib/python3.9/logging/__init__.py", line 1087, in emit
    self.flush()
  File "/usr/local/lib/python3.9/logging/__init__.py", line 1067, in flush
    self.stream.flush()
RuntimeError: reentrant call inside <_io.BufferedWriter name='/opt/***/logs/dag_id=dag_with_taskflow_api_v02/run_id=scheduled__2021-11-15T00:00:00+00:00/task_id=greet/attempt=1.log'>

During handling of the above exception, another exception occurred:

Traceback (most recent call last):
  File "/usr/local/lib/python3.9/logging/__init__.py", line 1087, in emit
    self.flush()
  File "/usr/local/lib/python3.9/logging/__init__.py", line 1067, in flush
    self.stream.flush()
RuntimeError: reentrant call inside <_io.BufferedWriter name='/opt/***/logs/dag_id=dag_with_taskflow_api_v02/run_id=scheduled__2021-11-15T00:00:00+00:00/task_id=greet/attempt=1.log'>

During handling of the above exception, another exception occurred:

Traceback (most recent call last):
  File "/usr/local/lib/python3.9/logging/__init__.py", line 1087, in emit
    self.flush()
  File "/usr/local/lib/python3.9/logging/__init__.py", line 1067, in flush
    self.stream.flush()
RuntimeError: reentrant call inside <_io.BufferedWriter name='/opt/***/logs/dag_id=dag_with_taskflow_api_v02/run_id=scheduled__2021-11-15T00:00:00+00:00/task_id=greet/attempt=1.log'>

During handling of the above exception, another exception occurred:

Traceback (most recent call last):
  File "/usr/local/lib/python3.9/logging/__init__.py", line 1087, in emit
    self.flush()
  File "/usr/local/lib/python3.9/logging/__init__.py", line 1067, in flush
    self.stream.flush()
RuntimeError: reentrant call inside <_io.BufferedWriter name='/opt/***/logs/dag_id=dag_with_taskflow_api_v02/run_id=scheduled__2021-11-15T00:00:00+00:00/task_id=greet/attempt=1.log'>

During handling of the above exception, another exception occurred:

Traceback (most recent call last):
  File "/usr/local/lib/python3.9/logging/__init__.py", line 1087, in emit
    self.flush()
  File "/usr/local/lib/python3.9/logging/__init__.py", line 1067, in flush
    self.stream.flush()
RuntimeError: reentrant call inside <_io.BufferedWriter name='/opt/***/logs/dag_id=dag_with_taskflow_api_v02/run_id=scheduled__2021-11-15T00:00:00+00:00/task_id=greet/attempt=1.log'>

During handling of the above exception, another exception occurred:

Traceback (most recent call last):
  File "/usr/local/lib/python3.9/logging/__init__.py", line 1087, in emit
    self.flush()
  File "/usr/local/lib/python3.9/logging/__init__.py", line 1067, in flush
    self.stream.flush()
RuntimeError: reentrant call inside <_io.BufferedWriter name='/opt/***/logs/dag_id=dag_with_taskflow_api_v02/run_id=scheduled__2021-11-15T00:00:00+00:00/task_id=greet/attempt=1.log'>

During handling of the above exception, another exception occurred:

Traceback (most recent call last):
  File "/usr/local/lib/python3.9/logging/__init__.py", line 1087, in emit
    self.flush()
  File "/usr/local/lib/python3.9/logging/__init__.py", line 1067, in flush
    self.stream.flush()
RuntimeError: reentrant call inside <_io.BufferedWriter name='/opt/***/logs/dag_id=dag_with_taskflow_api_v02/run_id=scheduled__2021-11-15T00:00:00+00:00/task_id=greet/attempt=1.log'>

During handling of the above exception, another exception occurred:

Traceback (most recent call last):
  File "/usr/local/lib/python3.9/logging/__init__.py", line 1087, in emit
    self.flush()
  File "/usr/local/lib/python3.9/logging/__init__.py", line 1067, in flush
    self.stream.flush()
RuntimeError: reentrant call inside <_io.BufferedWriter name='/opt/***/logs/dag_id=dag_with_taskflow_api_v02/run_id=scheduled__2021-11-15T00:00:00+00:00/task_id=greet/attempt=1.log'>

During handling of the above exception, another exception occurred:

Traceback (most recent call last):
  File "/usr/local/lib/python3.9/logging/__init__.py", line 1087, in emit
    self.flush()
  File "/usr/local/lib/python3.9/logging/__init__.py", line 1067, in flush
    self.stream.flush()
RuntimeError: reentrant call inside <_io.BufferedWriter name='/opt/***/logs/dag_id=dag_with_taskflow_api_v02/run_id=scheduled__2021-11-15T00:00:00+00:00/task_id=greet/attempt=1.log'>

During handling of the above exception, another exception occurred:

Traceback (most recent call last):
  File "/usr/local/lib/python3.9/logging/__init__.py", line 1087, in emit
    self.flush()
  File "/usr/local/lib/python3.9/logging/__init__.py", line 1067, in flush
    self.stream.flush()
RuntimeError: reentrant call inside <_io.BufferedWriter name='/opt/***/logs/dag_id=dag_with_taskflow_api_v02/run_id=scheduled__2021-11-15T00:00:00+00:00/task_id=greet/attempt=1.log'>

During handling of the above exception, another exception occurred:

Traceback (most recent call last):
  File "/usr/local/lib/python3.9/logging/__init__.py", line 1087, in emit
    self.flush()
  File "/usr/local/lib/python3.9/logging/__init__.py", line 1067, in flush
    self.stream.flush()
RuntimeError: reentrant call inside <_io.BufferedWriter name='/opt/***/logs/dag_id=dag_with_taskflow_api_v02/run_id=scheduled__2021-11-15T00:00:00+00:00/task_id=greet/attempt=1.log'>

During handling of the above exception, another exception occurred:

Traceback (most recent call last):
  File "/usr/local/lib/python3.9/logging/__init__.py", line 1087, in emit
    self.flush()
  File "/usr/local/lib/python3.9/logging/__init__.py", line 1067, in flush
    self.stream.flush()
RuntimeError: reentrant call inside <_io.BufferedWriter name='/opt/***/logs/dag_id=dag_with_taskflow_api_v02/run_id=scheduled__2021-11-15T00:00:00+00:00/task_id=greet/attempt=1.log'>

During handling of the above exception, another exception occurred:

Traceback (most recent call last):
  File "/usr/local/lib/python3.9/logging/__init__.py", line 1087, in emit
    self.flush()
  File "/usr/local/lib/python3.9/logging/__init__.py", line 1067, in flush
    self.stream.flush()
RuntimeError: reentrant call inside <_io.BufferedWriter name='/opt/***/logs/dag_id=dag_with_taskflow_api_v02/run_id=scheduled__2021-11-15T00:00:00+00:00/task_id=greet/attempt=1.log'>

During handling of the above exception, another exception occurred:

Traceback (most recent call last):
  File "/usr/local/lib/python3.9/logging/__init__.py", line 1087, in emit
    self.flush()
  File "/usr/local/lib/python3.9/logging/__init__.py", line 1067, in flush
    self.stream.flush()
RuntimeError: reentrant call inside <_io.BufferedWriter name='/opt/***/logs/dag_id=dag_with_taskflow_api_v02/run_id=scheduled__2021-11-15T00:00:00+00:00/task_id=greet/attempt=1.log'>

During handling of the above exception, another exception occurred:

Traceback (most recent call last):
  File "/usr/local/lib/python3.9/logging/__init__.py", line 1087, in emit
    self.flush()
  File "/usr/local/lib/python3.9/logging/__init__.py", line 1067, in flush
    self.stream.flush()
RuntimeError: reentrant call inside <_io.BufferedWriter name='/opt/***/logs/dag_id=dag_with_taskflow_api_v02/run_id=scheduled__2021-11-15T00:00:00+00:00/task_id=greet/attempt=1.log'>

During handling of the above exception, another exception occurred:

Traceback (most recent call last):
  File "/usr/local/lib/python3.9/logging/__init__.py", line 1087, in emit
    self.flush()
  File "/usr/local/lib/python3.9/logging/__init__.py", line 1067, in flush
    self.stream.flush()
RuntimeError: reentrant call inside <_io.BufferedWriter name='/opt/***/logs/dag_id=dag_with_taskflow_api_v02/run_id=scheduled__2021-11-15T00:00:00+00:00/task_id=greet/attempt=1.log'>

During handling of the above exception, another exception occurred:

Traceback (most recent call last):
  File "/usr/local/lib/python3.9/logging/__init__.py", line 1087, in emit
    self.flush()
  File "/usr/local/lib/python3.9/logging/__init__.py", line 1067, in flush
    self.stream.flush()
RuntimeError: reentrant call inside <_io.BufferedWriter name='/opt/***/logs/dag_id=dag_with_taskflow_api_v02/run_id=scheduled__2021-11-15T00:00:00+00:00/task_id=greet/attempt=1.log'>

During handling of the above exception, another exception occurred:

Traceback (most recent call last):
  File "/usr/local/lib/python3.9/logging/__init__.py", line 1087, in emit
    self.flush()
  File "/usr/local/lib/python3.9/logging/__init__.py", line 1067, in flush
    self.stream.flush()
RuntimeError: reentrant call inside <_io.BufferedWriter name='/opt/***/logs/dag_id=dag_with_taskflow_api_v02/run_id=scheduled__2021-11-15T00:00:00+00:00/task_id=greet/attempt=1.log'>

During handling of the above exception, another exception occurred:

Traceback (most recent call last):
  File "/usr/local/lib/python3.9/logging/__init__.py", line 1087, in emit
    self.flush()
  File "/usr/local/lib/python3.9/logging/__init__.py", line 1067, in flush
    self.stream.flush()
RuntimeError: reentrant call inside <_io.BufferedWriter name='/opt/***/logs/dag_id=dag_with_taskflow_api_v02/run_id=scheduled__2021-11-15T00:00:00+00:00/task_id=greet/attempt=1.log'>

During handling of the above exception, another exception occurred:

Traceback (most recent call last):
  File "/usr/local/lib/python3.9/logging/__init__.py", line 1087, in emit
    self.flush()
  File "/usr/local/lib/python3.9/logging/__init__.py", line 1067, in flush
    self.stream.flush()
RuntimeError: reentrant call inside <_io.BufferedWriter name='/opt/***/logs/dag_id=dag_with_taskflow_api_v02/run_id=scheduled__2021-11-15T00:00:00+00:00/task_id=greet/attempt=1.log'>

During handling of the above exception, another exception occurred:

Traceback (most recent call last):
  File "/usr/local/lib/python3.9/logging/__init__.py", line 1087, in emit
    self.flush()
  File "/usr/local/lib/python3.9/logging/__init__.py", line 1067, in flush
    self.stream.flush()
RuntimeError: reentrant call inside <_io.BufferedWriter name='/opt/***/logs/dag_id=dag_with_taskflow_api_v02/run_id=scheduled__2021-11-15T00:00:00+00:00/task_id=greet/attempt=1.log'>

During handling of the above exception, another exception occurred:

Traceback (most recent call last):
  File "/usr/local/lib/python3.9/logging/__init__.py", line 1087, in emit
    self.flush()
  File "/usr/local/lib/python3.9/logging/__init__.py", line 1067, in flush
    self.stream.flush()
RuntimeError: reentrant call inside <_io.BufferedWriter name='/opt/***/logs/dag_id=dag_with_taskflow_api_v02/run_id=scheduled__2021-11-15T00:00:00+00:00/task_id=greet/attempt=1.log'>

During handling of the above exception, another exception occurred:

Traceback (most recent call last):
  File "/usr/local/lib/python3.9/logging/__init__.py", line 1087, in emit
    self.flush()
  File "/usr/local/lib/python3.9/logging/__init__.py", line 1067, in flush
    self.stream.flush()
RuntimeError: reentrant call inside <_io.BufferedWriter name='/opt/***/logs/dag_id=dag_with_taskflow_api_v02/run_id=scheduled__2021-11-15T00:00:00+00:00/task_id=greet/attempt=1.log'>

During handling of the above exception, another exception occurred:

Traceback (most recent call last):
  File "/usr/local/lib/python3.9/logging/__init__.py", line 1087, in emit
    self.flush()
  File "/usr/local/lib/python3.9/logging/__init__.py", line 1067, in flush
    self.stream.flush()
RuntimeError: reentrant call inside <_io.BufferedWriter name='/opt/***/logs/dag_id=dag_with_taskflow_api_v02/run_id=scheduled__2021-11-15T00:00:00+00:00/task_id=greet/attempt=1.log'>

During handling of the above exception, another exception occurred:

Traceback (most recent call last):
  File "/usr/local/lib/python3.9/logging/__init__.py", line 1087, in emit
    self.flush()
  File "/usr/local/lib/python3.9/logging/__init__.py", line 1067, in flush
    self.stream.flush()
RuntimeError: reentrant call inside <_io.BufferedWriter name='/opt/***/logs/dag_id=dag_with_taskflow_api_v02/run_id=scheduled__2021-11-15T00:00:00+00:00/task_id=greet/attempt=1.log'>

During handling of the above exception, another exception occurred:

Traceback (most recent call last):
  File "/usr/local/lib/python3.9/logging/__init__.py", line 1087, in emit
    self.flush()
  File "/usr/local/lib/python3.9/logging/__init__.py", line 1067, in flush
    self.stream.flush()
RuntimeError: reentrant call inside <_io.BufferedWriter name='/opt/***/logs/dag_id=dag_with_taskflow_api_v02/run_id=scheduled__2021-11-15T00:00:00+00:00/task_id=greet/attempt=1.log'>

During handling of the above exception, another exception occurred:

Traceback (most recent call last):
  File "/usr/local/lib/python3.9/logging/__init__.py", line 1087, in emit
    self.flush()
  File "/usr/local/lib/python3.9/logging/__init__.py", line 1067, in flush
    self.stream.flush()
RuntimeError: reentrant call inside <_io.BufferedWriter name='/opt/***/logs/dag_id=dag_with_taskflow_api_v02/run_id=scheduled__2021-11-15T00:00:00+00:00/task_id=greet/attempt=1.log'>

During handling of the above exception, another exception occurred:

Traceback (most recent call last):
  File "/usr/local/lib/python3.9/logging/__init__.py", line 1087, in emit
    self.flush()
  File "/usr/local/lib/python3.9/logging/__init__.py", line 1067, in flush
    self.stream.flush()
RuntimeError: reentrant call inside <_io.BufferedWriter name='/opt/***/logs/dag_id=dag_with_taskflow_api_v02/run_id=scheduled__2021-11-15T00:00:00+00:00/task_id=greet/attempt=1.log'>

During handling of the above exception, another exception occurred:

Traceback (most recent call last):
  File "/usr/local/lib/python3.9/logging/__init__.py", line 1087, in emit
    self.flush()
  File "/usr/local/lib/python3.9/logging/__init__.py", line 1067, in flush
    self.stream.flush()
RuntimeError: reentrant call inside <_io.BufferedWriter name='/opt/***/logs/dag_id=dag_with_taskflow_api_v02/run_id=scheduled__2021-11-15T00:00:00+00:00/task_id=greet/attempt=1.log'>

During handling of the above exception, another exception occurred:

Traceback (most recent call last):
  File "/usr/local/lib/python3.9/logging/__init__.py", line 1087, in emit
    self.flush()
  File "/usr/local/lib/python3.9/logging/__init__.py", line 1067, in flush
    self.stream.flush()
RuntimeError: reentrant call inside <_io.BufferedWriter name='/opt/***/logs/dag_id=dag_with_taskflow_api_v02/run_id=scheduled__2021-11-15T00:00:00+00:00/task_id=greet/attempt=1.log'>

During handling of the above exception, another exception occurred:

Traceback (most recent call last):
  File "/usr/local/lib/python3.9/logging/__init__.py", line 1087, in emit
    self.flush()
  File "/usr/local/lib/python3.9/logging/__init__.py", line 1067, in flush
    self.stream.flush()
RuntimeError: reentrant call inside <_io.BufferedWriter name='/opt/***/logs/dag_id=dag_with_taskflow_api_v02/run_id=scheduled__2021-11-15T00:00:00+00:00/task_id=greet/attempt=1.log'>

During handling of the above exception, another exception occurred:

Traceback (most recent call last):
  File "/usr/local/lib/python3.9/logging/__init__.py", line 1087, in emit
    self.flush()
  File "/usr/local/lib/python3.9/logging/__init__.py", line 1067, in flush
    self.stream.flush()
RuntimeError: reentrant call inside <_io.BufferedWriter name='/opt/***/logs/dag_id=dag_with_taskflow_api_v02/run_id=scheduled__2021-11-15T00:00:00+00:00/task_id=greet/attempt=1.log'>

During handling of the above exception, another exception occurred:

Traceback (most recent call last):
  File "/usr/local/lib/python3.9/logging/__init__.py", line 1087, in emit
    self.flush()
  File "/usr/local/lib/python3.9/logging/__init__.py", line 1067, in flush
    self.stream.flush()
RuntimeError: reentrant call inside <_io.BufferedWriter name='/opt/***/logs/dag_id=dag_with_taskflow_api_v02/run_id=scheduled__2021-11-15T00:00:00+00:00/task_id=greet/attempt=1.log'>

During handling of the above exception, another exception occurred:

Traceback (most recent call last):
  File "/home/airflow/.local/lib/python3.9/site-packages/airflow/decorators/base.py", line 220, in execute
    return_value = super().execute(context)
  File "/home/airflow/.local/lib/python3.9/site-packages/airflow/operators/python.py", line 183, in execute
    self.log.info("Done. Returned value was: %s", return_value)
  File "/usr/local/lib/python3.9/logging/__init__.py", line 1446, in info
    self._log(INFO, msg, args, **kwargs)
  File "/usr/local/lib/python3.9/logging/__init__.py", line 1589, in _log
    self.handle(record)
  File "/usr/local/lib/python3.9/logging/__init__.py", line 1599, in handle
    self.callHandlers(record)
  File "/usr/local/lib/python3.9/logging/__init__.py", line 1661, in callHandlers
    hdlr.handle(record)
  File "/usr/local/lib/python3.9/logging/__init__.py", line 952, in handle
    self.emit(record)
  File "/home/airflow/.local/lib/python3.9/site-packages/airflow/utils/log/file_task_handler.py", line 211, in emit
    self.handler.emit(record)
  File "/usr/local/lib/python3.9/logging/__init__.py", line 1187, in emit
    StreamHandler.emit(self, record)
  File "/usr/local/lib/python3.9/logging/__init__.py", line 1087, in emit
    self.flush()
  File "/usr/local/lib/python3.9/logging/__init__.py", line 1067, in flush
    self.stream.flush()
  File "/home/airflow/.local/lib/python3.9/site-packages/airflow/models/taskinstance.py", line 1540, in signal_handler
    self.log.error("Received SIGTERM. Terminating subprocesses.")
  File "/usr/local/lib/python3.9/logging/__init__.py", line 1475, in error
    self._log(ERROR, msg, args, **kwargs)
  File "/usr/local/lib/python3.9/logging/__init__.py", line 1589, in _log
    self.handle(record)
  File "/usr/local/lib/python3.9/logging/__init__.py", line 1599, in handle
    self.callHandlers(record)
  File "/usr/local/lib/python3.9/logging/__init__.py", line 1661, in callHandlers
    hdlr.handle(record)
  File "/usr/local/lib/python3.9/logging/__init__.py", line 952, in handle
    self.emit(record)
  File "/home/airflow/.local/lib/python3.9/site-packages/airflow/utils/log/file_task_handler.py", line 211, in emit
    self.handler.emit(record)
  File "/usr/local/lib/python3.9/logging/__init__.py", line 1187, in emit
    StreamHandler.emit(self, record)
  File "/usr/local/lib/python3.9/logging/__init__.py", line 1091, in emit
    self.handleError(record)
  File "/usr/local/lib/python3.9/logging/__init__.py", line 1004, in handleError
    sys.stderr.write('--- Logging error ---\n')
  File "/home/airflow/.local/lib/python3.9/site-packages/airflow/utils/log/logging_mixin.py", line 161, in write
    self.flush()
  File "/home/airflow/.local/lib/python3.9/site-packages/airflow/utils/log/logging_mixin.py", line 168, in flush
    self._propagate_log(buf)
  File "/home/airflow/.local/lib/python3.9/site-packages/airflow/utils/log/logging_mixin.py", line 149, in _propagate_log
    self.logger.log(self.level, remove_escape_codes(message))
  File "/usr/local/lib/python3.9/logging/__init__.py", line 1512, in log
    self._log(level, msg, args, **kwargs)
  File "/usr/local/lib/python3.9/logging/__init__.py", line 1589, in _log
    self.handle(record)
  File "/usr/local/lib/python3.9/logging/__init__.py", line 1599, in handle
    self.callHandlers(record)
  File "/usr/local/lib/python3.9/logging/__init__.py", line 1661, in callHandlers
    hdlr.handle(record)
  File "/usr/local/lib/python3.9/logging/__init__.py", line 952, in handle
    self.emit(record)
  File "/home/airflow/.local/lib/python3.9/site-packages/airflow/utils/log/file_task_handler.py", line 211, in emit
    self.handler.emit(record)
  File "/usr/local/lib/python3.9/logging/__init__.py", line 1187, in emit
    StreamHandler.emit(self, record)
  File "/usr/local/lib/python3.9/logging/__init__.py", line 1091, in emit
    self.handleError(record)
  File "/usr/local/lib/python3.9/logging/__init__.py", line 1004, in handleError
    sys.stderr.write('--- Logging error ---\n')
  File "/home/airflow/.local/lib/python3.9/site-packages/airflow/utils/log/logging_mixin.py", line 161, in write
    self.flush()
  File "/home/airflow/.local/lib/python3.9/site-packages/airflow/utils/log/logging_mixin.py", line 168, in flush
    self._propagate_log(buf)
  File "/home/airflow/.local/lib/python3.9/site-packages/airflow/utils/log/logging_mixin.py", line 149, in _propagate_log
    self.logger.log(self.level, remove_escape_codes(message))
  File "/usr/local/lib/python3.9/logging/__init__.py", line 1512, in log
    self._log(level, msg, args, **kwargs)
  File "/usr/local/lib/python3.9/logging/__init__.py", line 1589, in _log
    self.handle(record)
  File "/usr/local/lib/python3.9/logging/__init__.py", line 1599, in handle
    self.callHandlers(record)
  File "/usr/local/lib/python3.9/logging/__init__.py", line 1661, in callHandlers
    hdlr.handle(record)
  File "/usr/local/lib/python3.9/logging/__init__.py", line 952, in handle
    self.emit(record)
  File "/home/airflow/.local/lib/python3.9/site-packages/airflow/utils/log/file_task_handler.py", line 211, in emit
    self.handler.emit(record)
  File "/usr/local/lib/python3.9/logging/__init__.py", line 1187, in emit
    StreamHandler.emit(self, record)
  File "/usr/local/lib/python3.9/logging/__init__.py", line 1091, in emit
    self.handleError(record)
  File "/usr/local/lib/python3.9/logging/__init__.py", line 1004, in handleError
    sys.stderr.write('--- Logging error ---\n')
  File "/home/airflow/.local/lib/python3.9/site-packages/airflow/utils/log/logging_mixin.py", line 161, in write
    self.flush()
  File "/home/airflow/.local/lib/python3.9/site-packages/airflow/utils/log/logging_mixin.py", line 168, in flush
    self._propagate_log(buf)
  File "/home/airflow/.local/lib/python3.9/site-packages/airflow/utils/log/logging_mixin.py", line 149, in _propagate_log
    self.logger.log(self.level, remove_escape_codes(message))
  File "/usr/local/lib/python3.9/logging/__init__.py", line 1512, in log
    self._log(level, msg, args, **kwargs)
  File "/usr/local/lib/python3.9/logging/__init__.py", line 1589, in _log
    self.handle(record)
  File "/usr/local/lib/python3.9/logging/__init__.py", line 1599, in handle
    self.callHandlers(record)
  File "/usr/local/lib/python3.9/logging/__init__.py", line 1661, in callHandlers
    hdlr.handle(record)
  File "/usr/local/lib/python3.9/logging/__init__.py", line 952, in handle
    self.emit(record)
  File "/home/airflow/.local/lib/python3.9/site-packages/airflow/utils/log/file_task_handler.py", line 211, in emit
    self.handler.emit(record)
  File "/usr/local/lib/python3.9/logging/__init__.py", line 1187, in emit
    StreamHandler.emit(self, record)
  File "/usr/local/lib/python3.9/logging/__init__.py", line 1091, in emit
    self.handleError(record)
  File "/usr/local/lib/python3.9/logging/__init__.py", line 1004, in handleError
    sys.stderr.write('--- Logging error ---\n')
  File "/home/airflow/.local/lib/python3.9/site-packages/airflow/utils/log/logging_mixin.py", line 161, in write
    self.flush()
  File "/home/airflow/.local/lib/python3.9/site-packages/airflow/utils/log/logging_mixin.py", line 168, in flush
    self._propagate_log(buf)
  File "/home/airflow/.local/lib/python3.9/site-packages/airflow/utils/log/logging_mixin.py", line 149, in _propagate_log
    self.logger.log(self.level, remove_escape_codes(message))
  File "/usr/local/lib/python3.9/logging/__init__.py", line 1512, in log
    self._log(level, msg, args, **kwargs)
  File "/usr/local/lib/python3.9/logging/__init__.py", line 1589, in _log
    self.handle(record)
  File "/usr/local/lib/python3.9/logging/__init__.py", line 1599, in handle
    self.callHandlers(record)
  File "/usr/local/lib/python3.9/logging/__init__.py", line 1661, in callHandlers
    hdlr.handle(record)
  File "/usr/local/lib/python3.9/logging/__init__.py", line 952, in handle
    self.emit(record)
  File "/home/airflow/.local/lib/python3.9/site-packages/airflow/utils/log/file_task_handler.py", line 211, in emit
    self.handler.emit(record)
  File "/usr/local/lib/python3.9/logging/__init__.py", line 1187, in emit
    StreamHandler.emit(self, record)
  File "/usr/local/lib/python3.9/logging/__init__.py", line 1091, in emit
    self.handleError(record)
  File "/usr/local/lib/python3.9/logging/__init__.py", line 1004, in handleError
    sys.stderr.write('--- Logging error ---\n')
  File "/home/airflow/.local/lib/python3.9/site-packages/airflow/utils/log/logging_mixin.py", line 161, in write
    self.flush()
  File "/home/airflow/.local/lib/python3.9/site-packages/airflow/utils/log/logging_mixin.py", line 168, in flush
    self._propagate_log(buf)
  File "/home/airflow/.local/lib/python3.9/site-packages/airflow/utils/log/logging_mixin.py", line 149, in _propagate_log
    self.logger.log(self.level, remove_escape_codes(message))
  File "/usr/local/lib/python3.9/logging/__init__.py", line 1512, in log
    self._log(level, msg, args, **kwargs)
  File "/usr/local/lib/python3.9/logging/__init__.py", line 1589, in _log
    self.handle(record)
  File "/usr/local/lib/python3.9/logging/__init__.py", line 1599, in handle
    self.callHandlers(record)
  File "/usr/local/lib/python3.9/logging/__init__.py", line 1661, in callHandlers
    hdlr.handle(record)
  File "/usr/local/lib/python3.9/logging/__init__.py", line 952, in handle
    self.emit(record)
  File "/home/airflow/.local/lib/python3.9/site-packages/airflow/utils/log/file_task_handler.py", line 211, in emit
    self.handler.emit(record)
  File "/usr/local/lib/python3.9/logging/__init__.py", line 1187, in emit
    StreamHandler.emit(self, record)
  File "/usr/local/lib/python3.9/logging/__init__.py", line 1091, in emit
    self.handleError(record)
  File "/usr/local/lib/python3.9/logging/__init__.py", line 1004, in handleError
    sys.stderr.write('--- Logging error ---\n')
  File "/home/airflow/.local/lib/python3.9/site-packages/airflow/utils/log/logging_mixin.py", line 161, in write
    self.flush()
  File "/home/airflow/.local/lib/python3.9/site-packages/airflow/utils/log/logging_mixin.py", line 168, in flush
    self._propagate_log(buf)
  File "/home/airflow/.local/lib/python3.9/site-packages/airflow/utils/log/logging_mixin.py", line 149, in _propagate_log
    self.logger.log(self.level, remove_escape_codes(message))
  File "/usr/local/lib/python3.9/logging/__init__.py", line 1512, in log
    self._log(level, msg, args, **kwargs)
  File "/usr/local/lib/python3.9/logging/__init__.py", line 1589, in _log
    self.handle(record)
  File "/usr/local/lib/python3.9/logging/__init__.py", line 1599, in handle
    self.callHandlers(record)
  File "/usr/local/lib/python3.9/logging/__init__.py", line 1661, in callHandlers
    hdlr.handle(record)
  File "/usr/local/lib/python3.9/logging/__init__.py", line 952, in handle
    self.emit(record)
  File "/home/airflow/.local/lib/python3.9/site-packages/airflow/utils/log/file_task_handler.py", line 211, in emit
    self.handler.emit(record)
  File "/usr/local/lib/python3.9/logging/__init__.py", line 1187, in emit
    StreamHandler.emit(self, record)
  File "/usr/local/lib/python3.9/logging/__init__.py", line 1091, in emit
    self.handleError(record)
  File "/usr/local/lib/python3.9/logging/__init__.py", line 1004, in handleError
    sys.stderr.write('--- Logging error ---\n')
  File "/home/airflow/.local/lib/python3.9/site-packages/airflow/utils/log/logging_mixin.py", line 161, in write
    self.flush()
  File "/home/airflow/.local/lib/python3.9/site-packages/airflow/utils/log/logging_mixin.py", line 168, in flush
    self._propagate_log(buf)
  File "/home/airflow/.local/lib/python3.9/site-packages/airflow/utils/log/logging_mixin.py", line 149, in _propagate_log
    self.logger.log(self.level, remove_escape_codes(message))
  File "/usr/local/lib/python3.9/logging/__init__.py", line 1512, in log
    self._log(level, msg, args, **kwargs)
  File "/usr/local/lib/python3.9/logging/__init__.py", line 1589, in _log
    self.handle(record)
  File "/usr/local/lib/python3.9/logging/__init__.py", line 1599, in handle
    self.callHandlers(record)
  File "/usr/local/lib/python3.9/logging/__init__.py", line 1661, in callHandlers
    hdlr.handle(record)
  File "/usr/local/lib/python3.9/logging/__init__.py", line 952, in handle
    self.emit(record)
  File "/home/airflow/.local/lib/python3.9/site-packages/airflow/utils/log/file_task_handler.py", line 211, in emit
    self.handler.emit(record)
  File "/usr/local/lib/python3.9/logging/__init__.py", line 1187, in emit
    StreamHandler.emit(self, record)
  File "/usr/local/lib/python3.9/logging/__init__.py", line 1091, in emit
    self.handleError(record)
  File "/usr/local/lib/python3.9/logging/__init__.py", line 1004, in handleError
    sys.stderr.write('--- Logging error ---\n')
  File "/home/airflow/.local/lib/python3.9/site-packages/airflow/utils/log/logging_mixin.py", line 161, in write
    self.flush()
  File "/home/airflow/.local/lib/python3.9/site-packages/airflow/utils/log/logging_mixin.py", line 168, in flush
    self._propagate_log(buf)
  File "/home/airflow/.local/lib/python3.9/site-packages/airflow/utils/log/logging_mixin.py", line 149, in _propagate_log
    self.logger.log(self.level, remove_escape_codes(message))
  File "/usr/local/lib/python3.9/logging/__init__.py", line 1512, in log
    self._log(level, msg, args, **kwargs)
  File "/usr/local/lib/python3.9/logging/__init__.py", line 1589, in _log
    self.handle(record)
  File "/usr/local/lib/python3.9/logging/__init__.py", line 1599, in handle
    self.callHandlers(record)
  File "/usr/local/lib/python3.9/logging/__init__.py", line 1661, in callHandlers
    hdlr.handle(record)
  File "/usr/local/lib/python3.9/logging/__init__.py", line 952, in handle
    self.emit(record)
  File "/home/airflow/.local/lib/python3.9/site-packages/airflow/utils/log/file_task_handler.py", line 211, in emit
    self.handler.emit(record)
  File "/usr/local/lib/python3.9/logging/__init__.py", line 1187, in emit
    StreamHandler.emit(self, record)
  File "/usr/local/lib/python3.9/logging/__init__.py", line 1091, in emit
    self.handleError(record)
  File "/usr/local/lib/python3.9/logging/__init__.py", line 1004, in handleError
    sys.stderr.write('--- Logging error ---\n')
  File "/home/airflow/.local/lib/python3.9/site-packages/airflow/utils/log/logging_mixin.py", line 161, in write
    self.flush()
  File "/home/airflow/.local/lib/python3.9/site-packages/airflow/utils/log/logging_mixin.py", line 168, in flush
    self._propagate_log(buf)
  File "/home/airflow/.local/lib/python3.9/site-packages/airflow/utils/log/logging_mixin.py", line 149, in _propagate_log
    self.logger.log(self.level, remove_escape_codes(message))
  File "/usr/local/lib/python3.9/logging/__init__.py", line 1512, in log
    self._log(level, msg, args, **kwargs)
  File "/usr/local/lib/python3.9/logging/__init__.py", line 1589, in _log
    self.handle(record)
  File "/usr/local/lib/python3.9/logging/__init__.py", line 1599, in handle
    self.callHandlers(record)
  File "/usr/local/lib/python3.9/logging/__init__.py", line 1661, in callHandlers
    hdlr.handle(record)
  File "/usr/local/lib/python3.9/logging/__init__.py", line 952, in handle
    self.emit(record)
  File "/home/airflow/.local/lib/python3.9/site-packages/airflow/utils/log/file_task_handler.py", line 211, in emit
    self.handler.emit(record)
  File "/usr/local/lib/python3.9/logging/__init__.py", line 1187, in emit
    StreamHandler.emit(self, record)
  File "/usr/local/lib/python3.9/logging/__init__.py", line 1091, in emit
    self.handleError(record)
  File "/usr/local/lib/python3.9/logging/__init__.py", line 1004, in handleError
    sys.stderr.write('--- Logging error ---\n')
  File "/home/airflow/.local/lib/python3.9/site-packages/airflow/utils/log/logging_mixin.py", line 161, in write
    self.flush()
  File "/home/airflow/.local/lib/python3.9/site-packages/airflow/utils/log/logging_mixin.py", line 168, in flush
    self._propagate_log(buf)
  File "/home/airflow/.local/lib/python3.9/site-packages/airflow/utils/log/logging_mixin.py", line 149, in _propagate_log
    self.logger.log(self.level, remove_escape_codes(message))
  File "/usr/local/lib/python3.9/logging/__init__.py", line 1512, in log
    self._log(level, msg, args, **kwargs)
  File "/usr/local/lib/python3.9/logging/__init__.py", line 1589, in _log
    self.handle(record)
  File "/usr/local/lib/python3.9/logging/__init__.py", line 1599, in handle
    self.callHandlers(record)
  File "/usr/local/lib/python3.9/logging/__init__.py", line 1661, in callHandlers
    hdlr.handle(record)
  File "/usr/local/lib/python3.9/logging/__init__.py", line 952, in handle
    self.emit(record)
  File "/home/airflow/.local/lib/python3.9/site-packages/airflow/utils/log/file_task_handler.py", line 211, in emit
    self.handler.emit(record)
  File "/usr/local/lib/python3.9/logging/__init__.py", line 1187, in emit
    StreamHandler.emit(self, record)
  File "/usr/local/lib/python3.9/logging/__init__.py", line 1091, in emit
    self.handleError(record)
  File "/usr/local/lib/python3.9/logging/__init__.py", line 1004, in handleError
    sys.stderr.write('--- Logging error ---\n')
  File "/home/airflow/.local/lib/python3.9/site-packages/airflow/utils/log/logging_mixin.py", line 161, in write
    self.flush()
  File "/home/airflow/.local/lib/python3.9/site-packages/airflow/utils/log/logging_mixin.py", line 168, in flush
    self._propagate_log(buf)
  File "/home/airflow/.local/lib/python3.9/site-packages/airflow/utils/log/logging_mixin.py", line 149, in _propagate_log
    self.logger.log(self.level, remove_escape_codes(message))
  File "/usr/local/lib/python3.9/logging/__init__.py", line 1512, in log
    self._log(level, msg, args, **kwargs)
  File "/usr/local/lib/python3.9/logging/__init__.py", line 1589, in _log
    self.handle(record)
  File "/usr/local/lib/python3.9/logging/__init__.py", line 1599, in handle
    self.callHandlers(record)
  File "/usr/local/lib/python3.9/logging/__init__.py", line 1661, in callHandlers
    hdlr.handle(record)
  File "/usr/local/lib/python3.9/logging/__init__.py", line 952, in handle
    self.emit(record)
  File "/home/airflow/.local/lib/python3.9/site-packages/airflow/utils/log/file_task_handler.py", line 211, in emit
    self.handler.emit(record)
  File "/usr/local/lib/python3.9/logging/__init__.py", line 1187, in emit
    StreamHandler.emit(self, record)
  File "/usr/local/lib/python3.9/logging/__init__.py", line 1091, in emit
    self.handleError(record)
  File "/usr/local/lib/python3.9/logging/__init__.py", line 1004, in handleError
    sys.stderr.write('--- Logging error ---\n')
  File "/home/airflow/.local/lib/python3.9/site-packages/airflow/utils/log/logging_mixin.py", line 161, in write
    self.flush()
  File "/home/airflow/.local/lib/python3.9/site-packages/airflow/utils/log/logging_mixin.py", line 168, in flush
    self._propagate_log(buf)
  File "/home/airflow/.local/lib/python3.9/site-packages/airflow/utils/log/logging_mixin.py", line 149, in _propagate_log
    self.logger.log(self.level, remove_escape_codes(message))
  File "/usr/local/lib/python3.9/logging/__init__.py", line 1512, in log
    self._log(level, msg, args, **kwargs)
  File "/usr/local/lib/python3.9/logging/__init__.py", line 1589, in _log
    self.handle(record)
  File "/usr/local/lib/python3.9/logging/__init__.py", line 1599, in handle
    self.callHandlers(record)
  File "/usr/local/lib/python3.9/logging/__init__.py", line 1661, in callHandlers
    hdlr.handle(record)
  File "/usr/local/lib/python3.9/logging/__init__.py", line 952, in handle
    self.emit(record)
  File "/home/airflow/.local/lib/python3.9/site-packages/airflow/utils/log/file_task_handler.py", line 211, in emit
    self.handler.emit(record)
  File "/usr/local/lib/python3.9/logging/__init__.py", line 1187, in emit
    StreamHandler.emit(self, record)
  File "/usr/local/lib/python3.9/logging/__init__.py", line 1091, in emit
    self.handleError(record)
  File "/usr/local/lib/python3.9/logging/__init__.py", line 1004, in handleError
    sys.stderr.write('--- Logging error ---\n')
  File "/home/airflow/.local/lib/python3.9/site-packages/airflow/utils/log/logging_mixin.py", line 161, in write
    self.flush()
  File "/home/airflow/.local/lib/python3.9/site-packages/airflow/utils/log/logging_mixin.py", line 168, in flush
    self._propagate_log(buf)
  File "/home/airflow/.local/lib/python3.9/site-packages/airflow/utils/log/logging_mixin.py", line 149, in _propagate_log
    self.logger.log(self.level, remove_escape_codes(message))
  File "/usr/local/lib/python3.9/logging/__init__.py", line 1512, in log
    self._log(level, msg, args, **kwargs)
  File "/usr/local/lib/python3.9/logging/__init__.py", line 1589, in _log
    self.handle(record)
  File "/usr/local/lib/python3.9/logging/__init__.py", line 1599, in handle
    self.callHandlers(record)
  File "/usr/local/lib/python3.9/logging/__init__.py", line 1661, in callHandlers
    hdlr.handle(record)
  File "/usr/local/lib/python3.9/logging/__init__.py", line 952, in handle
    self.emit(record)
  File "/home/airflow/.local/lib/python3.9/site-packages/airflow/utils/log/file_task_handler.py", line 211, in emit
    self.handler.emit(record)
  File "/usr/local/lib/python3.9/logging/__init__.py", line 1187, in emit
    StreamHandler.emit(self, record)
  File "/usr/local/lib/python3.9/logging/__init__.py", line 1091, in emit
    self.handleError(record)
  File "/usr/local/lib/python3.9/logging/__init__.py", line 1004, in handleError
    sys.stderr.write('--- Logging error ---\n')
  File "/home/airflow/.local/lib/python3.9/site-packages/airflow/utils/log/logging_mixin.py", line 161, in write
    self.flush()
  File "/home/airflow/.local/lib/python3.9/site-packages/airflow/utils/log/logging_mixin.py", line 168, in flush
    self._propagate_log(buf)
  File "/home/airflow/.local/lib/python3.9/site-packages/airflow/utils/log/logging_mixin.py", line 149, in _propagate_log
    self.logger.log(self.level, remove_escape_codes(message))
  File "/usr/local/lib/python3.9/logging/__init__.py", line 1512, in log
    self._log(level, msg, args, **kwargs)
  File "/usr/local/lib/python3.9/logging/__init__.py", line 1589, in _log
    self.handle(record)
  File "/usr/local/lib/python3.9/logging/__init__.py", line 1599, in handle
    self.callHandlers(record)
  File "/usr/local/lib/python3.9/logging/__init__.py", line 1661, in callHandlers
    hdlr.handle(record)
  File "/usr/local/lib/python3.9/logging/__init__.py", line 952, in handle
    self.emit(record)
  File "/home/airflow/.local/lib/python3.9/site-packages/airflow/utils/log/file_task_handler.py", line 211, in emit
    self.handler.emit(record)
  File "/usr/local/lib/python3.9/logging/__init__.py", line 1187, in emit
    StreamHandler.emit(self, record)
  File "/usr/local/lib/python3.9/logging/__init__.py", line 1091, in emit
    self.handleError(record)
  File "/usr/local/lib/python3.9/logging/__init__.py", line 1004, in handleError
    sys.stderr.write('--- Logging error ---\n')
  File "/home/airflow/.local/lib/python3.9/site-packages/airflow/utils/log/logging_mixin.py", line 161, in write
    self.flush()
  File "/home/airflow/.local/lib/python3.9/site-packages/airflow/utils/log/logging_mixin.py", line 168, in flush
    self._propagate_log(buf)
  File "/home/airflow/.local/lib/python3.9/site-packages/airflow/utils/log/logging_mixin.py", line 149, in _propagate_log
    self.logger.log(self.level, remove_escape_codes(message))
  File "/usr/local/lib/python3.9/logging/__init__.py", line 1512, in log
    self._log(level, msg, args, **kwargs)
  File "/usr/local/lib/python3.9/logging/__init__.py", line 1589, in _log
    self.handle(record)
  File "/usr/local/lib/python3.9/logging/__init__.py", line 1599, in handle
    self.callHandlers(record)
  File "/usr/local/lib/python3.9/logging/__init__.py", line 1661, in callHandlers
    hdlr.handle(record)
  File "/usr/local/lib/python3.9/logging/__init__.py", line 952, in handle
    self.emit(record)
  File "/home/airflow/.local/lib/python3.9/site-packages/airflow/utils/log/file_task_handler.py", line 211, in emit
    self.handler.emit(record)
  File "/usr/local/lib/python3.9/logging/__init__.py", line 1187, in emit
    StreamHandler.emit(self, record)
  File "/usr/local/lib/python3.9/logging/__init__.py", line 1091, in emit
    self.handleError(record)
  File "/usr/local/lib/python3.9/logging/__init__.py", line 1004, in handleError
    sys.stderr.write('--- Logging error ---\n')
  File "/home/airflow/.local/lib/python3.9/site-packages/airflow/utils/log/logging_mixin.py", line 161, in write
    self.flush()
  File "/home/airflow/.local/lib/python3.9/site-packages/airflow/utils/log/logging_mixin.py", line 168, in flush
    self._propagate_log(buf)
  File "/home/airflow/.local/lib/python3.9/site-packages/airflow/utils/log/logging_mixin.py", line 149, in _propagate_log
    self.logger.log(self.level, remove_escape_codes(message))
  File "/usr/local/lib/python3.9/logging/__init__.py", line 1512, in log
    self._log(level, msg, args, **kwargs)
  File "/usr/local/lib/python3.9/logging/__init__.py", line 1589, in _log
    self.handle(record)
  File "/usr/local/lib/python3.9/logging/__init__.py", line 1599, in handle
    self.callHandlers(record)
  File "/usr/local/lib/python3.9/logging/__init__.py", line 1661, in callHandlers
    hdlr.handle(record)
  File "/usr/local/lib/python3.9/logging/__init__.py", line 952, in handle
    self.emit(record)
  File "/home/airflow/.local/lib/python3.9/site-packages/airflow/utils/log/file_task_handler.py", line 211, in emit
    self.handler.emit(record)
  File "/usr/local/lib/python3.9/logging/__init__.py", line 1187, in emit
    StreamHandler.emit(self, record)
  File "/usr/local/lib/python3.9/logging/__init__.py", line 1091, in emit
    self.handleError(record)
  File "/usr/local/lib/python3.9/logging/__init__.py", line 1004, in handleError
    sys.stderr.write('--- Logging error ---\n')
  File "/home/airflow/.local/lib/python3.9/site-packages/airflow/utils/log/logging_mixin.py", line 161, in write
    self.flush()
  File "/home/airflow/.local/lib/python3.9/site-packages/airflow/utils/log/logging_mixin.py", line 168, in flush
    self._propagate_log(buf)
  File "/home/airflow/.local/lib/python3.9/site-packages/airflow/utils/log/logging_mixin.py", line 149, in _propagate_log
    self.logger.log(self.level, remove_escape_codes(message))
  File "/usr/local/lib/python3.9/logging/__init__.py", line 1512, in log
    self._log(level, msg, args, **kwargs)
  File "/usr/local/lib/python3.9/logging/__init__.py", line 1589, in _log
    self.handle(record)
  File "/usr/local/lib/python3.9/logging/__init__.py", line 1599, in handle
    self.callHandlers(record)
  File "/usr/local/lib/python3.9/logging/__init__.py", line 1661, in callHandlers
    hdlr.handle(record)
  File "/usr/local/lib/python3.9/logging/__init__.py", line 952, in handle
    self.emit(record)
  File "/home/airflow/.local/lib/python3.9/site-packages/airflow/utils/log/file_task_handler.py", line 211, in emit
    self.handler.emit(record)
  File "/usr/local/lib/python3.9/logging/__init__.py", line 1187, in emit
    StreamHandler.emit(self, record)
  File "/usr/local/lib/python3.9/logging/__init__.py", line 1091, in emit
    self.handleError(record)
  File "/usr/local/lib/python3.9/logging/__init__.py", line 1004, in handleError
    sys.stderr.write('--- Logging error ---\n')
  File "/home/airflow/.local/lib/python3.9/site-packages/airflow/utils/log/logging_mixin.py", line 161, in write
    self.flush()
  File "/home/airflow/.local/lib/python3.9/site-packages/airflow/utils/log/logging_mixin.py", line 168, in flush
    self._propagate_log(buf)
  File "/home/airflow/.local/lib/python3.9/site-packages/airflow/utils/log/logging_mixin.py", line 149, in _propagate_log
    self.logger.log(self.level, remove_escape_codes(message))
  File "/usr/local/lib/python3.9/logging/__init__.py", line 1512, in log
    self._log(level, msg, args, **kwargs)
  File "/usr/local/lib/python3.9/logging/__init__.py", line 1589, in _log
    self.handle(record)
  File "/usr/local/lib/python3.9/logging/__init__.py", line 1599, in handle
    self.callHandlers(record)
  File "/usr/local/lib/python3.9/logging/__init__.py", line 1661, in callHandlers
    hdlr.handle(record)
  File "/usr/local/lib/python3.9/logging/__init__.py", line 952, in handle
    self.emit(record)
  File "/home/airflow/.local/lib/python3.9/site-packages/airflow/utils/log/file_task_handler.py", line 211, in emit
    self.handler.emit(record)
  File "/usr/local/lib/python3.9/logging/__init__.py", line 1187, in emit
    StreamHandler.emit(self, record)
  File "/usr/local/lib/python3.9/logging/__init__.py", line 1091, in emit
    self.handleError(record)
  File "/usr/local/lib/python3.9/logging/__init__.py", line 1004, in handleError
    sys.stderr.write('--- Logging error ---\n')
  File "/home/airflow/.local/lib/python3.9/site-packages/airflow/utils/log/logging_mixin.py", line 161, in write
    self.flush()
  File "/home/airflow/.local/lib/python3.9/site-packages/airflow/utils/log/logging_mixin.py", line 168, in flush
    self._propagate_log(buf)
  File "/home/airflow/.local/lib/python3.9/site-packages/airflow/utils/log/logging_mixin.py", line 149, in _propagate_log
    self.logger.log(self.level, remove_escape_codes(message))
  File "/usr/local/lib/python3.9/logging/__init__.py", line 1512, in log
    self._log(level, msg, args, **kwargs)
  File "/usr/local/lib/python3.9/logging/__init__.py", line 1589, in _log
    self.handle(record)
  File "/usr/local/lib/python3.9/logging/__init__.py", line 1599, in handle
    self.callHandlers(record)
  File "/usr/local/lib/python3.9/logging/__init__.py", line 1661, in callHandlers
    hdlr.handle(record)
  File "/usr/local/lib/python3.9/logging/__init__.py", line 952, in handle
    self.emit(record)
  File "/home/airflow/.local/lib/python3.9/site-packages/airflow/utils/log/file_task_handler.py", line 211, in emit
    self.handler.emit(record)
  File "/usr/local/lib/python3.9/logging/__init__.py", line 1187, in emit
    StreamHandler.emit(self, record)
  File "/usr/local/lib/python3.9/logging/__init__.py", line 1091, in emit
    self.handleError(record)
  File "/usr/local/lib/python3.9/logging/__init__.py", line 1004, in handleError
    sys.stderr.write('--- Logging error ---\n')
  File "/home/airflow/.local/lib/python3.9/site-packages/airflow/utils/log/logging_mixin.py", line 161, in write
    self.flush()
  File "/home/airflow/.local/lib/python3.9/site-packages/airflow/utils/log/logging_mixin.py", line 168, in flush
    self._propagate_log(buf)
  File "/home/airflow/.local/lib/python3.9/site-packages/airflow/utils/log/logging_mixin.py", line 149, in _propagate_log
    self.logger.log(self.level, remove_escape_codes(message))
  File "/usr/local/lib/python3.9/logging/__init__.py", line 1512, in log
    self._log(level, msg, args, **kwargs)
  File "/usr/local/lib/python3.9/logging/__init__.py", line 1589, in _log
    self.handle(record)
  File "/usr/local/lib/python3.9/logging/__init__.py", line 1599, in handle
    self.callHandlers(record)
  File "/usr/local/lib/python3.9/logging/__init__.py", line 1661, in callHandlers
    hdlr.handle(record)
  File "/usr/local/lib/python3.9/logging/__init__.py", line 952, in handle
    self.emit(record)
  File "/home/airflow/.local/lib/python3.9/site-packages/airflow/utils/log/file_task_handler.py", line 211, in emit
    self.handler.emit(record)
  File "/usr/local/lib/python3.9/logging/__init__.py", line 1187, in emit
    StreamHandler.emit(self, record)
  File "/usr/local/lib/python3.9/logging/__init__.py", line 1091, in emit
    self.handleError(record)
  File "/usr/local/lib/python3.9/logging/__init__.py", line 1004, in handleError
    sys.stderr.write('--- Logging error ---\n')
  File "/home/airflow/.local/lib/python3.9/site-packages/airflow/utils/log/logging_mixin.py", line 161, in write
    self.flush()
  File "/home/airflow/.local/lib/python3.9/site-packages/airflow/utils/log/logging_mixin.py", line 168, in flush
    self._propagate_log(buf)
  File "/home/airflow/.local/lib/python3.9/site-packages/airflow/utils/log/logging_mixin.py", line 149, in _propagate_log
    self.logger.log(self.level, remove_escape_codes(message))
  File "/usr/local/lib/python3.9/logging/__init__.py", line 1512, in log
    self._log(level, msg, args, **kwargs)
  File "/usr/local/lib/python3.9/logging/__init__.py", line 1589, in _log
    self.handle(record)
  File "/usr/local/lib/python3.9/logging/__init__.py", line 1599, in handle
    self.callHandlers(record)
  File "/usr/local/lib/python3.9/logging/__init__.py", line 1661, in callHandlers
    hdlr.handle(record)
  File "/usr/local/lib/python3.9/logging/__init__.py", line 952, in handle
    self.emit(record)
  File "/home/airflow/.local/lib/python3.9/site-packages/airflow/utils/log/file_task_handler.py", line 211, in emit
    self.handler.emit(record)
  File "/usr/local/lib/python3.9/logging/__init__.py", line 1187, in emit
    StreamHandler.emit(self, record)
  File "/usr/local/lib/python3.9/logging/__init__.py", line 1091, in emit
    self.handleError(record)
  File "/usr/local/lib/python3.9/logging/__init__.py", line 1004, in handleError
    sys.stderr.write('--- Logging error ---\n')
  File "/home/airflow/.local/lib/python3.9/site-packages/airflow/utils/log/logging_mixin.py", line 161, in write
    self.flush()
  File "/home/airflow/.local/lib/python3.9/site-packages/airflow/utils/log/logging_mixin.py", line 168, in flush
    self._propagate_log(buf)
  File "/home/airflow/.local/lib/python3.9/site-packages/airflow/utils/log/logging_mixin.py", line 149, in _propagate_log
    self.logger.log(self.level, remove_escape_codes(message))
  File "/usr/local/lib/python3.9/logging/__init__.py", line 1512, in log
    self._log(level, msg, args, **kwargs)
  File "/usr/local/lib/python3.9/logging/__init__.py", line 1589, in _log
    self.handle(record)
  File "/usr/local/lib/python3.9/logging/__init__.py", line 1599, in handle
    self.callHandlers(record)
  File "/usr/local/lib/python3.9/logging/__init__.py", line 1661, in callHandlers
    hdlr.handle(record)
  File "/usr/local/lib/python3.9/logging/__init__.py", line 952, in handle
    self.emit(record)
  File "/home/airflow/.local/lib/python3.9/site-packages/airflow/utils/log/file_task_handler.py", line 211, in emit
    self.handler.emit(record)
  File "/usr/local/lib/python3.9/logging/__init__.py", line 1187, in emit
    StreamHandler.emit(self, record)
  File "/usr/local/lib/python3.9/logging/__init__.py", line 1091, in emit
    self.handleError(record)
  File "/usr/local/lib/python3.9/logging/__init__.py", line 1004, in handleError
    sys.stderr.write('--- Logging error ---\n')
  File "/home/airflow/.local/lib/python3.9/site-packages/airflow/utils/log/logging_mixin.py", line 161, in write
    self.flush()
  File "/home/airflow/.local/lib/python3.9/site-packages/airflow/utils/log/logging_mixin.py", line 168, in flush
    self._propagate_log(buf)
  File "/home/airflow/.local/lib/python3.9/site-packages/airflow/utils/log/logging_mixin.py", line 149, in _propagate_log
    self.logger.log(self.level, remove_escape_codes(message))
  File "/usr/local/lib/python3.9/logging/__init__.py", line 1512, in log
    self._log(level, msg, args, **kwargs)
  File "/usr/local/lib/python3.9/logging/__init__.py", line 1589, in _log
    self.handle(record)
  File "/usr/local/lib/python3.9/logging/__init__.py", line 1599, in handle
    self.callHandlers(record)
  File "/usr/local/lib/python3.9/logging/__init__.py", line 1661, in callHandlers
    hdlr.handle(record)
  File "/usr/local/lib/python3.9/logging/__init__.py", line 952, in handle
    self.emit(record)
  File "/home/airflow/.local/lib/python3.9/site-packages/airflow/utils/log/file_task_handler.py", line 211, in emit
    self.handler.emit(record)
  File "/usr/local/lib/python3.9/logging/__init__.py", line 1187, in emit
    StreamHandler.emit(self, record)
  File "/usr/local/lib/python3.9/logging/__init__.py", line 1091, in emit
    self.handleError(record)
  File "/usr/local/lib/python3.9/logging/__init__.py", line 1004, in handleError
    sys.stderr.write('--- Logging error ---\n')
  File "/home/airflow/.local/lib/python3.9/site-packages/airflow/utils/log/logging_mixin.py", line 161, in write
    self.flush()
  File "/home/airflow/.local/lib/python3.9/site-packages/airflow/utils/log/logging_mixin.py", line 168, in flush
    self._propagate_log(buf)
  File "/home/airflow/.local/lib/python3.9/site-packages/airflow/utils/log/logging_mixin.py", line 149, in _propagate_log
    self.logger.log(self.level, remove_escape_codes(message))
  File "/usr/local/lib/python3.9/logging/__init__.py", line 1512, in log
    self._log(level, msg, args, **kwargs)
  File "/usr/local/lib/python3.9/logging/__init__.py", line 1589, in _log
    self.handle(record)
  File "/usr/local/lib/python3.9/logging/__init__.py", line 1599, in handle
    self.callHandlers(record)
  File "/usr/local/lib/python3.9/logging/__init__.py", line 1661, in callHandlers
    hdlr.handle(record)
  File "/usr/local/lib/python3.9/logging/__init__.py", line 952, in handle
    self.emit(record)
  File "/home/airflow/.local/lib/python3.9/site-packages/airflow/utils/log/file_task_handler.py", line 211, in emit
    self.handler.emit(record)
  File "/usr/local/lib/python3.9/logging/__init__.py", line 1187, in emit
    StreamHandler.emit(self, record)
  File "/usr/local/lib/python3.9/logging/__init__.py", line 1091, in emit
    self.handleError(record)
  File "/usr/local/lib/python3.9/logging/__init__.py", line 1004, in handleError
    sys.stderr.write('--- Logging error ---\n')
  File "/home/airflow/.local/lib/python3.9/site-packages/airflow/utils/log/logging_mixin.py", line 161, in write
    self.flush()
  File "/home/airflow/.local/lib/python3.9/site-packages/airflow/utils/log/logging_mixin.py", line 168, in flush
    self._propagate_log(buf)
  File "/home/airflow/.local/lib/python3.9/site-packages/airflow/utils/log/logging_mixin.py", line 149, in _propagate_log
    self.logger.log(self.level, remove_escape_codes(message))
  File "/usr/local/lib/python3.9/logging/__init__.py", line 1512, in log
    self._log(level, msg, args, **kwargs)
  File "/usr/local/lib/python3.9/logging/__init__.py", line 1589, in _log
    self.handle(record)
  File "/usr/local/lib/python3.9/logging/__init__.py", line 1599, in handle
    self.callHandlers(record)
  File "/usr/local/lib/python3.9/logging/__init__.py", line 1661, in callHandlers
    hdlr.handle(record)
  File "/usr/local/lib/python3.9/logging/__init__.py", line 952, in handle
    self.emit(record)
  File "/home/airflow/.local/lib/python3.9/site-packages/airflow/utils/log/file_task_handler.py", line 211, in emit
    self.handler.emit(record)
  File "/usr/local/lib/python3.9/logging/__init__.py", line 1187, in emit
    StreamHandler.emit(self, record)
  File "/usr/local/lib/python3.9/logging/__init__.py", line 1091, in emit
    self.handleError(record)
  File "/usr/local/lib/python3.9/logging/__init__.py", line 1004, in handleError
    sys.stderr.write('--- Logging error ---\n')
  File "/home/airflow/.local/lib/python3.9/site-packages/airflow/utils/log/logging_mixin.py", line 161, in write
    self.flush()
  File "/home/airflow/.local/lib/python3.9/site-packages/airflow/utils/log/logging_mixin.py", line 168, in flush
    self._propagate_log(buf)
  File "/home/airflow/.local/lib/python3.9/site-packages/airflow/utils/log/logging_mixin.py", line 149, in _propagate_log
    self.logger.log(self.level, remove_escape_codes(message))
  File "/usr/local/lib/python3.9/logging/__init__.py", line 1512, in log
    self._log(level, msg, args, **kwargs)
  File "/usr/local/lib/python3.9/logging/__init__.py", line 1589, in _log
    self.handle(record)
  File "/usr/local/lib/python3.9/logging/__init__.py", line 1599, in handle
    self.callHandlers(record)
  File "/usr/local/lib/python3.9/logging/__init__.py", line 1661, in callHandlers
    hdlr.handle(record)
  File "/usr/local/lib/python3.9/logging/__init__.py", line 952, in handle
    self.emit(record)
  File "/home/airflow/.local/lib/python3.9/site-packages/airflow/utils/log/file_task_handler.py", line 211, in emit
    self.handler.emit(record)
  File "/usr/local/lib/python3.9/logging/__init__.py", line 1187, in emit
    StreamHandler.emit(self, record)
  File "/usr/local/lib/python3.9/logging/__init__.py", line 1091, in emit
    self.handleError(record)
  File "/usr/local/lib/python3.9/logging/__init__.py", line 1004, in handleError
    sys.stderr.write('--- Logging error ---\n')
  File "/home/airflow/.local/lib/python3.9/site-packages/airflow/utils/log/logging_mixin.py", line 161, in write
    self.flush()
  File "/home/airflow/.local/lib/python3.9/site-packages/airflow/utils/log/logging_mixin.py", line 168, in flush
    self._propagate_log(buf)
  File "/home/airflow/.local/lib/python3.9/site-packages/airflow/utils/log/logging_mixin.py", line 149, in _propagate_log
    self.logger.log(self.level, remove_escape_codes(message))
  File "/usr/local/lib/python3.9/logging/__init__.py", line 1512, in log
    self._log(level, msg, args, **kwargs)
  File "/usr/local/lib/python3.9/logging/__init__.py", line 1589, in _log
    self.handle(record)
  File "/usr/local/lib/python3.9/logging/__init__.py", line 1599, in handle
    self.callHandlers(record)
  File "/usr/local/lib/python3.9/logging/__init__.py", line 1661, in callHandlers
    hdlr.handle(record)
  File "/usr/local/lib/python3.9/logging/__init__.py", line 952, in handle
    self.emit(record)
  File "/home/airflow/.local/lib/python3.9/site-packages/airflow/utils/log/file_task_handler.py", line 211, in emit
    self.handler.emit(record)
  File "/usr/local/lib/python3.9/logging/__init__.py", line 1187, in emit
    StreamHandler.emit(self, record)
  File "/usr/local/lib/python3.9/logging/__init__.py", line 1091, in emit
    self.handleError(record)
  File "/usr/local/lib/python3.9/logging/__init__.py", line 1004, in handleError
    sys.stderr.write('--- Logging error ---\n')
  File "/home/airflow/.local/lib/python3.9/site-packages/airflow/utils/log/logging_mixin.py", line 161, in write
    self.flush()
  File "/home/airflow/.local/lib/python3.9/site-packages/airflow/utils/log/logging_mixin.py", line 168, in flush
    self._propagate_log(buf)
  File "/home/airflow/.local/lib/python3.9/site-packages/airflow/utils/log/logging_mixin.py", line 149, in _propagate_log
    self.logger.log(self.level, remove_escape_codes(message))
  File "/usr/local/lib/python3.9/logging/__init__.py", line 1512, in log
    self._log(level, msg, args, **kwargs)
  File "/usr/local/lib/python3.9/logging/__init__.py", line 1589, in _log
    self.handle(record)
  File "/usr/local/lib/python3.9/logging/__init__.py", line 1599, in handle
    self.callHandlers(record)
  File "/usr/local/lib/python3.9/logging/__init__.py", line 1661, in callHandlers
    hdlr.handle(record)
  File "/usr/local/lib/python3.9/logging/__init__.py", line 952, in handle
    self.emit(record)
  File "/home/airflow/.local/lib/python3.9/site-packages/airflow/utils/log/file_task_handler.py", line 211, in emit
    self.handler.emit(record)
  File "/usr/local/lib/python3.9/logging/__init__.py", line 1187, in emit
    StreamHandler.emit(self, record)
  File "/usr/local/lib/python3.9/logging/__init__.py", line 1091, in emit
    self.handleError(record)
  File "/usr/local/lib/python3.9/logging/__init__.py", line 1004, in handleError
    sys.stderr.write('--- Logging error ---\n')
  File "/home/airflow/.local/lib/python3.9/site-packages/airflow/utils/log/logging_mixin.py", line 161, in write
    self.flush()
  File "/home/airflow/.local/lib/python3.9/site-packages/airflow/utils/log/logging_mixin.py", line 168, in flush
    self._propagate_log(buf)
  File "/home/airflow/.local/lib/python3.9/site-packages/airflow/utils/log/logging_mixin.py", line 149, in _propagate_log
    self.logger.log(self.level, remove_escape_codes(message))
  File "/usr/local/lib/python3.9/logging/__init__.py", line 1512, in log
    self._log(level, msg, args, **kwargs)
  File "/usr/local/lib/python3.9/logging/__init__.py", line 1589, in _log
    self.handle(record)
  File "/usr/local/lib/python3.9/logging/__init__.py", line 1599, in handle
    self.callHandlers(record)
  File "/usr/local/lib/python3.9/logging/__init__.py", line 1661, in callHandlers
    hdlr.handle(record)
  File "/usr/local/lib/python3.9/logging/__init__.py", line 952, in handle
    self.emit(record)
  File "/home/airflow/.local/lib/python3.9/site-packages/airflow/utils/log/file_task_handler.py", line 211, in emit
    self.handler.emit(record)
  File "/usr/local/lib/python3.9/logging/__init__.py", line 1187, in emit
    StreamHandler.emit(self, record)
  File "/usr/local/lib/python3.9/logging/__init__.py", line 1091, in emit
    self.handleError(record)
  File "/usr/local/lib/python3.9/logging/__init__.py", line 1004, in handleError
    sys.stderr.write('--- Logging error ---\n')
  File "/home/airflow/.local/lib/python3.9/site-packages/airflow/utils/log/logging_mixin.py", line 161, in write
    self.flush()
  File "/home/airflow/.local/lib/python3.9/site-packages/airflow/utils/log/logging_mixin.py", line 168, in flush
    self._propagate_log(buf)
  File "/home/airflow/.local/lib/python3.9/site-packages/airflow/utils/log/logging_mixin.py", line 149, in _propagate_log
    self.logger.log(self.level, remove_escape_codes(message))
  File "/usr/local/lib/python3.9/logging/__init__.py", line 1512, in log
    self._log(level, msg, args, **kwargs)
  File "/usr/local/lib/python3.9/logging/__init__.py", line 1589, in _log
    self.handle(record)
  File "/usr/local/lib/python3.9/logging/__init__.py", line 1599, in handle
    self.callHandlers(record)
  File "/usr/local/lib/python3.9/logging/__init__.py", line 1661, in callHandlers
    hdlr.handle(record)
  File "/usr/local/lib/python3.9/logging/__init__.py", line 952, in handle
    self.emit(record)
  File "/home/airflow/.local/lib/python3.9/site-packages/airflow/utils/log/file_task_handler.py", line 211, in emit
    self.handler.emit(record)
  File "/usr/local/lib/python3.9/logging/__init__.py", line 1187, in emit
    StreamHandler.emit(self, record)
  File "/usr/local/lib/python3.9/logging/__init__.py", line 1091, in emit
    self.handleError(record)
  File "/usr/local/lib/python3.9/logging/__init__.py", line 1004, in handleError
    sys.stderr.write('--- Logging error ---\n')
  File "/home/airflow/.local/lib/python3.9/site-packages/airflow/utils/log/logging_mixin.py", line 161, in write
    self.flush()
  File "/home/airflow/.local/lib/python3.9/site-packages/airflow/utils/log/logging_mixin.py", line 168, in flush
    self._propagate_log(buf)
  File "/home/airflow/.local/lib/python3.9/site-packages/airflow/utils/log/logging_mixin.py", line 149, in _propagate_log
    self.logger.log(self.level, remove_escape_codes(message))
  File "/usr/local/lib/python3.9/logging/__init__.py", line 1512, in log
    self._log(level, msg, args, **kwargs)
  File "/usr/local/lib/python3.9/logging/__init__.py", line 1589, in _log
    self.handle(record)
  File "/usr/local/lib/python3.9/logging/__init__.py", line 1599, in handle
    self.callHandlers(record)
  File "/usr/local/lib/python3.9/logging/__init__.py", line 1661, in callHandlers
    hdlr.handle(record)
  File "/usr/local/lib/python3.9/logging/__init__.py", line 952, in handle
    self.emit(record)
  File "/home/airflow/.local/lib/python3.9/site-packages/airflow/utils/log/file_task_handler.py", line 211, in emit
    self.handler.emit(record)
  File "/usr/local/lib/python3.9/logging/__init__.py", line 1187, in emit
    StreamHandler.emit(self, record)
  File "/usr/local/lib/python3.9/logging/__init__.py", line 1091, in emit
    self.handleError(record)
  File "/usr/local/lib/python3.9/logging/__init__.py", line 1004, in handleError
    sys.stderr.write('--- Logging error ---\n')
  File "/home/airflow/.local/lib/python3.9/site-packages/airflow/utils/log/logging_mixin.py", line 161, in write
    self.flush()
  File "/home/airflow/.local/lib/python3.9/site-packages/airflow/utils/log/logging_mixin.py", line 168, in flush
    self._propagate_log(buf)
  File "/home/airflow/.local/lib/python3.9/site-packages/airflow/utils/log/logging_mixin.py", line 149, in _propagate_log
    self.logger.log(self.level, remove_escape_codes(message))
  File "/usr/local/lib/python3.9/logging/__init__.py", line 1512, in log
    self._log(level, msg, args, **kwargs)
  File "/usr/local/lib/python3.9/logging/__init__.py", line 1589, in _log
    self.handle(record)
  File "/usr/local/lib/python3.9/logging/__init__.py", line 1599, in handle
    self.callHandlers(record)
  File "/usr/local/lib/python3.9/logging/__init__.py", line 1661, in callHandlers
    hdlr.handle(record)
  File "/usr/local/lib/python3.9/logging/__init__.py", line 952, in handle
    self.emit(record)
  File "/home/airflow/.local/lib/python3.9/site-packages/airflow/utils/log/file_task_handler.py", line 211, in emit
    self.handler.emit(record)
  File "/usr/local/lib/python3.9/logging/__init__.py", line 1187, in emit
    StreamHandler.emit(self, record)
  File "/usr/local/lib/python3.9/logging/__init__.py", line 1091, in emit
    self.handleError(record)
  File "/usr/local/lib/python3.9/logging/__init__.py", line 1004, in handleError
    sys.stderr.write('--- Logging error ---\n')
  File "/home/airflow/.local/lib/python3.9/site-packages/airflow/utils/log/logging_mixin.py", line 161, in write
    self.flush()
  File "/home/airflow/.local/lib/python3.9/site-packages/airflow/utils/log/logging_mixin.py", line 168, in flush
    self._propagate_log(buf)
  File "/home/airflow/.local/lib/python3.9/site-packages/airflow/utils/log/logging_mixin.py", line 149, in _propagate_log
    self.logger.log(self.level, remove_escape_codes(message))
  File "/usr/local/lib/python3.9/logging/__init__.py", line 1512, in log
    self._log(level, msg, args, **kwargs)
  File "/usr/local/lib/python3.9/logging/__init__.py", line 1589, in _log
    self.handle(record)
  File "/usr/local/lib/python3.9/logging/__init__.py", line 1599, in handle
    self.callHandlers(record)
  File "/usr/local/lib/python3.9/logging/__init__.py", line 1661, in callHandlers
    hdlr.handle(record)
  File "/usr/local/lib/python3.9/logging/__init__.py", line 952, in handle
    self.emit(record)
  File "/home/airflow/.local/lib/python3.9/site-packages/airflow/utils/log/file_task_handler.py", line 211, in emit
    self.handler.emit(record)
  File "/usr/local/lib/python3.9/logging/__init__.py", line 1187, in emit
    StreamHandler.emit(self, record)
  File "/usr/local/lib/python3.9/logging/__init__.py", line 1091, in emit
    self.handleError(record)
  File "/usr/local/lib/python3.9/logging/__init__.py", line 1004, in handleError
    sys.stderr.write('--- Logging error ---\n')
  File "/home/airflow/.local/lib/python3.9/site-packages/airflow/utils/log/logging_mixin.py", line 161, in write
    self.flush()
  File "/home/airflow/.local/lib/python3.9/site-packages/airflow/utils/log/logging_mixin.py", line 168, in flush
    self._propagate_log(buf)
  File "/home/airflow/.local/lib/python3.9/site-packages/airflow/utils/log/logging_mixin.py", line 149, in _propagate_log
    self.logger.log(self.level, remove_escape_codes(message))
  File "/usr/local/lib/python3.9/logging/__init__.py", line 1512, in log
    self._log(level, msg, args, **kwargs)
  File "/usr/local/lib/python3.9/logging/__init__.py", line 1589, in _log
    self.handle(record)
  File "/usr/local/lib/python3.9/logging/__init__.py", line 1599, in handle
    self.callHandlers(record)
  File "/usr/local/lib/python3.9/logging/__init__.py", line 1661, in callHandlers
    hdlr.handle(record)
  File "/usr/local/lib/python3.9/logging/__init__.py", line 952, in handle
    self.emit(record)
  File "/home/airflow/.local/lib/python3.9/site-packages/airflow/utils/log/file_task_handler.py", line 211, in emit
    self.handler.emit(record)
  File "/usr/local/lib/python3.9/logging/__init__.py", line 1187, in emit
    StreamHandler.emit(self, record)
  File "/usr/local/lib/python3.9/logging/__init__.py", line 1091, in emit
    self.handleError(record)
  File "/usr/local/lib/python3.9/logging/__init__.py", line 1004, in handleError
    sys.stderr.write('--- Logging error ---\n')
  File "/home/airflow/.local/lib/python3.9/site-packages/airflow/utils/log/logging_mixin.py", line 161, in write
    self.flush()
  File "/home/airflow/.local/lib/python3.9/site-packages/airflow/utils/log/logging_mixin.py", line 168, in flush
    self._propagate_log(buf)
  File "/home/airflow/.local/lib/python3.9/site-packages/airflow/utils/log/logging_mixin.py", line 149, in _propagate_log
    self.logger.log(self.level, remove_escape_codes(message))
  File "/usr/local/lib/python3.9/logging/__init__.py", line 1512, in log
    self._log(level, msg, args, **kwargs)
  File "/usr/local/lib/python3.9/logging/__init__.py", line 1589, in _log
    self.handle(record)
  File "/usr/local/lib/python3.9/logging/__init__.py", line 1599, in handle
    self.callHandlers(record)
  File "/usr/local/lib/python3.9/logging/__init__.py", line 1661, in callHandlers
    hdlr.handle(record)
  File "/usr/local/lib/python3.9/logging/__init__.py", line 952, in handle
    self.emit(record)
  File "/home/airflow/.local/lib/python3.9/site-packages/airflow/utils/log/file_task_handler.py", line 211, in emit
    self.handler.emit(record)
  File "/usr/local/lib/python3.9/logging/__init__.py", line 1187, in emit
    StreamHandler.emit(self, record)
  File "/usr/local/lib/python3.9/logging/__init__.py", line 1091, in emit
    self.handleError(record)
  File "/usr/local/lib/python3.9/logging/__init__.py", line 1004, in handleError
    sys.stderr.write('--- Logging error ---\n')
  File "/home/airflow/.local/lib/python3.9/site-packages/airflow/utils/log/logging_mixin.py", line 161, in write
    self.flush()
  File "/home/airflow/.local/lib/python3.9/site-packages/airflow/utils/log/logging_mixin.py", line 168, in flush
    self._propagate_log(buf)
  File "/home/airflow/.local/lib/python3.9/site-packages/airflow/utils/log/logging_mixin.py", line 149, in _propagate_log
    self.logger.log(self.level, remove_escape_codes(message))
  File "/usr/local/lib/python3.9/logging/__init__.py", line 1512, in log
    self._log(level, msg, args, **kwargs)
  File "/usr/local/lib/python3.9/logging/__init__.py", line 1589, in _log
    self.handle(record)
  File "/usr/local/lib/python3.9/logging/__init__.py", line 1599, in handle
    self.callHandlers(record)
  File "/usr/local/lib/python3.9/logging/__init__.py", line 1661, in callHandlers
    hdlr.handle(record)
  File "/usr/local/lib/python3.9/logging/__init__.py", line 952, in handle
    self.emit(record)
  File "/home/airflow/.local/lib/python3.9/site-packages/airflow/utils/log/file_task_handler.py", line 211, in emit
    self.handler.emit(record)
  File "/usr/local/lib/python3.9/logging/__init__.py", line 1187, in emit
    StreamHandler.emit(self, record)
  File "/usr/local/lib/python3.9/logging/__init__.py", line 1091, in emit
    self.handleError(record)
  File "/usr/local/lib/python3.9/logging/__init__.py", line 1004, in handleError
    sys.stderr.write('--- Logging error ---\n')
  File "/home/airflow/.local/lib/python3.9/site-packages/airflow/utils/log/logging_mixin.py", line 161, in write
    self.flush()
  File "/home/airflow/.local/lib/python3.9/site-packages/airflow/utils/log/logging_mixin.py", line 168, in flush
    self._propagate_log(buf)
  File "/home/airflow/.local/lib/python3.9/site-packages/airflow/utils/log/logging_mixin.py", line 149, in _propagate_log
    self.logger.log(self.level, remove_escape_codes(message))
  File "/usr/local/lib/python3.9/logging/__init__.py", line 1512, in log
    self._log(level, msg, args, **kwargs)
  File "/usr/local/lib/python3.9/logging/__init__.py", line 1589, in _log
    self.handle(record)
  File "/usr/local/lib/python3.9/logging/__init__.py", line 1599, in handle
    self.callHandlers(record)
  File "/usr/local/lib/python3.9/logging/__init__.py", line 1661, in callHandlers
    hdlr.handle(record)
  File "/usr/local/lib/python3.9/logging/__init__.py", line 952, in handle
    self.emit(record)
  File "/home/airflow/.local/lib/python3.9/site-packages/airflow/utils/log/file_task_handler.py", line 211, in emit
    self.handler.emit(record)
  File "/usr/local/lib/python3.9/logging/__init__.py", line 1187, in emit
    StreamHandler.emit(self, record)
  File "/usr/local/lib/python3.9/logging/__init__.py", line 1091, in emit
    self.handleError(record)
  File "/usr/local/lib/python3.9/logging/__init__.py", line 1004, in handleError
    sys.stderr.write('--- Logging error ---\n')
  File "/home/airflow/.local/lib/python3.9/site-packages/airflow/utils/log/logging_mixin.py", line 161, in write
    self.flush()
  File "/home/airflow/.local/lib/python3.9/site-packages/airflow/utils/log/logging_mixin.py", line 168, in flush
    self._propagate_log(buf)
  File "/home/airflow/.local/lib/python3.9/site-packages/airflow/utils/log/logging_mixin.py", line 149, in _propagate_log
    self.logger.log(self.level, remove_escape_codes(message))
  File "/usr/local/lib/python3.9/logging/__init__.py", line 1512, in log
    self._log(level, msg, args, **kwargs)
  File "/usr/local/lib/python3.9/logging/__init__.py", line 1589, in _log
    self.handle(record)
  File "/usr/local/lib/python3.9/logging/__init__.py", line 1599, in handle
    self.callHandlers(record)
  File "/usr/local/lib/python3.9/logging/__init__.py", line 1661, in callHandlers
    hdlr.handle(record)
  File "/usr/local/lib/python3.9/logging/__init__.py", line 952, in handle
    self.emit(record)
  File "/home/airflow/.local/lib/python3.9/site-packages/airflow/utils/log/file_task_handler.py", line 211, in emit
    self.handler.emit(record)
  File "/usr/local/lib/python3.9/logging/__init__.py", line 1187, in emit
    StreamHandler.emit(self, record)
  File "/usr/local/lib/python3.9/logging/__init__.py", line 1091, in emit
    self.handleError(record)
  File "/usr/local/lib/python3.9/logging/__init__.py", line 1004, in handleError
    sys.stderr.write('--- Logging error ---\n')
  File "/home/airflow/.local/lib/python3.9/site-packages/airflow/utils/log/logging_mixin.py", line 161, in write
    self.flush()
  File "/home/airflow/.local/lib/python3.9/site-packages/airflow/utils/log/logging_mixin.py", line 168, in flush
    self._propagate_log(buf)
  File "/home/airflow/.local/lib/python3.9/site-packages/airflow/utils/log/logging_mixin.py", line 149, in _propagate_log
    self.logger.log(self.level, remove_escape_codes(message))
  File "/usr/local/lib/python3.9/logging/__init__.py", line 1512, in log
    self._log(level, msg, args, **kwargs)
  File "/usr/local/lib/python3.9/logging/__init__.py", line 1589, in _log
    self.handle(record)
  File "/usr/local/lib/python3.9/logging/__init__.py", line 1599, in handle
    self.callHandlers(record)
  File "/usr/local/lib/python3.9/logging/__init__.py", line 1661, in callHandlers
    hdlr.handle(record)
  File "/usr/local/lib/python3.9/logging/__init__.py", line 952, in handle
    self.emit(record)
  File "/home/airflow/.local/lib/python3.9/site-packages/airflow/utils/log/file_task_handler.py", line 211, in emit
    self.handler.emit(record)
  File "/usr/local/lib/python3.9/logging/__init__.py", line 1187, in emit
    StreamHandler.emit(self, record)
  File "/usr/local/lib/python3.9/logging/__init__.py", line 1091, in emit
    self.handleError(record)
  File "/usr/local/lib/python3.9/logging/__init__.py", line 1004, in handleError
    sys.stderr.write('--- Logging error ---\n')
  File "/home/airflow/.local/lib/python3.9/site-packages/airflow/utils/log/logging_mixin.py", line 161, in write
    self.flush()
  File "/home/airflow/.local/lib/python3.9/site-packages/airflow/utils/log/logging_mixin.py", line 168, in flush
    self._propagate_log(buf)
  File "/home/airflow/.local/lib/python3.9/site-packages/airflow/utils/log/logging_mixin.py", line 149, in _propagate_log
    self.logger.log(self.level, remove_escape_codes(message))
  File "/usr/local/lib/python3.9/logging/__init__.py", line 1512, in log
    self._log(level, msg, args, **kwargs)
  File "/usr/local/lib/python3.9/logging/__init__.py", line 1589, in _log
    self.handle(record)
  File "/usr/local/lib/python3.9/logging/__init__.py", line 1599, in handle
    self.callHandlers(record)
  File "/usr/local/lib/python3.9/logging/__init__.py", line 1661, in callHandlers
    hdlr.handle(record)
  File "/usr/local/lib/python3.9/logging/__init__.py", line 952, in handle
    self.emit(record)
  File "/home/airflow/.local/lib/python3.9/site-packages/airflow/utils/log/file_task_handler.py", line 211, in emit
    self.handler.emit(record)
  File "/usr/local/lib/python3.9/logging/__init__.py", line 1187, in emit
    StreamHandler.emit(self, record)
  File "/usr/local/lib/python3.9/logging/__init__.py", line 1091, in emit
    self.handleError(record)
  File "/usr/local/lib/python3.9/logging/__init__.py", line 1004, in handleError
    sys.stderr.write('--- Logging error ---\n')
  File "/home/airflow/.local/lib/python3.9/site-packages/airflow/utils/log/logging_mixin.py", line 161, in write
    self.flush()
  File "/home/airflow/.local/lib/python3.9/site-packages/airflow/utils/log/logging_mixin.py", line 168, in flush
    self._propagate_log(buf)
  File "/home/airflow/.local/lib/python3.9/site-packages/airflow/utils/log/logging_mixin.py", line 149, in _propagate_log
    self.logger.log(self.level, remove_escape_codes(message))
  File "/usr/local/lib/python3.9/logging/__init__.py", line 1512, in log
    self._log(level, msg, args, **kwargs)
  File "/usr/local/lib/python3.9/logging/__init__.py", line 1589, in _log
    self.handle(record)
  File "/usr/local/lib/python3.9/logging/__init__.py", line 1599, in handle
    self.callHandlers(record)
  File "/usr/local/lib/python3.9/logging/__init__.py", line 1661, in callHandlers
    hdlr.handle(record)
  File "/usr/local/lib/python3.9/logging/__init__.py", line 952, in handle
    self.emit(record)
  File "/home/airflow/.local/lib/python3.9/site-packages/airflow/utils/log/file_task_handler.py", line 211, in emit
    self.handler.emit(record)
  File "/usr/local/lib/python3.9/logging/__init__.py", line 1187, in emit
    StreamHandler.emit(self, record)
  File "/usr/local/lib/python3.9/logging/__init__.py", line 1091, in emit
    self.handleError(record)
  File "/usr/local/lib/python3.9/logging/__init__.py", line 1004, in handleError
    sys.stderr.write('--- Logging error ---\n')
  File "/home/airflow/.local/lib/python3.9/site-packages/airflow/utils/log/logging_mixin.py", line 161, in write
    self.flush()
  File "/home/airflow/.local/lib/python3.9/site-packages/airflow/utils/log/logging_mixin.py", line 168, in flush
    self._propagate_log(buf)
  File "/home/airflow/.local/lib/python3.9/site-packages/airflow/utils/log/logging_mixin.py", line 149, in _propagate_log
    self.logger.log(self.level, remove_escape_codes(message))
  File "/usr/local/lib/python3.9/logging/__init__.py", line 1512, in log
    self._log(level, msg, args, **kwargs)
  File "/usr/local/lib/python3.9/logging/__init__.py", line 1589, in _log
    self.handle(record)
  File "/usr/local/lib/python3.9/logging/__init__.py", line 1599, in handle
    self.callHandlers(record)
  File "/usr/local/lib/python3.9/logging/__init__.py", line 1661, in callHandlers
    hdlr.handle(record)
  File "/usr/local/lib/python3.9/logging/__init__.py", line 952, in handle
    self.emit(record)
  File "/home/airflow/.local/lib/python3.9/site-packages/airflow/utils/log/file_task_handler.py", line 211, in emit
    self.handler.emit(record)
  File "/usr/local/lib/python3.9/logging/__init__.py", line 1187, in emit
    StreamHandler.emit(self, record)
  File "/usr/local/lib/python3.9/logging/__init__.py", line 1091, in emit
    self.handleError(record)
  File "/usr/local/lib/python3.9/logging/__init__.py", line 1004, in handleError
    sys.stderr.write('--- Logging error ---\n')
  File "/home/airflow/.local/lib/python3.9/site-packages/airflow/utils/log/logging_mixin.py", line 161, in write
    self.flush()
  File "/home/airflow/.local/lib/python3.9/site-packages/airflow/utils/log/logging_mixin.py", line 168, in flush
    self._propagate_log(buf)
  File "/home/airflow/.local/lib/python3.9/site-packages/airflow/utils/log/logging_mixin.py", line 149, in _propagate_log
    self.logger.log(self.level, remove_escape_codes(message))
  File "/usr/local/lib/python3.9/logging/__init__.py", line 1512, in log
    self._log(level, msg, args, **kwargs)
  File "/usr/local/lib/python3.9/logging/__init__.py", line 1589, in _log
    self.handle(record)
  File "/usr/local/lib/python3.9/logging/__init__.py", line 1599, in handle
    self.callHandlers(record)
  File "/usr/local/lib/python3.9/logging/__init__.py", line 1661, in callHandlers
    hdlr.handle(record)
  File "/usr/local/lib/python3.9/logging/__init__.py", line 952, in handle
    self.emit(record)
  File "/home/airflow/.local/lib/python3.9/site-packages/airflow/utils/log/file_task_handler.py", line 211, in emit
    self.handler.emit(record)
  File "/usr/local/lib/python3.9/logging/__init__.py", line 1187, in emit
    StreamHandler.emit(self, record)
  File "/usr/local/lib/python3.9/logging/__init__.py", line 1091, in emit
    self.handleError(record)
  File "/usr/local/lib/python3.9/logging/__init__.py", line 1004, in handleError
    sys.stderr.write('--- Logging error ---\n')
  File "/home/airflow/.local/lib/python3.9/site-packages/airflow/utils/log/logging_mixin.py", line 161, in write
    self.flush()
  File "/home/airflow/.local/lib/python3.9/site-packages/airflow/utils/log/logging_mixin.py", line 168, in flush
    self._propagate_log(buf)
  File "/home/airflow/.local/lib/python3.9/site-packages/airflow/utils/log/logging_mixin.py", line 149, in _propagate_log
    self.logger.log(self.level, remove_escape_codes(message))
  File "/usr/local/lib/python3.9/logging/__init__.py", line 1512, in log
    self._log(level, msg, args, **kwargs)
  File "/usr/local/lib/python3.9/logging/__init__.py", line 1589, in _log
    self.handle(record)
  File "/usr/local/lib/python3.9/logging/__init__.py", line 1599, in handle
    self.callHandlers(record)
  File "/usr/local/lib/python3.9/logging/__init__.py", line 1661, in callHandlers
    hdlr.handle(record)
  File "/usr/local/lib/python3.9/logging/__init__.py", line 952, in handle
    self.emit(record)
  File "/home/airflow/.local/lib/python3.9/site-packages/airflow/utils/log/file_task_handler.py", line 211, in emit
    self.handler.emit(record)
  File "/usr/local/lib/python3.9/logging/__init__.py", line 1187, in emit
    StreamHandler.emit(self, record)
  File "/usr/local/lib/python3.9/logging/__init__.py", line 1091, in emit
    self.handleError(record)
  File "/usr/local/lib/python3.9/logging/__init__.py", line 1004, in handleError
    sys.stderr.write('--- Logging error ---\n')
  File "/home/airflow/.local/lib/python3.9/site-packages/airflow/utils/log/logging_mixin.py", line 161, in write
    self.flush()
  File "/home/airflow/.local/lib/python3.9/site-packages/airflow/utils/log/logging_mixin.py", line 168, in flush
    self._propagate_log(buf)
  File "/home/airflow/.local/lib/python3.9/site-packages/airflow/utils/log/logging_mixin.py", line 149, in _propagate_log
    self.logger.log(self.level, remove_escape_codes(message))
  File "/usr/local/lib/python3.9/logging/__init__.py", line 1512, in log
    self._log(level, msg, args, **kwargs)
  File "/usr/local/lib/python3.9/logging/__init__.py", line 1589, in _log
    self.handle(record)
  File "/usr/local/lib/python3.9/logging/__init__.py", line 1599, in handle
    self.callHandlers(record)
  File "/usr/local/lib/python3.9/logging/__init__.py", line 1661, in callHandlers
    hdlr.handle(record)
  File "/usr/local/lib/python3.9/logging/__init__.py", line 952, in handle
    self.emit(record)
  File "/home/airflow/.local/lib/python3.9/site-packages/airflow/utils/log/file_task_handler.py", line 211, in emit
    self.handler.emit(record)
  File "/usr/local/lib/python3.9/logging/__init__.py", line 1187, in emit
    StreamHandler.emit(self, record)
  File "/usr/local/lib/python3.9/logging/__init__.py", line 1091, in emit
    self.handleError(record)
  File "/usr/local/lib/python3.9/logging/__init__.py", line 1004, in handleError
    sys.stderr.write('--- Logging error ---\n')
  File "/home/airflow/.local/lib/python3.9/site-packages/airflow/utils/log/logging_mixin.py", line 161, in write
    self.flush()
  File "/home/airflow/.local/lib/python3.9/site-packages/airflow/utils/log/logging_mixin.py", line 168, in flush
    self._propagate_log(buf)
  File "/home/airflow/.local/lib/python3.9/site-packages/airflow/utils/log/logging_mixin.py", line 149, in _propagate_log
    self.logger.log(self.level, remove_escape_codes(message))
  File "/usr/local/lib/python3.9/logging/__init__.py", line 1512, in log
    self._log(level, msg, args, **kwargs)
  File "/usr/local/lib/python3.9/logging/__init__.py", line 1589, in _log
    self.handle(record)
  File "/usr/local/lib/python3.9/logging/__init__.py", line 1599, in handle
    self.callHandlers(record)
  File "/usr/local/lib/python3.9/logging/__init__.py", line 1661, in callHandlers
    hdlr.handle(record)
  File "/usr/local/lib/python3.9/logging/__init__.py", line 952, in handle
    self.emit(record)
  File "/home/airflow/.local/lib/python3.9/site-packages/airflow/utils/log/file_task_handler.py", line 211, in emit
    self.handler.emit(record)
  File "/usr/local/lib/python3.9/logging/__init__.py", line 1187, in emit
    StreamHandler.emit(self, record)
  File "/usr/local/lib/python3.9/logging/__init__.py", line 1091, in emit
    self.handleError(record)
  File "/usr/local/lib/python3.9/logging/__init__.py", line 1004, in handleError
    sys.stderr.write('--- Logging error ---\n')
  File "/home/airflow/.local/lib/python3.9/site-packages/airflow/utils/log/logging_mixin.py", line 161, in write
    self.flush()
  File "/home/airflow/.local/lib/python3.9/site-packages/airflow/utils/log/logging_mixin.py", line 168, in flush
    self._propagate_log(buf)
  File "/home/airflow/.local/lib/python3.9/site-packages/airflow/utils/log/logging_mixin.py", line 149, in _propagate_log
    self.logger.log(self.level, remove_escape_codes(message))
  File "/usr/local/lib/python3.9/logging/__init__.py", line 1512, in log
    self._log(level, msg, args, **kwargs)
  File "/usr/local/lib/python3.9/logging/__init__.py", line 1589, in _log
    self.handle(record)
  File "/usr/local/lib/python3.9/logging/__init__.py", line 1599, in handle
    self.callHandlers(record)
  File "/usr/local/lib/python3.9/logging/__init__.py", line 1661, in callHandlers
    hdlr.handle(record)
  File "/usr/local/lib/python3.9/logging/__init__.py", line 952, in handle
    self.emit(record)
  File "/home/airflow/.local/lib/python3.9/site-packages/airflow/utils/log/file_task_handler.py", line 211, in emit
    self.handler.emit(record)
  File "/usr/local/lib/python3.9/logging/__init__.py", line 1187, in emit
    StreamHandler.emit(self, record)
  File "/usr/local/lib/python3.9/logging/__init__.py", line 1091, in emit
    self.handleError(record)
  File "/usr/local/lib/python3.9/logging/__init__.py", line 1004, in handleError
    sys.stderr.write('--- Logging error ---\n')
  File "/home/airflow/.local/lib/python3.9/site-packages/airflow/utils/log/logging_mixin.py", line 161, in write
    self.flush()
  File "/home/airflow/.local/lib/python3.9/site-packages/airflow/utils/log/logging_mixin.py", line 168, in flush
    self._propagate_log(buf)
  File "/home/airflow/.local/lib/python3.9/site-packages/airflow/utils/log/logging_mixin.py", line 149, in _propagate_log
    self.logger.log(self.level, remove_escape_codes(message))
  File "/usr/local/lib/python3.9/logging/__init__.py", line 1512, in log
    self._log(level, msg, args, **kwargs)
  File "/usr/local/lib/python3.9/logging/__init__.py", line 1589, in _log
    self.handle(record)
  File "/usr/local/lib/python3.9/logging/__init__.py", line 1599, in handle
    self.callHandlers(record)
  File "/usr/local/lib/python3.9/logging/__init__.py", line 1661, in callHandlers
    hdlr.handle(record)
  File "/usr/local/lib/python3.9/logging/__init__.py", line 952, in handle
    self.emit(record)
  File "/home/airflow/.local/lib/python3.9/site-packages/airflow/utils/log/file_task_handler.py", line 211, in emit
    self.handler.emit(record)
  File "/usr/local/lib/python3.9/logging/__init__.py", line 1187, in emit
    StreamHandler.emit(self, record)
  File "/usr/local/lib/python3.9/logging/__init__.py", line 1091, in emit
    self.handleError(record)
  File "/usr/local/lib/python3.9/logging/__init__.py", line 1004, in handleError
    sys.stderr.write('--- Logging error ---\n')
  File "/home/airflow/.local/lib/python3.9/site-packages/airflow/utils/log/logging_mixin.py", line 161, in write
    self.flush()
  File "/home/airflow/.local/lib/python3.9/site-packages/airflow/utils/log/logging_mixin.py", line 168, in flush
    self._propagate_log(buf)
  File "/home/airflow/.local/lib/python3.9/site-packages/airflow/utils/log/logging_mixin.py", line 149, in _propagate_log
    self.logger.log(self.level, remove_escape_codes(message))
  File "/usr/local/lib/python3.9/logging/__init__.py", line 1512, in log
    self._log(level, msg, args, **kwargs)
  File "/usr/local/lib/python3.9/logging/__init__.py", line 1589, in _log
    self.handle(record)
  File "/usr/local/lib/python3.9/logging/__init__.py", line 1599, in handle
    self.callHandlers(record)
  File "/usr/local/lib/python3.9/logging/__init__.py", line 1661, in callHandlers
    hdlr.handle(record)
  File "/usr/local/lib/python3.9/logging/__init__.py", line 952, in handle
    self.emit(record)
  File "/home/airflow/.local/lib/python3.9/site-packages/airflow/utils/log/file_task_handler.py", line 211, in emit
    self.handler.emit(record)
  File "/usr/local/lib/python3.9/logging/__init__.py", line 1187, in emit
    StreamHandler.emit(self, record)
  File "/usr/local/lib/python3.9/logging/__init__.py", line 1091, in emit
    self.handleError(record)
  File "/usr/local/lib/python3.9/logging/__init__.py", line 1004, in handleError
    sys.stderr.write('--- Logging error ---\n')
  File "/home/airflow/.local/lib/python3.9/site-packages/airflow/utils/log/logging_mixin.py", line 161, in write
    self.flush()
  File "/home/airflow/.local/lib/python3.9/site-packages/airflow/utils/log/logging_mixin.py", line 168, in flush
    self._propagate_log(buf)
  File "/home/airflow/.local/lib/python3.9/site-packages/airflow/utils/log/logging_mixin.py", line 149, in _propagate_log
    self.logger.log(self.level, remove_escape_codes(message))
  File "/usr/local/lib/python3.9/logging/__init__.py", line 1512, in log
    self._log(level, msg, args, **kwargs)
  File "/usr/local/lib/python3.9/logging/__init__.py", line 1589, in _log
    self.handle(record)
  File "/usr/local/lib/python3.9/logging/__init__.py", line 1599, in handle
    self.callHandlers(record)
  File "/usr/local/lib/python3.9/logging/__init__.py", line 1661, in callHandlers
    hdlr.handle(record)
  File "/usr/local/lib/python3.9/logging/__init__.py", line 952, in handle
    self.emit(record)
  File "/home/airflow/.local/lib/python3.9/site-packages/airflow/utils/log/file_task_handler.py", line 211, in emit
    self.handler.emit(record)
  File "/usr/local/lib/python3.9/logging/__init__.py", line 1187, in emit
    StreamHandler.emit(self, record)
  File "/usr/local/lib/python3.9/logging/__init__.py", line 1091, in emit
    self.handleError(record)
  File "/usr/local/lib/python3.9/logging/__init__.py", line 1004, in handleError
    sys.stderr.write('--- Logging error ---\n')
  File "/home/airflow/.local/lib/python3.9/site-packages/airflow/utils/log/logging_mixin.py", line 161, in write
    self.flush()
  File "/home/airflow/.local/lib/python3.9/site-packages/airflow/utils/log/logging_mixin.py", line 168, in flush
    self._propagate_log(buf)
  File "/home/airflow/.local/lib/python3.9/site-packages/airflow/utils/log/logging_mixin.py", line 149, in _propagate_log
    self.logger.log(self.level, remove_escape_codes(message))
  File "/usr/local/lib/python3.9/logging/__init__.py", line 1512, in log
    self._log(level, msg, args, **kwargs)
  File "/usr/local/lib/python3.9/logging/__init__.py", line 1589, in _log
    self.handle(record)
  File "/usr/local/lib/python3.9/logging/__init__.py", line 1599, in handle
    self.callHandlers(record)
  File "/usr/local/lib/python3.9/logging/__init__.py", line 1661, in callHandlers
    hdlr.handle(record)
  File "/usr/local/lib/python3.9/logging/__init__.py", line 952, in handle
    self.emit(record)
  File "/home/airflow/.local/lib/python3.9/site-packages/airflow/utils/log/file_task_handler.py", line 211, in emit
    self.handler.emit(record)
  File "/usr/local/lib/python3.9/logging/__init__.py", line 1187, in emit
    StreamHandler.emit(self, record)
  File "/usr/local/lib/python3.9/logging/__init__.py", line 1091, in emit
    self.handleError(record)
  File "/usr/local/lib/python3.9/logging/__init__.py", line 1004, in handleError
    sys.stderr.write('--- Logging error ---\n')
  File "/home/airflow/.local/lib/python3.9/site-packages/airflow/utils/log/logging_mixin.py", line 161, in write
    self.flush()
  File "/home/airflow/.local/lib/python3.9/site-packages/airflow/utils/log/logging_mixin.py", line 168, in flush
    self._propagate_log(buf)
  File "/home/airflow/.local/lib/python3.9/site-packages/airflow/utils/log/logging_mixin.py", line 149, in _propagate_log
    self.logger.log(self.level, remove_escape_codes(message))
  File "/usr/local/lib/python3.9/logging/__init__.py", line 1512, in log
    self._log(level, msg, args, **kwargs)
  File "/usr/local/lib/python3.9/logging/__init__.py", line 1589, in _log
    self.handle(record)
  File "/usr/local/lib/python3.9/logging/__init__.py", line 1599, in handle
    self.callHandlers(record)
  File "/usr/local/lib/python3.9/logging/__init__.py", line 1661, in callHandlers
    hdlr.handle(record)
  File "/usr/local/lib/python3.9/logging/__init__.py", line 952, in handle
    self.emit(record)
  File "/home/airflow/.local/lib/python3.9/site-packages/airflow/utils/log/file_task_handler.py", line 211, in emit
    self.handler.emit(record)
  File "/usr/local/lib/python3.9/logging/__init__.py", line 1187, in emit
    StreamHandler.emit(self, record)
  File "/usr/local/lib/python3.9/logging/__init__.py", line 1091, in emit
    self.handleError(record)
  File "/usr/local/lib/python3.9/logging/__init__.py", line 1004, in handleError
    sys.stderr.write('--- Logging error ---\n')
  File "/home/airflow/.local/lib/python3.9/site-packages/airflow/utils/log/logging_mixin.py", line 161, in write
    self.flush()
  File "/home/airflow/.local/lib/python3.9/site-packages/airflow/utils/log/logging_mixin.py", line 168, in flush
    self._propagate_log(buf)
  File "/home/airflow/.local/lib/python3.9/site-packages/airflow/utils/log/logging_mixin.py", line 149, in _propagate_log
    self.logger.log(self.level, remove_escape_codes(message))
  File "/usr/local/lib/python3.9/logging/__init__.py", line 1512, in log
    self._log(level, msg, args, **kwargs)
  File "/usr/local/lib/python3.9/logging/__init__.py", line 1589, in _log
    self.handle(record)
  File "/usr/local/lib/python3.9/logging/__init__.py", line 1599, in handle
    self.callHandlers(record)
  File "/usr/local/lib/python3.9/logging/__init__.py", line 1661, in callHandlers
    hdlr.handle(record)
  File "/usr/local/lib/python3.9/logging/__init__.py", line 952, in handle
    self.emit(record)
  File "/home/airflow/.local/lib/python3.9/site-packages/airflow/utils/log/file_task_handler.py", line 211, in emit
    self.handler.emit(record)
  File "/usr/local/lib/python3.9/logging/__init__.py", line 1187, in emit
    StreamHandler.emit(self, record)
  File "/usr/local/lib/python3.9/logging/__init__.py", line 1091, in emit
    self.handleError(record)
  File "/usr/local/lib/python3.9/logging/__init__.py", line 1004, in handleError
    sys.stderr.write('--- Logging error ---\n')
  File "/home/airflow/.local/lib/python3.9/site-packages/airflow/utils/log/logging_mixin.py", line 161, in write
    self.flush()
  File "/home/airflow/.local/lib/python3.9/site-packages/airflow/utils/log/logging_mixin.py", line 168, in flush
    self._propagate_log(buf)
  File "/home/airflow/.local/lib/python3.9/site-packages/airflow/utils/log/logging_mixin.py", line 149, in _propagate_log
    self.logger.log(self.level, remove_escape_codes(message))
  File "/usr/local/lib/python3.9/logging/__init__.py", line 1512, in log
    self._log(level, msg, args, **kwargs)
  File "/usr/local/lib/python3.9/logging/__init__.py", line 1589, in _log
    self.handle(record)
  File "/usr/local/lib/python3.9/logging/__init__.py", line 1599, in handle
    self.callHandlers(record)
  File "/usr/local/lib/python3.9/logging/__init__.py", line 1661, in callHandlers
    hdlr.handle(record)
  File "/usr/local/lib/python3.9/logging/__init__.py", line 952, in handle
    self.emit(record)
  File "/home/airflow/.local/lib/python3.9/site-packages/airflow/utils/log/file_task_handler.py", line 211, in emit
    self.handler.emit(record)
  File "/usr/local/lib/python3.9/logging/__init__.py", line 1187, in emit
    StreamHandler.emit(self, record)
  File "/usr/local/lib/python3.9/logging/__init__.py", line 1091, in emit
    self.handleError(record)
  File "/usr/local/lib/python3.9/logging/__init__.py", line 1004, in handleError
    sys.stderr.write('--- Logging error ---\n')
  File "/home/airflow/.local/lib/python3.9/site-packages/airflow/utils/log/logging_mixin.py", line 161, in write
    self.flush()
  File "/home/airflow/.local/lib/python3.9/site-packages/airflow/utils/log/logging_mixin.py", line 168, in flush
    self._propagate_log(buf)
  File "/home/airflow/.local/lib/python3.9/site-packages/airflow/utils/log/logging_mixin.py", line 149, in _propagate_log
    self.logger.log(self.level, remove_escape_codes(message))
  File "/usr/local/lib/python3.9/logging/__init__.py", line 1512, in log
    self._log(level, msg, args, **kwargs)
  File "/usr/local/lib/python3.9/logging/__init__.py", line 1589, in _log
    self.handle(record)
  File "/usr/local/lib/python3.9/logging/__init__.py", line 1599, in handle
    self.callHandlers(record)
  File "/usr/local/lib/python3.9/logging/__init__.py", line 1661, in callHandlers
    hdlr.handle(record)
  File "/usr/local/lib/python3.9/logging/__init__.py", line 952, in handle
    self.emit(record)
  File "/home/airflow/.local/lib/python3.9/site-packages/airflow/utils/log/file_task_handler.py", line 211, in emit
    self.handler.emit(record)
  File "/usr/local/lib/python3.9/logging/__init__.py", line 1187, in emit
    StreamHandler.emit(self, record)
  File "/usr/local/lib/python3.9/logging/__init__.py", line 1091, in emit
    self.handleError(record)
  File "/usr/local/lib/python3.9/logging/__init__.py", line 1004, in handleError
    sys.stderr.write('--- Logging error ---\n')
  File "/home/airflow/.local/lib/python3.9/site-packages/airflow/utils/log/logging_mixin.py", line 161, in write
    self.flush()
  File "/home/airflow/.local/lib/python3.9/site-packages/airflow/utils/log/logging_mixin.py", line 168, in flush
    self._propagate_log(buf)
  File "/home/airflow/.local/lib/python3.9/site-packages/airflow/utils/log/logging_mixin.py", line 149, in _propagate_log
    self.logger.log(self.level, remove_escape_codes(message))
  File "/usr/local/lib/python3.9/logging/__init__.py", line 1512, in log
    self._log(level, msg, args, **kwargs)
  File "/usr/local/lib/python3.9/logging/__init__.py", line 1589, in _log
    self.handle(record)
  File "/usr/local/lib/python3.9/logging/__init__.py", line 1599, in handle
    self.callHandlers(record)
  File "/usr/local/lib/python3.9/logging/__init__.py", line 1661, in callHandlers
    hdlr.handle(record)
  File "/usr/local/lib/python3.9/logging/__init__.py", line 952, in handle
    self.emit(record)
  File "/home/airflow/.local/lib/python3.9/site-packages/airflow/utils/log/file_task_handler.py", line 211, in emit
    self.handler.emit(record)
  File "/usr/local/lib/python3.9/logging/__init__.py", line 1187, in emit
    StreamHandler.emit(self, record)
  File "/usr/local/lib/python3.9/logging/__init__.py", line 1091, in emit
    self.handleError(record)
  File "/usr/local/lib/python3.9/logging/__init__.py", line 1004, in handleError
    sys.stderr.write('--- Logging error ---\n')
  File "/home/airflow/.local/lib/python3.9/site-packages/airflow/utils/log/logging_mixin.py", line 161, in write
    self.flush()
  File "/home/airflow/.local/lib/python3.9/site-packages/airflow/utils/log/logging_mixin.py", line 168, in flush
    self._propagate_log(buf)
  File "/home/airflow/.local/lib/python3.9/site-packages/airflow/utils/log/logging_mixin.py", line 149, in _propagate_log
    self.logger.log(self.level, remove_escape_codes(message))
  File "/usr/local/lib/python3.9/logging/__init__.py", line 1512, in log
    self._log(level, msg, args, **kwargs)
  File "/usr/local/lib/python3.9/logging/__init__.py", line 1589, in _log
    self.handle(record)
  File "/usr/local/lib/python3.9/logging/__init__.py", line 1599, in handle
    self.callHandlers(record)
  File "/usr/local/lib/python3.9/logging/__init__.py", line 1661, in callHandlers
    hdlr.handle(record)
  File "/usr/local/lib/python3.9/logging/__init__.py", line 952, in handle
    self.emit(record)
  File "/home/airflow/.local/lib/python3.9/site-packages/airflow/utils/log/file_task_handler.py", line 211, in emit
    self.handler.emit(record)
  File "/usr/local/lib/python3.9/logging/__init__.py", line 1187, in emit
    StreamHandler.emit(self, record)
  File "/usr/local/lib/python3.9/logging/__init__.py", line 1091, in emit
    self.handleError(record)
  File "/usr/local/lib/python3.9/logging/__init__.py", line 1004, in handleError
    sys.stderr.write('--- Logging error ---\n')
  File "/home/airflow/.local/lib/python3.9/site-packages/airflow/utils/log/logging_mixin.py", line 161, in write
    self.flush()
  File "/home/airflow/.local/lib/python3.9/site-packages/airflow/utils/log/logging_mixin.py", line 168, in flush
    self._propagate_log(buf)
  File "/home/airflow/.local/lib/python3.9/site-packages/airflow/utils/log/logging_mixin.py", line 149, in _propagate_log
    self.logger.log(self.level, remove_escape_codes(message))
  File "/usr/local/lib/python3.9/logging/__init__.py", line 1512, in log
    self._log(level, msg, args, **kwargs)
  File "/usr/local/lib/python3.9/logging/__init__.py", line 1589, in _log
    self.handle(record)
  File "/usr/local/lib/python3.9/logging/__init__.py", line 1599, in handle
    self.callHandlers(record)
  File "/usr/local/lib/python3.9/logging/__init__.py", line 1661, in callHandlers
    hdlr.handle(record)
  File "/usr/local/lib/python3.9/logging/__init__.py", line 952, in handle
    self.emit(record)
  File "/home/airflow/.local/lib/python3.9/site-packages/airflow/utils/log/file_task_handler.py", line 211, in emit
    self.handler.emit(record)
  File "/usr/local/lib/python3.9/logging/__init__.py", line 1187, in emit
    StreamHandler.emit(self, record)
  File "/usr/local/lib/python3.9/logging/__init__.py", line 1091, in emit
    self.handleError(record)
  File "/usr/local/lib/python3.9/logging/__init__.py", line 1004, in handleError
    sys.stderr.write('--- Logging error ---\n')
  File "/home/airflow/.local/lib/python3.9/site-packages/airflow/utils/log/logging_mixin.py", line 161, in write
    self.flush()
  File "/home/airflow/.local/lib/python3.9/site-packages/airflow/utils/log/logging_mixin.py", line 168, in flush
    self._propagate_log(buf)
  File "/home/airflow/.local/lib/python3.9/site-packages/airflow/utils/log/logging_mixin.py", line 149, in _propagate_log
    self.logger.log(self.level, remove_escape_codes(message))
  File "/usr/local/lib/python3.9/logging/__init__.py", line 1512, in log
    self._log(level, msg, args, **kwargs)
  File "/usr/local/lib/python3.9/logging/__init__.py", line 1589, in _log
    self.handle(record)
  File "/usr/local/lib/python3.9/logging/__init__.py", line 1599, in handle
    self.callHandlers(record)
  File "/usr/local/lib/python3.9/logging/__init__.py", line 1661, in callHandlers
    hdlr.handle(record)
  File "/usr/local/lib/python3.9/logging/__init__.py", line 952, in handle
    self.emit(record)
  File "/home/airflow/.local/lib/python3.9/site-packages/airflow/utils/log/file_task_handler.py", line 211, in emit
    self.handler.emit(record)
  File "/usr/local/lib/python3.9/logging/__init__.py", line 1187, in emit
    StreamHandler.emit(self, record)
  File "/usr/local/lib/python3.9/logging/__init__.py", line 1091, in emit
    self.handleError(record)
  File "/usr/local/lib/python3.9/logging/__init__.py", line 1004, in handleError
    sys.stderr.write('--- Logging error ---\n')
  File "/home/airflow/.local/lib/python3.9/site-packages/airflow/utils/log/logging_mixin.py", line 161, in write
    self.flush()
  File "/home/airflow/.local/lib/python3.9/site-packages/airflow/utils/log/logging_mixin.py", line 168, in flush
    self._propagate_log(buf)
  File "/home/airflow/.local/lib/python3.9/site-packages/airflow/utils/log/logging_mixin.py", line 149, in _propagate_log
    self.logger.log(self.level, remove_escape_codes(message))
  File "/usr/local/lib/python3.9/logging/__init__.py", line 1512, in log
    self._log(level, msg, args, **kwargs)
  File "/usr/local/lib/python3.9/logging/__init__.py", line 1589, in _log
    self.handle(record)
  File "/usr/local/lib/python3.9/logging/__init__.py", line 1599, in handle
    self.callHandlers(record)
  File "/usr/local/lib/python3.9/logging/__init__.py", line 1661, in callHandlers
    hdlr.handle(record)
  File "/usr/local/lib/python3.9/logging/__init__.py", line 952, in handle
    self.emit(record)
  File "/home/airflow/.local/lib/python3.9/site-packages/airflow/utils/log/file_task_handler.py", line 211, in emit
    self.handler.emit(record)
  File "/usr/local/lib/python3.9/logging/__init__.py", line 1187, in emit
    StreamHandler.emit(self, record)
  File "/usr/local/lib/python3.9/logging/__init__.py", line 1091, in emit
    self.handleError(record)
  File "/usr/local/lib/python3.9/logging/__init__.py", line 1004, in handleError
    sys.stderr.write('--- Logging error ---\n')
  File "/home/airflow/.local/lib/python3.9/site-packages/airflow/utils/log/logging_mixin.py", line 161, in write
    self.flush()
  File "/home/airflow/.local/lib/python3.9/site-packages/airflow/utils/log/logging_mixin.py", line 168, in flush
    self._propagate_log(buf)
  File "/home/airflow/.local/lib/python3.9/site-packages/airflow/utils/log/logging_mixin.py", line 149, in _propagate_log
    self.logger.log(self.level, remove_escape_codes(message))
  File "/usr/local/lib/python3.9/logging/__init__.py", line 1512, in log
    self._log(level, msg, args, **kwargs)
  File "/usr/local/lib/python3.9/logging/__init__.py", line 1589, in _log
    self.handle(record)
  File "/usr/local/lib/python3.9/logging/__init__.py", line 1599, in handle
    self.callHandlers(record)
  File "/usr/local/lib/python3.9/logging/__init__.py", line 1661, in callHandlers
    hdlr.handle(record)
  File "/usr/local/lib/python3.9/logging/__init__.py", line 952, in handle
    self.emit(record)
  File "/home/airflow/.local/lib/python3.9/site-packages/airflow/utils/log/file_task_handler.py", line 211, in emit
    self.handler.emit(record)
  File "/usr/local/lib/python3.9/logging/__init__.py", line 1187, in emit
    StreamHandler.emit(self, record)
  File "/usr/local/lib/python3.9/logging/__init__.py", line 1091, in emit
    self.handleError(record)
  File "/usr/local/lib/python3.9/logging/__init__.py", line 1004, in handleError
    sys.stderr.write('--- Logging error ---\n')
  File "/home/airflow/.local/lib/python3.9/site-packages/airflow/utils/log/logging_mixin.py", line 161, in write
    self.flush()
  File "/home/airflow/.local/lib/python3.9/site-packages/airflow/utils/log/logging_mixin.py", line 168, in flush
    self._propagate_log(buf)
  File "/home/airflow/.local/lib/python3.9/site-packages/airflow/utils/log/logging_mixin.py", line 149, in _propagate_log
    self.logger.log(self.level, remove_escape_codes(message))
  File "/usr/local/lib/python3.9/logging/__init__.py", line 1512, in log
    self._log(level, msg, args, **kwargs)
  File "/usr/local/lib/python3.9/logging/__init__.py", line 1589, in _log
    self.handle(record)
  File "/usr/local/lib/python3.9/logging/__init__.py", line 1599, in handle
    self.callHandlers(record)
  File "/usr/local/lib/python3.9/logging/__init__.py", line 1661, in callHandlers
    hdlr.handle(record)
  File "/usr/local/lib/python3.9/logging/__init__.py", line 952, in handle
    self.emit(record)
  File "/home/airflow/.local/lib/python3.9/site-packages/airflow/utils/log/file_task_handler.py", line 211, in emit
    self.handler.emit(record)
  File "/usr/local/lib/python3.9/logging/__init__.py", line 1187, in emit
    StreamHandler.emit(self, record)
  File "/usr/local/lib/python3.9/logging/__init__.py", line 1091, in emit
    self.handleError(record)
  File "/usr/local/lib/python3.9/logging/__init__.py", line 1004, in handleError
    sys.stderr.write('--- Logging error ---\n')
  File "/home/airflow/.local/lib/python3.9/site-packages/airflow/utils/log/logging_mixin.py", line 161, in write
    self.flush()
  File "/home/airflow/.local/lib/python3.9/site-packages/airflow/utils/log/logging_mixin.py", line 168, in flush
    self._propagate_log(buf)
  File "/home/airflow/.local/lib/python3.9/site-packages/airflow/utils/log/logging_mixin.py", line 149, in _propagate_log
    self.logger.log(self.level, remove_escape_codes(message))
  File "/usr/local/lib/python3.9/logging/__init__.py", line 1512, in log
    self._log(level, msg, args, **kwargs)
  File "/usr/local/lib/python3.9/logging/__init__.py", line 1589, in _log
    self.handle(record)
  File "/usr/local/lib/python3.9/logging/__init__.py", line 1599, in handle
    self.callHandlers(record)
  File "/usr/local/lib/python3.9/logging/__init__.py", line 1661, in callHandlers
    hdlr.handle(record)
  File "/usr/local/lib/python3.9/logging/__init__.py", line 952, in handle
    self.emit(record)
  File "/home/airflow/.local/lib/python3.9/site-packages/airflow/utils/log/file_task_handler.py", line 211, in emit
    self.handler.emit(record)
  File "/usr/local/lib/python3.9/logging/__init__.py", line 1187, in emit
    StreamHandler.emit(self, record)
  File "/usr/local/lib/python3.9/logging/__init__.py", line 1091, in emit
    self.handleError(record)
  File "/usr/local/lib/python3.9/logging/__init__.py", line 1004, in handleError
    sys.stderr.write('--- Logging error ---\n')
  File "/home/airflow/.local/lib/python3.9/site-packages/airflow/utils/log/logging_mixin.py", line 161, in write
    self.flush()
  File "/home/airflow/.local/lib/python3.9/site-packages/airflow/utils/log/logging_mixin.py", line 168, in flush
    self._propagate_log(buf)
  File "/home/airflow/.local/lib/python3.9/site-packages/airflow/utils/log/logging_mixin.py", line 149, in _propagate_log
    self.logger.log(self.level, remove_escape_codes(message))
  File "/usr/local/lib/python3.9/logging/__init__.py", line 1512, in log
    self._log(level, msg, args, **kwargs)
  File "/usr/local/lib/python3.9/logging/__init__.py", line 1589, in _log
    self.handle(record)
  File "/usr/local/lib/python3.9/logging/__init__.py", line 1599, in handle
    self.callHandlers(record)
  File "/usr/local/lib/python3.9/logging/__init__.py", line 1661, in callHandlers
    hdlr.handle(record)
  File "/usr/local/lib/python3.9/logging/__init__.py", line 952, in handle
    self.emit(record)
  File "/home/airflow/.local/lib/python3.9/site-packages/airflow/utils/log/file_task_handler.py", line 211, in emit
    self.handler.emit(record)
  File "/usr/local/lib/python3.9/logging/__init__.py", line 1187, in emit
    StreamHandler.emit(self, record)
  File "/usr/local/lib/python3.9/logging/__init__.py", line 1091, in emit
    self.handleError(record)
  File "/usr/local/lib/python3.9/logging/__init__.py", line 1004, in handleError
    sys.stderr.write('--- Logging error ---\n')
  File "/home/airflow/.local/lib/python3.9/site-packages/airflow/utils/log/logging_mixin.py", line 161, in write
    self.flush()
  File "/home/airflow/.local/lib/python3.9/site-packages/airflow/utils/log/logging_mixin.py", line 168, in flush
    self._propagate_log(buf)
  File "/home/airflow/.local/lib/python3.9/site-packages/airflow/utils/log/logging_mixin.py", line 149, in _propagate_log
    self.logger.log(self.level, remove_escape_codes(message))
  File "/usr/local/lib/python3.9/logging/__init__.py", line 1512, in log
    self._log(level, msg, args, **kwargs)
  File "/usr/local/lib/python3.9/logging/__init__.py", line 1589, in _log
    self.handle(record)
  File "/usr/local/lib/python3.9/logging/__init__.py", line 1599, in handle
    self.callHandlers(record)
  File "/usr/local/lib/python3.9/logging/__init__.py", line 1661, in callHandlers
    hdlr.handle(record)
  File "/usr/local/lib/python3.9/logging/__init__.py", line 952, in handle
    self.emit(record)
  File "/home/airflow/.local/lib/python3.9/site-packages/airflow/utils/log/file_task_handler.py", line 211, in emit
    self.handler.emit(record)
  File "/usr/local/lib/python3.9/logging/__init__.py", line 1187, in emit
    StreamHandler.emit(self, record)
  File "/usr/local/lib/python3.9/logging/__init__.py", line 1091, in emit
    self.handleError(record)
  File "/usr/local/lib/python3.9/logging/__init__.py", line 1004, in handleError
    sys.stderr.write('--- Logging error ---\n')
  File "/home/airflow/.local/lib/python3.9/site-packages/airflow/utils/log/logging_mixin.py", line 161, in write
    self.flush()
  File "/home/airflow/.local/lib/python3.9/site-packages/airflow/utils/log/logging_mixin.py", line 168, in flush
    self._propagate_log(buf)
  File "/home/airflow/.local/lib/python3.9/site-packages/airflow/utils/log/logging_mixin.py", line 149, in _propagate_log
    self.logger.log(self.level, remove_escape_codes(message))
  File "/usr/local/lib/python3.9/logging/__init__.py", line 1512, in log
    self._log(level, msg, args, **kwargs)
  File "/usr/local/lib/python3.9/logging/__init__.py", line 1589, in _log
    self.handle(record)
  File "/usr/local/lib/python3.9/logging/__init__.py", line 1599, in handle
    self.callHandlers(record)
  File "/usr/local/lib/python3.9/logging/__init__.py", line 1661, in callHandlers
    hdlr.handle(record)
  File "/usr/local/lib/python3.9/logging/__init__.py", line 952, in handle
    self.emit(record)
  File "/home/airflow/.local/lib/python3.9/site-packages/airflow/utils/log/file_task_handler.py", line 211, in emit
    self.handler.emit(record)
  File "/usr/local/lib/python3.9/logging/__init__.py", line 1187, in emit
    StreamHandler.emit(self, record)
  File "/usr/local/lib/python3.9/logging/__init__.py", line 1091, in emit
    self.handleError(record)
  File "/usr/local/lib/python3.9/logging/__init__.py", line 1004, in handleError
    sys.stderr.write('--- Logging error ---\n')
  File "/home/airflow/.local/lib/python3.9/site-packages/airflow/utils/log/logging_mixin.py", line 161, in write
    self.flush()
  File "/home/airflow/.local/lib/python3.9/site-packages/airflow/utils/log/logging_mixin.py", line 168, in flush
    self._propagate_log(buf)
  File "/home/airflow/.local/lib/python3.9/site-packages/airflow/utils/log/logging_mixin.py", line 149, in _propagate_log
    self.logger.log(self.level, remove_escape_codes(message))
  File "/usr/local/lib/python3.9/logging/__init__.py", line 1512, in log
    self._log(level, msg, args, **kwargs)
  File "/usr/local/lib/python3.9/logging/__init__.py", line 1589, in _log
    self.handle(record)
  File "/usr/local/lib/python3.9/logging/__init__.py", line 1599, in handle
    self.callHandlers(record)
  File "/usr/local/lib/python3.9/logging/__init__.py", line 1661, in callHandlers
    hdlr.handle(record)
  File "/usr/local/lib/python3.9/logging/__init__.py", line 952, in handle
    self.emit(record)
  File "/home/airflow/.local/lib/python3.9/site-packages/airflow/utils/log/file_task_handler.py", line 211, in emit
    self.handler.emit(record)
  File "/usr/local/lib/python3.9/logging/__init__.py", line 1187, in emit
    StreamHandler.emit(self, record)
  File "/usr/local/lib/python3.9/logging/__init__.py", line 1091, in emit
    self.handleError(record)
  File "/usr/local/lib/python3.9/logging/__init__.py", line 1004, in handleError
    sys.stderr.write('--- Logging error ---\n')
  File "/home/airflow/.local/lib/python3.9/site-packages/airflow/utils/log/logging_mixin.py", line 161, in write
    self.flush()
  File "/home/airflow/.local/lib/python3.9/site-packages/airflow/utils/log/logging_mixin.py", line 168, in flush
    self._propagate_log(buf)
  File "/home/airflow/.local/lib/python3.9/site-packages/airflow/utils/log/logging_mixin.py", line 149, in _propagate_log
    self.logger.log(self.level, remove_escape_codes(message))
  File "/usr/local/lib/python3.9/logging/__init__.py", line 1512, in log
    self._log(level, msg, args, **kwargs)
  File "/usr/local/lib/python3.9/logging/__init__.py", line 1589, in _log
    self.handle(record)
  File "/usr/local/lib/python3.9/logging/__init__.py", line 1599, in handle
    self.callHandlers(record)
  File "/usr/local/lib/python3.9/logging/__init__.py", line 1661, in callHandlers
    hdlr.handle(record)
  File "/usr/local/lib/python3.9/logging/__init__.py", line 952, in handle
    self.emit(record)
  File "/home/airflow/.local/lib/python3.9/site-packages/airflow/utils/log/file_task_handler.py", line 211, in emit
    self.handler.emit(record)
  File "/usr/local/lib/python3.9/logging/__init__.py", line 1187, in emit
    StreamHandler.emit(self, record)
  File "/usr/local/lib/python3.9/logging/__init__.py", line 1091, in emit
    self.handleError(record)
  File "/usr/local/lib/python3.9/logging/__init__.py", line 1004, in handleError
    sys.stderr.write('--- Logging error ---\n')
  File "/home/airflow/.local/lib/python3.9/site-packages/airflow/utils/log/logging_mixin.py", line 161, in write
    self.flush()
  File "/home/airflow/.local/lib/python3.9/site-packages/airflow/utils/log/logging_mixin.py", line 168, in flush
    self._propagate_log(buf)
  File "/home/airflow/.local/lib/python3.9/site-packages/airflow/utils/log/logging_mixin.py", line 149, in _propagate_log
    self.logger.log(self.level, remove_escape_codes(message))
  File "/usr/local/lib/python3.9/logging/__init__.py", line 1512, in log
    self._log(level, msg, args, **kwargs)
  File "/usr/local/lib/python3.9/logging/__init__.py", line 1589, in _log
    self.handle(record)
  File "/usr/local/lib/python3.9/logging/__init__.py", line 1599, in handle
    self.callHandlers(record)
  File "/usr/local/lib/python3.9/logging/__init__.py", line 1661, in callHandlers
    hdlr.handle(record)
  File "/usr/local/lib/python3.9/logging/__init__.py", line 952, in handle
    self.emit(record)
  File "/home/airflow/.local/lib/python3.9/site-packages/airflow/utils/log/file_task_handler.py", line 211, in emit
    self.handler.emit(record)
  File "/usr/local/lib/python3.9/logging/__init__.py", line 1187, in emit
    StreamHandler.emit(self, record)
  File "/usr/local/lib/python3.9/logging/__init__.py", line 1091, in emit
    self.handleError(record)
  File "/usr/local/lib/python3.9/logging/__init__.py", line 1004, in handleError
    sys.stderr.write('--- Logging error ---\n')
  File "/home/airflow/.local/lib/python3.9/site-packages/airflow/utils/log/logging_mixin.py", line 161, in write
    self.flush()
  File "/home/airflow/.local/lib/python3.9/site-packages/airflow/utils/log/logging_mixin.py", line 168, in flush
    self._propagate_log(buf)
  File "/home/airflow/.local/lib/python3.9/site-packages/airflow/utils/log/logging_mixin.py", line 149, in _propagate_log
    self.logger.log(self.level, remove_escape_codes(message))
  File "/usr/local/lib/python3.9/logging/__init__.py", line 1512, in log
    self._log(level, msg, args, **kwargs)
  File "/usr/local/lib/python3.9/logging/__init__.py", line 1589, in _log
    self.handle(record)
  File "/usr/local/lib/python3.9/logging/__init__.py", line 1599, in handle
    self.callHandlers(record)
  File "/usr/local/lib/python3.9/logging/__init__.py", line 1661, in callHandlers
    hdlr.handle(record)
  File "/usr/local/lib/python3.9/logging/__init__.py", line 952, in handle
    self.emit(record)
  File "/home/airflow/.local/lib/python3.9/site-packages/airflow/utils/log/file_task_handler.py", line 211, in emit
    self.handler.emit(record)
  File "/usr/local/lib/python3.9/logging/__init__.py", line 1187, in emit
    StreamHandler.emit(self, record)
  File "/usr/local/lib/python3.9/logging/__init__.py", line 1091, in emit
    self.handleError(record)
  File "/usr/local/lib/python3.9/logging/__init__.py", line 1004, in handleError
    sys.stderr.write('--- Logging error ---\n')
  File "/home/airflow/.local/lib/python3.9/site-packages/airflow/utils/log/logging_mixin.py", line 161, in write
    self.flush()
  File "/home/airflow/.local/lib/python3.9/site-packages/airflow/utils/log/logging_mixin.py", line 168, in flush
    self._propagate_log(buf)
  File "/home/airflow/.local/lib/python3.9/site-packages/airflow/utils/log/logging_mixin.py", line 149, in _propagate_log
    self.logger.log(self.level, remove_escape_codes(message))
  File "/usr/local/lib/python3.9/logging/__init__.py", line 1512, in log
    self._log(level, msg, args, **kwargs)
  File "/usr/local/lib/python3.9/logging/__init__.py", line 1589, in _log
    self.handle(record)
  File "/usr/local/lib/python3.9/logging/__init__.py", line 1599, in handle
    self.callHandlers(record)
  File "/usr/local/lib/python3.9/logging/__init__.py", line 1661, in callHandlers
    hdlr.handle(record)
  File "/usr/local/lib/python3.9/logging/__init__.py", line 952, in handle
    self.emit(record)
  File "/home/airflow/.local/lib/python3.9/site-packages/airflow/utils/log/file_task_handler.py", line 211, in emit
    self.handler.emit(record)
  File "/usr/local/lib/python3.9/logging/__init__.py", line 1187, in emit
    StreamHandler.emit(self, record)
  File "/usr/local/lib/python3.9/logging/__init__.py", line 1091, in emit
    self.handleError(record)
  File "/usr/local/lib/python3.9/logging/__init__.py", line 1004, in handleError
    sys.stderr.write('--- Logging error ---\n')
  File "/home/airflow/.local/lib/python3.9/site-packages/airflow/utils/log/logging_mixin.py", line 161, in write
    self.flush()
  File "/home/airflow/.local/lib/python3.9/site-packages/airflow/utils/log/logging_mixin.py", line 168, in flush
    self._propagate_log(buf)
  File "/home/airflow/.local/lib/python3.9/site-packages/airflow/utils/log/logging_mixin.py", line 149, in _propagate_log
    self.logger.log(self.level, remove_escape_codes(message))
  File "/usr/local/lib/python3.9/logging/__init__.py", line 1512, in log
    self._log(level, msg, args, **kwargs)
  File "/usr/local/lib/python3.9/logging/__init__.py", line 1589, in _log
    self.handle(record)
  File "/usr/local/lib/python3.9/logging/__init__.py", line 1599, in handle
    self.callHandlers(record)
  File "/usr/local/lib/python3.9/logging/__init__.py", line 1661, in callHandlers
    hdlr.handle(record)
  File "/usr/local/lib/python3.9/logging/__init__.py", line 952, in handle
    self.emit(record)
  File "/home/airflow/.local/lib/python3.9/site-packages/airflow/utils/log/file_task_handler.py", line 211, in emit
    self.handler.emit(record)
  File "/usr/local/lib/python3.9/logging/__init__.py", line 1187, in emit
    StreamHandler.emit(self, record)
  File "/usr/local/lib/python3.9/logging/__init__.py", line 1091, in emit
    self.handleError(record)
  File "/usr/local/lib/python3.9/logging/__init__.py", line 1004, in handleError
    sys.stderr.write('--- Logging error ---\n')
  File "/home/airflow/.local/lib/python3.9/site-packages/airflow/utils/log/logging_mixin.py", line 161, in write
    self.flush()
  File "/home/airflow/.local/lib/python3.9/site-packages/airflow/utils/log/logging_mixin.py", line 168, in flush
    self._propagate_log(buf)
  File "/home/airflow/.local/lib/python3.9/site-packages/airflow/utils/log/logging_mixin.py", line 149, in _propagate_log
    self.logger.log(self.level, remove_escape_codes(message))
  File "/usr/local/lib/python3.9/logging/__init__.py", line 1512, in log
    self._log(level, msg, args, **kwargs)
  File "/usr/local/lib/python3.9/logging/__init__.py", line 1589, in _log
    self.handle(record)
  File "/usr/local/lib/python3.9/logging/__init__.py", line 1599, in handle
    self.callHandlers(record)
  File "/usr/local/lib/python3.9/logging/__init__.py", line 1661, in callHandlers
    hdlr.handle(record)
  File "/usr/local/lib/python3.9/logging/__init__.py", line 952, in handle
    self.emit(record)
  File "/home/airflow/.local/lib/python3.9/site-packages/airflow/utils/log/file_task_handler.py", line 211, in emit
    self.handler.emit(record)
  File "/usr/local/lib/python3.9/logging/__init__.py", line 1187, in emit
    StreamHandler.emit(self, record)
  File "/usr/local/lib/python3.9/logging/__init__.py", line 1091, in emit
    self.handleError(record)
  File "/usr/local/lib/python3.9/logging/__init__.py", line 1004, in handleError
    sys.stderr.write('--- Logging error ---\n')
  File "/home/airflow/.local/lib/python3.9/site-packages/airflow/utils/log/logging_mixin.py", line 161, in write
    self.flush()
  File "/home/airflow/.local/lib/python3.9/site-packages/airflow/utils/log/logging_mixin.py", line 168, in flush
    self._propagate_log(buf)
  File "/home/airflow/.local/lib/python3.9/site-packages/airflow/utils/log/logging_mixin.py", line 149, in _propagate_log
    self.logger.log(self.level, remove_escape_codes(message))
  File "/usr/local/lib/python3.9/logging/__init__.py", line 1512, in log
    self._log(level, msg, args, **kwargs)
  File "/usr/local/lib/python3.9/logging/__init__.py", line 1589, in _log
    self.handle(record)
  File "/usr/local/lib/python3.9/logging/__init__.py", line 1599, in handle
    self.callHandlers(record)
  File "/usr/local/lib/python3.9/logging/__init__.py", line 1661, in callHandlers
    hdlr.handle(record)
  File "/usr/local/lib/python3.9/logging/__init__.py", line 952, in handle
    self.emit(record)
  File "/home/airflow/.local/lib/python3.9/site-packages/airflow/utils/log/file_task_handler.py", line 211, in emit
    self.handler.emit(record)
  File "/usr/local/lib/python3.9/logging/__init__.py", line 1187, in emit
    StreamHandler.emit(self, record)
  File "/usr/local/lib/python3.9/logging/__init__.py", line 1091, in emit
    self.handleError(record)
  File "/usr/local/lib/python3.9/logging/__init__.py", line 1004, in handleError
    sys.stderr.write('--- Logging error ---\n')
  File "/home/airflow/.local/lib/python3.9/site-packages/airflow/utils/log/logging_mixin.py", line 161, in write
    self.flush()
  File "/home/airflow/.local/lib/python3.9/site-packages/airflow/utils/log/logging_mixin.py", line 168, in flush
    self._propagate_log(buf)
  File "/home/airflow/.local/lib/python3.9/site-packages/airflow/utils/log/logging_mixin.py", line 149, in _propagate_log
    self.logger.log(self.level, remove_escape_codes(message))
  File "/usr/local/lib/python3.9/logging/__init__.py", line 1512, in log
    self._log(level, msg, args, **kwargs)
  File "/usr/local/lib/python3.9/logging/__init__.py", line 1589, in _log
    self.handle(record)
  File "/usr/local/lib/python3.9/logging/__init__.py", line 1599, in handle
    self.callHandlers(record)
  File "/usr/local/lib/python3.9/logging/__init__.py", line 1661, in callHandlers
    hdlr.handle(record)
  File "/usr/local/lib/python3.9/logging/__init__.py", line 952, in handle
    self.emit(record)
  File "/home/airflow/.local/lib/python3.9/site-packages/airflow/utils/log/file_task_handler.py", line 211, in emit
    self.handler.emit(record)
  File "/usr/local/lib/python3.9/logging/__init__.py", line 1187, in emit
    StreamHandler.emit(self, record)
  File "/usr/local/lib/python3.9/logging/__init__.py", line 1091, in emit
    self.handleError(record)
  File "/usr/local/lib/python3.9/logging/__init__.py", line 1004, in handleError
    sys.stderr.write('--- Logging error ---\n')
  File "/home/airflow/.local/lib/python3.9/site-packages/airflow/utils/log/logging_mixin.py", line 161, in write
    self.flush()
  File "/home/airflow/.local/lib/python3.9/site-packages/airflow/utils/log/logging_mixin.py", line 168, in flush
    self._propagate_log(buf)
  File "/home/airflow/.local/lib/python3.9/site-packages/airflow/utils/log/logging_mixin.py", line 149, in _propagate_log
    self.logger.log(self.level, remove_escape_codes(message))
  File "/usr/local/lib/python3.9/logging/__init__.py", line 1512, in log
    self._log(level, msg, args, **kwargs)
  File "/usr/local/lib/python3.9/logging/__init__.py", line 1589, in _log
    self.handle(record)
  File "/usr/local/lib/python3.9/logging/__init__.py", line 1599, in handle
    self.callHandlers(record)
  File "/usr/local/lib/python3.9/logging/__init__.py", line 1661, in callHandlers
    hdlr.handle(record)
  File "/usr/local/lib/python3.9/logging/__init__.py", line 952, in handle
    self.emit(record)
  File "/home/airflow/.local/lib/python3.9/site-packages/airflow/utils/log/file_task_handler.py", line 211, in emit
    self.handler.emit(record)
  File "/usr/local/lib/python3.9/logging/__init__.py", line 1187, in emit
    StreamHandler.emit(self, record)
  File "/usr/local/lib/python3.9/logging/__init__.py", line 1091, in emit
    self.handleError(record)
  File "/usr/local/lib/python3.9/logging/__init__.py", line 1004, in handleError
    sys.stderr.write('--- Logging error ---\n')
  File "/home/airflow/.local/lib/python3.9/site-packages/airflow/utils/log/logging_mixin.py", line 161, in write
    self.flush()
  File "/home/airflow/.local/lib/python3.9/site-packages/airflow/utils/log/logging_mixin.py", line 168, in flush
    self._propagate_log(buf)
  File "/home/airflow/.local/lib/python3.9/site-packages/airflow/utils/log/logging_mixin.py", line 149, in _propagate_log
    self.logger.log(self.level, remove_escape_codes(message))
  File "/usr/local/lib/python3.9/logging/__init__.py", line 1512, in log
    self._log(level, msg, args, **kwargs)
  File "/usr/local/lib/python3.9/logging/__init__.py", line 1589, in _log
    self.handle(record)
  File "/usr/local/lib/python3.9/logging/__init__.py", line 1599, in handle
    self.callHandlers(record)
  File "/usr/local/lib/python3.9/logging/__init__.py", line 1661, in callHandlers
    hdlr.handle(record)
  File "/usr/local/lib/python3.9/logging/__init__.py", line 952, in handle
    self.emit(record)
  File "/home/airflow/.local/lib/python3.9/site-packages/airflow/utils/log/file_task_handler.py", line 211, in emit
    self.handler.emit(record)
  File "/usr/local/lib/python3.9/logging/__init__.py", line 1187, in emit
    StreamHandler.emit(self, record)
  File "/usr/local/lib/python3.9/logging/__init__.py", line 1091, in emit
    self.handleError(record)
  File "/usr/local/lib/python3.9/logging/__init__.py", line 1004, in handleError
    sys.stderr.write('--- Logging error ---\n')
  File "/home/airflow/.local/lib/python3.9/site-packages/airflow/utils/log/logging_mixin.py", line 161, in write
    self.flush()
  File "/home/airflow/.local/lib/python3.9/site-packages/airflow/utils/log/logging_mixin.py", line 168, in flush
    self._propagate_log(buf)
  File "/home/airflow/.local/lib/python3.9/site-packages/airflow/utils/log/logging_mixin.py", line 149, in _propagate_log
    self.logger.log(self.level, remove_escape_codes(message))
  File "/usr/local/lib/python3.9/logging/__init__.py", line 1512, in log
    self._log(level, msg, args, **kwargs)
  File "/usr/local/lib/python3.9/logging/__init__.py", line 1587, in _log
    record = self.makeRecord(self.name, level, fn, lno, msg, args,
  File "/usr/local/lib/python3.9/logging/__init__.py", line 1556, in makeRecord
    rv = _logRecordFactory(name, level, fn, lno, msg, args, exc_info, func,
  File "/usr/local/lib/python3.9/logging/__init__.py", line 312, in __init__
    self.levelname = getLevelName(level)
  File "/usr/local/lib/python3.9/logging/__init__.py", line 138, in getLevelName
    result = _levelToName.get(level)
RecursionError: maximum recursion depth exceeded while calling a Python object
[2023-09-22T16:52:46.696+0000] {taskinstance.py:1368} INFO - Marking task as UP_FOR_RETRY. dag_id=dag_with_taskflow_api_v02, task_id=greet, execution_date=20211115T000000, start_date=20230922T165240, end_date=20230922T165246
[2023-09-22T16:52:46.730+0000] {standard_task_runner.py:104} ERROR - Failed to execute job 169 for task greet (maximum recursion depth exceeded while calling a Python object; 622)
[2023-09-22T16:52:46.793+0000] {process_utils.py:79} INFO - Process psutil.Process(pid=622, status='terminated', exitcode=1, started='16:52:39') (622) terminated with exit code 1
[2023-09-22T16:52:46.809+0000] {local_task_job_runner.py:232} INFO - Task exited with return code 143
[2023-09-22T16:52:47.771+0000] {taskinstance.py:2674} INFO - 0 downstream tasks scheduled from follow-on schedule check
