[2023-09-22T16:52:39.904+0000] {logging_mixin.py:149} WARNING - /home/***/.local/lib/python3.9/site-packages/***/utils/sqlalchemy.py:124 DeprecationWarning: The sql_alchemy_conn option in [core] has been moved to the sql_alchemy_conn option in [database] - the old setting has been used, but please update your config.
[2023-09-22T16:52:40.170+0000] {taskinstance.py:1125} INFO - Dependencies all met for dep_context=non-requeueable deps ti=<TaskInstance: dag_with_taskflow_api_v02.greet__1 scheduled__2021-11-18T00:00:00+00:00 [queued]>
[2023-09-22T16:52:40.199+0000] {taskinstance.py:1125} INFO - Dependencies all met for dep_context=requeueable deps ti=<TaskInstance: dag_with_taskflow_api_v02.greet__1 scheduled__2021-11-18T00:00:00+00:00 [queued]>
[2023-09-22T16:52:40.201+0000] {taskinstance.py:1331} INFO - Starting attempt 1 of 6
[2023-09-22T16:52:40.240+0000] {taskinstance.py:1350} INFO - Executing <Task(_PythonDecoratedOperator): greet__1> on 2021-11-18 00:00:00+00:00
[2023-09-22T16:52:40.254+0000] {standard_task_runner.py:57} INFO - Started process 614 to run task
[2023-09-22T16:52:40.303+0000] {standard_task_runner.py:84} INFO - Running: ['***', 'tasks', 'run', 'dag_with_taskflow_api_v02', 'greet__1', 'scheduled__2021-11-18T00:00:00+00:00', '--job-id', '158', '--raw', '--subdir', 'DAGS_FOLDER/test2.py', '--cfg-path', '/tmp/tmpj4tx7k3a']
[2023-09-22T16:52:40.312+0000] {standard_task_runner.py:85} INFO - Job 158: Subtask greet__1
[2023-09-22T16:52:40.358+0000] {logging_mixin.py:149} WARNING - /home/***/.local/lib/python3.9/site-packages/***/settings.py:188 DeprecationWarning: The sql_alchemy_conn option in [core] has been moved to the sql_alchemy_conn option in [database] - the old setting has been used, but please update your config.
[2023-09-22T16:52:40.432+0000] {task_command.py:410} INFO - Running <TaskInstance: dag_with_taskflow_api_v02.greet__1 scheduled__2021-11-18T00:00:00+00:00 [running]> on host 75cee4990e54
[2023-09-22T16:52:40.480+0000] {logging_mixin.py:149} WARNING - /home/***/.local/lib/python3.9/site-packages/***/utils/sqlalchemy.py:124 DeprecationWarning: The sql_alchemy_conn option in [core] has been moved to the sql_alchemy_conn option in [database] - the old setting has been used, but please update your config.
[2023-09-22T16:52:45.960+0000] {local_task_job_runner.py:122} ERROR - Received SIGTERM. Terminating subprocesses
[2023-09-22T16:52:46.269+0000] {process_utils.py:131} INFO - Sending Signals.SIGTERM to group 614. PIDs of all processes in the group: [614]
[2023-09-22T16:52:46.302+0000] {process_utils.py:86} INFO - Sending the signal Signals.SIGTERM to group 614
[2023-09-22T16:52:46.313+0000] {taskinstance.py:1540} ERROR - Received SIGTERM. Terminating subprocesses.
[2023-09-22T16:52:46.377+0000] {taskinstance.py:1847} ERROR - Task failed with exception
Traceback (most recent call last):
  File "/home/airflow/.local/lib/python3.9/site-packages/airflow/models/taskinstance.py", line 1430, in _run_raw_task
    self._execute_task_with_callbacks(context, test_mode)
  File "/home/airflow/.local/lib/python3.9/site-packages/airflow/models/taskinstance.py", line 1558, in _execute_task_with_callbacks
    RenderedTaskInstanceFields.delete_old_records(self.task_id, self.dag_id)
  File "/home/airflow/.local/lib/python3.9/site-packages/airflow/utils/session.py", line 76, in wrapper
    return func(*args, session=session, **kwargs)
  File "/home/airflow/.local/lib/python3.9/site-packages/airflow/models/renderedtifields.py", line 219, in delete_old_records
    cls._do_delete_old_records(
  File "/home/airflow/.local/lib/python3.9/site-packages/airflow/utils/retries.py", line 78, in wrapped_function
    for attempt in run_with_db_retries(max_retries=retries, logger=logger, **retry_kwargs):
  File "/home/airflow/.local/lib/python3.9/site-packages/tenacity/__init__.py", line 347, in __iter__
    do = self.iter(retry_state=retry_state)
  File "/home/airflow/.local/lib/python3.9/site-packages/tenacity/__init__.py", line 314, in iter
    return fut.result()
  File "/usr/local/lib/python3.9/concurrent/futures/_base.py", line 439, in result
    return self.__get_result()
  File "/usr/local/lib/python3.9/concurrent/futures/_base.py", line 391, in __get_result
    raise self._exception
  File "/home/airflow/.local/lib/python3.9/site-packages/airflow/utils/retries.py", line 87, in wrapped_function
    return func(*args, **kwargs)
  File "/home/airflow/.local/lib/python3.9/site-packages/airflow/models/renderedtifields.py", line 238, in _do_delete_old_records
    session.query(cls).filter(
  File "/home/airflow/.local/lib/python3.9/site-packages/sqlalchemy/orm/query.py", line 3222, in delete
    result = self.session.execute(
  File "/home/airflow/.local/lib/python3.9/site-packages/sqlalchemy/orm/session.py", line 1714, in execute
    result = conn._execute_20(statement, params or {}, execution_options)
  File "/home/airflow/.local/lib/python3.9/site-packages/sqlalchemy/engine/base.py", line 1705, in _execute_20
    return meth(self, args_10style, kwargs_10style, execution_options)
  File "/home/airflow/.local/lib/python3.9/site-packages/sqlalchemy/sql/elements.py", line 334, in _execute_on_connection
    return connection._execute_clauseelement(
  File "/home/airflow/.local/lib/python3.9/site-packages/sqlalchemy/engine/base.py", line 1572, in _execute_clauseelement
    ret = self._execute_context(
  File "/home/airflow/.local/lib/python3.9/site-packages/sqlalchemy/engine/base.py", line 1943, in _execute_context
    self._handle_dbapi_exception(
  File "/home/airflow/.local/lib/python3.9/site-packages/sqlalchemy/engine/base.py", line 2128, in _handle_dbapi_exception
    util.raise_(exc_info[1], with_traceback=exc_info[2])
  File "/home/airflow/.local/lib/python3.9/site-packages/sqlalchemy/util/compat.py", line 211, in raise_
    raise exception
  File "/home/airflow/.local/lib/python3.9/site-packages/sqlalchemy/engine/base.py", line 1900, in _execute_context
    self.dialect.do_execute(
  File "/home/airflow/.local/lib/python3.9/site-packages/sqlalchemy/engine/default.py", line 736, in do_execute
    cursor.execute(statement, parameters)
  File "/usr/local/lib/python3.9/encodings/utf_8.py", line 15, in decode
    def decode(input, errors='strict'):
  File "/home/airflow/.local/lib/python3.9/site-packages/airflow/models/taskinstance.py", line 1542, in signal_handler
    raise AirflowException("Task received SIGTERM signal")
airflow.exceptions.AirflowException: Task received SIGTERM signal
[2023-09-22T16:52:46.533+0000] {taskinstance.py:1368} INFO - Marking task as UP_FOR_RETRY. dag_id=dag_with_taskflow_api_v02, task_id=greet__1, execution_date=20211118T000000, start_date=20230922T165240, end_date=20230922T165246
[2023-09-22T16:52:46.574+0000] {standard_task_runner.py:104} ERROR - Failed to execute job 158 for task greet__1 (Task received SIGTERM signal; 614)
[2023-09-22T16:52:46.649+0000] {process_utils.py:79} INFO - Process psutil.Process(pid=614, status='terminated', exitcode=1, started='16:52:39') (614) terminated with exit code 1
[2023-09-22T16:52:46.669+0000] {local_task_job_runner.py:232} INFO - Task exited with return code 143
[2023-09-22T16:52:47.772+0000] {taskinstance.py:2674} INFO - 0 downstream tasks scheduled from follow-on schedule check
