[2023-09-22T16:52:39.915+0000] {logging_mixin.py:149} WARNING - /home/***/.local/lib/python3.9/site-packages/***/utils/sqlalchemy.py:124 DeprecationWarning: The sql_alchemy_conn option in [core] has been moved to the sql_alchemy_conn option in [database] - the old setting has been used, but please update your config.
[2023-09-22T16:52:40.184+0000] {taskinstance.py:1125} INFO - Dependencies all met for dep_context=non-requeueable deps ti=<TaskInstance: dag_with_taskflow_api_v02.get_age scheduled__2021-11-24T00:00:00+00:00 [queued]>
[2023-09-22T16:52:40.211+0000] {taskinstance.py:1125} INFO - Dependencies all met for dep_context=requeueable deps ti=<TaskInstance: dag_with_taskflow_api_v02.get_age scheduled__2021-11-24T00:00:00+00:00 [queued]>
[2023-09-22T16:52:40.218+0000] {taskinstance.py:1331} INFO - Starting attempt 1 of 6
[2023-09-22T16:52:40.271+0000] {taskinstance.py:1350} INFO - Executing <Task(_PythonDecoratedOperator): get_age> on 2021-11-24 00:00:00+00:00
[2023-09-22T16:52:40.285+0000] {standard_task_runner.py:57} INFO - Started process 624 to run task
[2023-09-22T16:52:40.309+0000] {standard_task_runner.py:84} INFO - Running: ['***', 'tasks', 'run', 'dag_with_taskflow_api_v02', 'get_age', 'scheduled__2021-11-24T00:00:00+00:00', '--job-id', '162', '--raw', '--subdir', 'DAGS_FOLDER/test2.py', '--cfg-path', '/tmp/tmpdh8dnew0']
[2023-09-22T16:52:40.320+0000] {standard_task_runner.py:85} INFO - Job 162: Subtask get_age
[2023-09-22T16:52:40.364+0000] {logging_mixin.py:149} WARNING - /home/***/.local/lib/python3.9/site-packages/***/settings.py:188 DeprecationWarning: The sql_alchemy_conn option in [core] has been moved to the sql_alchemy_conn option in [database] - the old setting has been used, but please update your config.
[2023-09-22T16:52:40.491+0000] {task_command.py:410} INFO - Running <TaskInstance: dag_with_taskflow_api_v02.get_age scheduled__2021-11-24T00:00:00+00:00 [running]> on host 75cee4990e54
[2023-09-22T16:52:40.553+0000] {logging_mixin.py:149} WARNING - /home/***/.local/lib/python3.9/site-packages/***/utils/sqlalchemy.py:124 DeprecationWarning: The sql_alchemy_conn option in [core] has been moved to the sql_alchemy_conn option in [database] - the old setting has been used, but please update your config.
[2023-09-22T16:52:45.368+0000] {taskinstance.py:1568} INFO - Exporting env vars: AIRFLOW_CTX_DAG_OWNER='coder2j' AIRFLOW_CTX_DAG_ID='dag_with_taskflow_api_v02' AIRFLOW_CTX_TASK_ID='get_age' AIRFLOW_CTX_EXECUTION_DATE='2021-11-24T00:00:00+00:00' AIRFLOW_CTX_TRY_NUMBER='1' AIRFLOW_CTX_DAG_RUN_ID='scheduled__2021-11-24T00:00:00+00:00'
[2023-09-22T16:52:45.520+0000] {python.py:183} INFO - Done. Returned value was: 19
[2023-09-22T16:52:46.107+0000] {local_task_job_runner.py:122} ERROR - Received SIGTERM. Terminating subprocesses
[2023-09-22T16:52:46.170+0000] {process_utils.py:131} INFO - Sending Signals.SIGTERM to group 624. PIDs of all processes in the group: [624]
[2023-09-22T16:52:46.184+0000] {process_utils.py:86} INFO - Sending the signal Signals.SIGTERM to group 624
[2023-09-22T16:52:46.196+0000] {taskinstance.py:1540} ERROR - Received SIGTERM. Terminating subprocesses.
[2023-09-22T16:52:46.269+0000] {taskinstance.py:1847} ERROR - Task failed with exception
Traceback (most recent call last):
  File "/home/airflow/.local/lib/python3.9/site-packages/airflow/models/taskinstance.py", line 1432, in _run_raw_task
    self.refresh_from_db(lock_for_update=True, session=session)
  File "/home/airflow/.local/lib/python3.9/site-packages/airflow/utils/session.py", line 73, in wrapper
    return func(*args, **kwargs)
  File "/home/airflow/.local/lib/python3.9/site-packages/airflow/models/taskinstance.py", line 829, in refresh_from_db
    for attempt in run_with_db_retries(logger=self.log):
  File "/home/airflow/.local/lib/python3.9/site-packages/tenacity/__init__.py", line 347, in __iter__
    do = self.iter(retry_state=retry_state)
  File "/home/airflow/.local/lib/python3.9/site-packages/tenacity/__init__.py", line 314, in iter
    return fut.result()
  File "/usr/local/lib/python3.9/concurrent/futures/_base.py", line 439, in result
    return self.__get_result()
  File "/usr/local/lib/python3.9/concurrent/futures/_base.py", line 391, in __get_result
    raise self._exception
  File "/home/airflow/.local/lib/python3.9/site-packages/airflow/models/taskinstance.py", line 831, in refresh_from_db
    ti: TaskInstance | None = qry.with_for_update().one_or_none()
  File "/home/airflow/.local/lib/python3.9/site-packages/sqlalchemy/orm/query.py", line 2850, in one_or_none
    return self._iter().one_or_none()
  File "/home/airflow/.local/lib/python3.9/site-packages/sqlalchemy/orm/query.py", line 2916, in _iter
    result = self.session.execute(
  File "/home/airflow/.local/lib/python3.9/site-packages/sqlalchemy/orm/session.py", line 1714, in execute
    result = conn._execute_20(statement, params or {}, execution_options)
  File "/home/airflow/.local/lib/python3.9/site-packages/sqlalchemy/engine/base.py", line 1705, in _execute_20
    return meth(self, args_10style, kwargs_10style, execution_options)
  File "/home/airflow/.local/lib/python3.9/site-packages/sqlalchemy/sql/elements.py", line 334, in _execute_on_connection
    return connection._execute_clauseelement(
  File "/home/airflow/.local/lib/python3.9/site-packages/sqlalchemy/engine/base.py", line 1572, in _execute_clauseelement
    ret = self._execute_context(
  File "/home/airflow/.local/lib/python3.9/site-packages/sqlalchemy/engine/base.py", line 1943, in _execute_context
    self._handle_dbapi_exception(
  File "/home/airflow/.local/lib/python3.9/site-packages/sqlalchemy/engine/base.py", line 2128, in _handle_dbapi_exception
    util.raise_(exc_info[1], with_traceback=exc_info[2])
  File "/home/airflow/.local/lib/python3.9/site-packages/sqlalchemy/util/compat.py", line 211, in raise_
    raise exception
  File "/home/airflow/.local/lib/python3.9/site-packages/sqlalchemy/engine/base.py", line 1900, in _execute_context
    self.dialect.do_execute(
  File "/home/airflow/.local/lib/python3.9/site-packages/sqlalchemy/engine/default.py", line 736, in do_execute
    cursor.execute(statement, parameters)
  File "/usr/local/lib/python3.9/encodings/utf_8.py", line 15, in decode
    def decode(input, errors='strict'):
  File "/home/airflow/.local/lib/python3.9/site-packages/airflow/models/taskinstance.py", line 1542, in signal_handler
    raise AirflowException("Task received SIGTERM signal")
airflow.exceptions.AirflowException: Task received SIGTERM signal
[2023-09-22T16:52:46.532+0000] {taskinstance.py:1368} INFO - Marking task as UP_FOR_RETRY. dag_id=dag_with_taskflow_api_v02, task_id=get_age, execution_date=20211124T000000, start_date=20230922T165240, end_date=20230922T165246
[2023-09-22T16:52:46.597+0000] {standard_task_runner.py:104} ERROR - Failed to execute job 162 for task get_age (Task received SIGTERM signal; 624)
[2023-09-22T16:52:46.711+0000] {process_utils.py:79} INFO - Process psutil.Process(pid=624, status='terminated', exitcode=1, started='16:52:39') (624) terminated with exit code 1
[2023-09-22T16:52:46.744+0000] {local_task_job_runner.py:232} INFO - Task exited with return code 143
[2023-09-22T16:52:48.112+0000] {taskinstance.py:2674} INFO - 0 downstream tasks scheduled from follow-on schedule check
